Workbook

Sheet Coffee Audit
A1: Date | B1: City | C1: Cafe_Name | D1: Coffee_Name | E1: Producer_Farm | F1: Origin | G1: Varietal | H1: Process | I1: Roast_Level | J1: Brew_Method | K1: Dose_g | L1: Yield_g | M1: Ratio | N1: Water_Temp_C | O1: Bloom | P1: Grinder | Q1: Price_SGD | R1: Official_Notes | S1: Your_Verdict | T1: Technical_Enrichment | U1: Visit_Context | V1: Source | W1: Gesha_Alert
A2: 46025 | B2: Ubud, Bali | C2: Seniman Coffee Studio | D2: Bali Karana Kintamanis | E2: Unknown | F2: Kintamani, Bali | G2: Unknown | H2: Natural | I2: Light | J2: Filter | K2: Unknown | L2: Unknown | M2: Unknown | N2: Unknown | O2: Unknown | P2: Unknown | Q2: Unknown | R2: Clean citrus; floral | S2: Excellent clarity for a natural process; clean citrus and floral notes. | T2: Natural processing contributed mild fruit-forward esters with relatively clean finish; foundational exposure to local Indonesian origins. | U2: Bali family trip | V2: Merged (Gemini + ChatGPT) | W2: =IF(OR(ISNUMBER(SEARCH("gesha",G2)),ISNUMBER(SEARCH("geisha",G2))),"⭐ GESHA","")
A3: 46026 | B3: Ubud, Bali | C3: Seniman Coffee Studio | D3: Sulawesi Toraja | E3: Unknown | F3: Sulawesi, Indonesia | G3: Unknown | H3: Wet-Hulled | I3: Medium | J3: Pour-over | K3: Unknown | L3: Unknown | M3: Unknown | N3: Unknown | O3: Unknown | P3: Unknown | Q3: Unknown | R3: Cocoa; earthy structures | S3: Heavy body with rich cocoa and earthy notes; low acidity; dense mouthfeel. | T3: Classic Giling Basah wet-hulled process emphasized earthy compounds and syrupy mouthfeel; structural density confirmed. | U3: Bali family trip | V3: Merged (Gemini + ChatGPT) | W3: =IF(OR(ISNUMBER(SEARCH("gesha",G3)),ISNUMBER(SEARCH("geisha",G3))),"⭐ GESHA","")
A4: 46026 | B4: Ubud, Bali | C4: Seniman Coffee Studio | D4: House Blend | E4: Unknown | F4: Unknown | G4: Unknown | H4: Unknown | I4: Espresso Roast | J4: Piccolo | K4: Unknown | L4: Unknown | M4: Unknown | N4: Unknown | O4: Unknown | P4: Unknown | Q4: Unknown | R4: Balanced | S4: Great milk integration; standard espresso + milk calibration. | T4: Baseline milk pairing; milk fats softened acidity and amplified sweetness and body. | U4: Bali family trip | V4: Merged (Gemini + ChatGPT) | W4: =IF(OR(ISNUMBER(SEARCH("gesha",G4)),ISNUMBER(SEARCH("geisha",G4))),"⭐ GESHA","")
A5: 46063 | B5: Singapore | C5: Kyuukei Coffee | D5: Kenya Kiamugumo AA | E5: New Ngariama Farmer's Cooperative Society | F5: Kiamugumo, Murang'a County, Kenya | G5: SL28 / SL34 | H5: Washed | I5: Unknown | J5: Pour-over (Flat-Bottom) | K5: 15 | L5: 240 | M5: 1:16 | N5: 93 | O5: Unknown | P5: 120mm Hybrid Burr | Q5: 8 | R5: Blackcurrant, Lemon, Citrus Zest, Mineral Finish | S5: Extremely clean and structured — classic Kenyan profile. Bright blackcurrant acidity layered with lemon and light white grape sweetness. Clarity was the standout: no fermentation noise, no muddiness — precise, well-executed extraction. Compelling demonstration of how a well-processed washed coffee performs when roasted and brewed correctly. Phosphoric acid signature fully confirmed across all phases. | T5: 120mm hybrid burr grinder delivered uniform particle distribution; flat-bottom pour-over geometry ensured even extraction across the full puck. 93°C water temp and 1:16 lean ratio preserved SL28/SL34 phosphoric acid clarity without over-extracting into bitterness. Brew time 2:45 consistent with controlled drawdown on flat-bottom geometry. Kenyan phosphoric acid and anthocyanin-driven blackcurrant notes are varietal signatures of Scott Laboratories SL28/SL34 genetics. | U5: Solo visit — early archive period, first Kyūkei filter audit | V5: Direct observation + infographic + Google review (10 Feb 2026) | W5: =IF(OR(ISNUMBER(SEARCH("gesha",G5)),ISNUMBER(SEARCH("geisha",G5))),"⭐ GESHA","")
A6: 46082 | B6: Mumbai | C6: Subko Coffee Roasters | D6: Project Pearl Ratnagiri | E6: Ratnagiri Estate | F6: India | G6: Unknown | H6: Anaerobic Natural | I6: Light (Agtron 89) | J6: Filter | K6: Unknown | L6: Unknown | M6: Unknown | N6: Unknown | O6: Unknown | P6: Unknown | Q6: Unknown | R6: Unknown | S6: Clean and balanced; interesting but restrained anaerobic expression. | T6: Very light roast (Agtron 89) suppressed ester development despite anaerobic process; muted expected fermented intensity. | U6: Mumbai café exploration | V6: Merged (Gemini + ChatGPT) | W6: =IF(OR(ISNUMBER(SEARCH("gesha",G6)),ISNUMBER(SEARCH("geisha",G6))),"⭐ GESHA","")
A7: 46089 | B7: Mumbai | C7: Grey Soul Coffee Roasters | D7: Raspberry in Loop - Zoya Estate | E7: Zoya Estate | F7: India | G7: Unknown | H7: Multi-stage Anaerobic | I7: Medium | J7: Filter | K7: Unknown | L7: Unknown | M7: Unknown | N7: Unknown | O7: Unknown | P7: Unknown | Q7: Unknown | R7: Chocolate | S7: Heavy body; over-smoothed expression muted brightness and terroir. | T7: Higher development in medium roast reduced aggressive fruit acidity; heavy multi-stage fermentation suppressed terroir expression. | U7: Mumbai café exploration | V7: Merged (Gemini + ChatGPT) | W7: =IF(OR(ISNUMBER(SEARCH("gesha",G7)),ISNUMBER(SEARCH("geisha",G7))),"⭐ GESHA","")
A8: 46099 | B8: Singapore | C8: Narrative Coffee Stand | D8: Finca La Siberia | E8: Unknown | F8: El Salvador | G8: Pacamara | H8: Natural | I8: Light | J8: Pour-over | K8: Unknown | L8: Unknown | M8: Unknown | N8: Unknown | O8: Unknown | P8: Unknown | Q8: Unknown | R8: Unknown | S8: Stewed apples; Apricot; Pu'er tea — Aanya's first specialty filter experience. | T8: Natural Pacamara generated beginner-friendly fruit esters and approachable sweetness; large Pacamara bean size aided even extraction. | U8: Father-daughter coffee exploration | V8: ChatGPT only | W8: =IF(OR(ISNUMBER(SEARCH("gesha",G8)),ISNUMBER(SEARCH("geisha",G8))),"⭐ GESHA","")
A9: 46099 | B9: Singapore | C9: Narrative Coffee Stand | D9: El Puente | E9: Unknown | F9: Honduras | G9: Catuai | H9: Washed | I9: Medium-Light | J9: Espresso | K9: Unknown | L9: Unknown | M9: Unknown | N9: Unknown | O9: Unknown | P9: Unknown | Q9: Unknown | R9: Unknown | S9: Black cherry; Apricot; Pecan — ordered for espresso contrast. | T9: Washed Central American espresso balanced nutty sweetness and fruit acidity; Catuai's consistent cell structure aided uniform extraction. | U9: Father-daughter coffee exploration | V9: ChatGPT only | W9: =IF(OR(ISNUMBER(SEARCH("gesha",G9)),ISNUMBER(SEARCH("geisha",G9))),"⭐ GESHA","")
A10: 46099 | B10: Singapore | C10: ASK Coffee Roastery | D10: Honduras Masaguara (S13) | E10: Unknown | F10: Honduras | G10: Catuai / Caturra | H10: Washed Co-Ferment | I10: Light | J10: Pour-over | K10: Unknown | L10: Unknown | M10: Unknown | N10: Unknown | O10: Unknown | P10: Unknown | Q10: 15 | R10: Lychee; Brandy; Honeydew; Milk Chocolate | S10: Premium but memorable; highly complex tropical profile. | T10: Co-fermentation amplified tropical ester complexity; co-ferment substrates introduced lychee lactones and brandy-like ethyl esters. | U10: Father-daughter coffee exploration | V10: ChatGPT only | W10: =IF(OR(ISNUMBER(SEARCH("gesha",G10)),ISNUMBER(SEARCH("geisha",G10))),"⭐ GESHA","")
A11: 46099 | B11: Singapore | C11: ASK Coffee Roastery | D11: House Blend | E11: Unknown | F11: Unknown | G11: Unknown | H11: Unknown | I11: Unknown | J11: Magic (Ristretto Milk) | K11: Unknown | L11: Unknown | M11: Unknown | N11: Unknown | O11: Unknown | P11: Unknown | Q11: Unknown | R11: Unknown | S11: Contrast milk calibration; excellent concentrated cocoa expression. | T11: Ristretto milk extraction increased sweetness density and concentrated cocoa compounds through reduced water content. | U11: Father-daughter coffee exploration | V11: ChatGPT only | W11: =IF(OR(ISNUMBER(SEARCH("gesha",G11)),ISNUMBER(SEARCH("geisha",G11))),"⭐ GESHA","")
A12: 46103 | B12: Singapore | C12: Apartment (Selegie Rd) | D12: Colombia Don Gallego - Wush Wush | E12: Don Gallego | F12: Colombia | G12: Wush Wush | H12: Washed | I12: Light | J12: Pour-over (Flat-Bottom) | K12: Unknown | L12: Unknown | M12: 1:17 | N12: Unknown | O12: Unknown | P12: Unknown | Q12: Unknown | R12: Tea-like | S12: Incredible tea-like clarity; transparent floral expression. | T12: Lean 1:17 ratio maximized aromatic separation; Wush Wush's Ethiopian-lineage genetics produced delicate phenolic and floral complexity. | U12: Solo specialty calibration | V12: Merged (Gemini + ChatGPT) | W12: =IF(OR(ISNUMBER(SEARCH("gesha",G12)),ISNUMBER(SEARCH("geisha",G12))),"⭐ GESHA","")
A13: 46105 | B13: Singapore | C13: Kyuukei Coffee | D13: Kenya Ndiaini AA | E13: Unknown | F13: Kenya | G13: SL28 / SL34 / Ruiru 11 | H13: Washed | I13: Unknown | J13: Pour-over | K13: Unknown | L13: Unknown | M13: Unknown | N13: Unknown | O13: Unknown | P13: Unknown | Q13: 9 | R13: Redcurrant; Elderflower; Lemon; Apricot | S13: Acidic and interesting; well balanced; high clarity. | T13: Ruiru 11 introduced structural body alongside classic SL28/SL34 brightness; further Kenyan terroir depth confirmed. | U13: Solo specialty calibration | V13: Merged (Gemini + ChatGPT) | W13: =IF(OR(ISNUMBER(SEARCH("gesha",G13)),ISNUMBER(SEARCH("geisha",G13))),"⭐ GESHA","")
A14: 46106 | B14: Singapore | C14: Agora Coffee | D14: Nicaragua Matagalpa - Finca La Virgen | E14: Finca La Virgen | F14: Nicaragua | G14: Unknown | H14: Fully Washed | I14: Espresso Roast | J14: Flat White | K14: Unknown | L14: Unknown | M14: Unknown | N14: Unknown | O14: Unknown | P14: Unknown | Q14: Unknown | R14: Caramel; Chocolate; Red Apple | S14: Solid milk beverage; clean apple acidity preserved in milk integration. | T14: Fully washed Central American profile preserved clean malic acidity in milk; espresso roast development amplified caramel Maillard notes. | U14: Solo specialty calibration | V14: Merged (Gemini + ChatGPT) | W14: =IF(OR(ISNUMBER(SEARCH("gesha",G14)),ISNUMBER(SEARCH("geisha",G14))),"⭐ GESHA","")
A15: 46108 | B15: Singapore | C15: Agora Coffee | D15: Ethiopia Yirgacheffe Beloya | E15: Beloya | F15: Yirgacheffe, Ethiopia | G15: Heirloom | H15: Natural | I15: Filter Roast | J15: V60 | K15: 15 | L15: 220 | M15: 1:14.6 | N15: Unknown | O15: Unknown | P15: Mahlkönig EK43 | Q15: Unknown | R15: Blackcurrant; Strawberry; White Floral | S15: Bright, floral, and distinct strawberry; classic natural Ethiopian profile. | T15: EK43 98mm flat burrs reduced fines and preserved clarity despite natural processing; 1:14.6 ratio retained fruity body. | U15: Solo specialty calibration | V15: Merged (Gemini + ChatGPT) | W15: =IF(OR(ISNUMBER(SEARCH("gesha",G15)),ISNUMBER(SEARCH("geisha",G15))),"⭐ GESHA","")
A16: 46109 | B16: Singapore | C16: Tiong Hoe Specialty Coffee | D16: Brazil Mogiana | E16: Unknown | F16: Mogiana, Brazil | G16: Unknown | H16: Natural | I16: Medium | J16: Pour-over | K16: 15 | L16: 225 | M16: 1:15 | N16: Unknown | O16: Unknown | P16: Unknown | Q16: 8 | R16: Red Dates; Chocolates; Honey | S16: Chocolate-heavy and satisfying; classic dense Brazilian profile. | T16: Tighter 1:15 ratio increased body and amplified Maillard-derived caramel sweetness; medium roast caramelized sugars without losing origin character. | U16: Solo specialty calibration | V16: Merged (Gemini + ChatGPT) | W16: =IF(OR(ISNUMBER(SEARCH("gesha",G16)),ISNUMBER(SEARCH("geisha",G16))),"⭐ GESHA","")
A17: 46109 | B17: Singapore | C17: Tiong Hoe Specialty Coffee | D17: Smoky Quartz Blend | E17: Unknown | F17: Brazil + India | G17: Unknown | H17: Unknown | I17: Unknown | J17: Piccolo Latte | K17: Unknown | L17: Unknown | M17: Unknown | N17: Unknown | O17: Unknown | P17: Unknown | Q17: 5.1 | R17: Dark Chocolates; Hazelnut; Smoky | S17: Strong milk side calibration; excellent concentrated cocoa expression. | T17: Low milk volume in piccolo format concentrated cocoa and hazelnut compounds; cross-origin blend leveraged Indian robusta structural density. | U17: Solo specialty calibration | V17: ChatGPT only | W17: =IF(OR(ISNUMBER(SEARCH("gesha",G17)),ISNUMBER(SEARCH("geisha",G17))),"⭐ GESHA","")
A18: 46110 | B18: Singapore | C18: Asylum Coffeehouse | D18: Peru Cajamarca Gesha (Iced) | E18: Wilder Garcia | F18: Cajamarca, Peru | G18: Gesha | H18: Washed | I18: Medium | J18: Iced Pour-over | K18: 15 | L18: 240 | M18: 1:16 | N18: 92.5 | O18: Unknown | P18: Option-O Lagom P64 | Q18: 11 | R18: Jasmine; Caramel; Lime; Cacao Nibs | S18: Super floral and elegant; flash-chilled expression of Gesha purity. | T18: Flash-chilled extraction via Option-O Lagom P64 preserved volatile floral monoterpenes (linalool); cold dilution stabilized aromatic compounds. | U18: Solo specialty calibration | V18: ChatGPT only | W18: =IF(OR(ISNUMBER(SEARCH("gesha",G18)),ISNUMBER(SEARCH("geisha",G18))),"⭐ GESHA","")
A19: 46113 | B19: Singapore | C19: Maxi Coffee Bar | D19: La Laja | E19: James Fernandez | F19: Cauca, Colombia | G19: Sudan Rume | H19: Washed | I19: Light | J19: Pour-over (Flat-Bottom) | K19: 15 | L19: 230 | M19: 1:15.3 | N19: 90-92 | O19: Unknown | P19: FM Grinder 120mm Flat Burr / Timemore Sculptor 078 | Q19: 9 | R19: Raspberry; Nectarine; Floral | S19: Nectarine and raspberry extremely clear; barista sophistication superb; technical milestone. | T19: 120mm flat burr geometry maximized uniform particle distribution; flat-bottom brewer enhanced sweetness while preserving Sudan Rume's rare genetic clarity. | U19: CBD lunch calibration | V19: Merged (Gemini + ChatGPT) | W19: =IF(OR(ISNUMBER(SEARCH("gesha",G19)),ISNUMBER(SEARCH("geisha",G19))),"⭐ GESHA","")
A20: 46113 | B20: Singapore | C20: Lume Café | D20: Corpachi Panama Geisha | E20: Corpachi | F20: Boquerón, Chiriquí, Panama | G20: Geisha | H20: Red Honey | I20: Filter Roast | J20: V60 | K20: Unknown | L20: Unknown | M20: 1:15 | N20: 90 + 70 | O20: Unknown | P20: Mahlkönig EK43 | Q20: 12 | R20: Mandarin Candy; Jasmine; Apricot | S20: Clearly perceived apricot and structured sweetness. | T20: Dual-temperature extraction balanced aromatics and body in honey-process Geisha; red honey partial mucilage retention amplified structured sweetness. | U20: Rainy CBD lunch calibration | V20: ChatGPT only | W20: =IF(OR(ISNUMBER(SEARCH("gesha",G20)),ISNUMBER(SEARCH("geisha",G20))),"⭐ GESHA","")
A21: 46117 | B21: Singapore | C21: Asylum Coffeehouse | D21: Castillo Watermelon (Jairo Arcila) | E21: Jairo Arcila | F21: Armenia, Quindío, Colombia | G21: Castillo | H21: Washed Co-Ferment (Watermelon Anaerobic) | I21: Unknown | J21: Pour-over (V60) | K21: 15 | L21: 225 | M21: 1:15 | N21: 90 + 70 | O21: Unknown | P21: Mahlkönig EK43 | Q21: 12.5 | R21: Watermelon; Mint; Lime; Chocolate | S21: Distinct fruit-forward expression; sweetness layered rather than sharp; experimental but controlled. | T21: Watermelon co-fermentation enhanced volatile ester complexity; dual-temperature extraction preserved layered aromatic architecture. | U21: Father-daughter coffee session | V21: Merged (Gemini + ChatGPT) | W21: =IF(OR(ISNUMBER(SEARCH("gesha",G21)),ISNUMBER(SEARCH("geisha",G21))),"⭐ GESHA","")
A22: 46117 | B22: Singapore | C22: Asylum Coffeehouse | D22: Peru Gesha (Wilder Garcia) | E22: Wilder Garcia | F22: Jaén, Peru | G22: Gesha | H22: Washed | I22: Filter Roast | J22: Pour-over (V60) | K22: 15 | L22: 225 | M22: 1:15 | N22: 90 + 70 | O22: Unknown | P22: Mahlkönig EK43 | Q22: 12.5 | R22: Jasmine; Caramel; Lime; Cacao Nibs | S22: Clean, structured, high-clarity cup; apricot-like sweetness and excellent structure. | T22: Dual-temperature extraction engineered aromatic separation and body control; Gesha genetics delivered intrinsic phenolic complexity with minimal processing interference. | U22: Father-daughter coffee session | V22: Merged (Gemini + ChatGPT) | W22: =IF(OR(ISNUMBER(SEARCH("gesha",G22)),ISNUMBER(SEARCH("geisha",G22))),"⭐ GESHA","")
A23: 46120 | B23: Singapore | C23: Maxi Coffee Bar | D23: La Villa #1 | E23: Eduard Gaviria | F23: Huila, Colombia | G23: Papayo | H23: Natural | I23: Unknown | J23: Pour-over (Flat-Bottom) | K23: 15 | L23: 225 | M23: 1:15 | N23: Unknown | O23: Unknown | P23: Timemore Sculptor 078 | Q23: 9 | R23: Stewed Forest Berries; Grape; Black Forest Cake | S23: Dense fruit profile with rounded sweetness. | T23: Flat-bottom geometry and tight 1:15 ratio emphasized body; Papayo varietal's high sugar content amplified by natural processing into rich fruit-cake profile. | U23: Lunch catch-up with Yichen | V23: ChatGPT only | W23: =IF(OR(ISNUMBER(SEARCH("gesha",G23)),ISNUMBER(SEARCH("geisha",G23))),"⭐ GESHA","")
A24: 46130 | B24: Johor Bahru | C24: Clod Coffee Bar & Roasters | D24: Hacienda La Florida | E24: Unknown | F24: Unknown | G24: Typica Mejorado | H24: Anaerobic Washed | I24: Unknown | J24: Origami (Conical) | K24: 18 | L24: 277 | M24: 1:15.4 | N24: Unknown | O24: 42g / 30s (1:2.3) | P24: Mahlkönig EK Omnia | Q24: 11.08 | R24: Lemon verbena; Red plum; Citronella; Hibiscus | S24: Excellent. Lime when hot, distinct plum as it cooled. | T24: EK Omnia precision grind and Origami conical drove extreme clarity; thermal phase shift perfectly isolated citric-to-malic acid transition (lime → plum). | U24: Unknown | V24: Gemini only | W24: =IF(OR(ISNUMBER(SEARCH("gesha",G24)),ISNUMBER(SEARCH("geisha",G24))),"⭐ GESHA","")
A25: 46136 | B25: Singapore | C25: Agora Coffee | D25: Brazil Santuário Sul | E25: Unknown | F25: Carmo de Minas, Brazil | G25: Unknown | H25: Natural Fermentation | I25: Light-Medium | J25: V60 | K25: 16 | L25: 224 | M25: 1:14 | N25: 95 | O25: Unknown | P25: Mahlkönig EK43 | Q25: Unknown | R25: Blackcurrant; Black Cherry; Dark Chocolate | S25: Full body; prominent blackcurrant; clear chocolaty finish. | T25: Tight 1:14 ratio engineered maximum body; EK43 98mm burrs maintained clarity to keep fermented natural fruit clean and non-bitter. | U25: Midday specialty calibration | V25: Merged (Gemini + ChatGPT) | W25: =IF(OR(ISNUMBER(SEARCH("gesha",G25)),ISNUMBER(SEARCH("geisha",G25))),"⭐ GESHA","")
A26: 46148 | B26: Singapore | C26: Nylon Coffee Roasters | D26: Brazil FAF Organic | E26: Unknown | F26: Brazil | G26: Arara | H26: Natural | I26: Filter Roast | J26: xBloom (Flat-Bottom) | K26: Unknown | L26: Unknown | M26: 1:17 | N26: Unknown | O26: Unknown | P26: Mahlkönig EK Omnia | Q26: 7.5 | R26: Red Apple; Cherry; Raisin; Milk Chocolate | S26: Solid body with crisp green apple (malic) front, resolving into smooth milk chocolate finish. | T26: High-quality Arara natural processing yielded excellent structural body while maintaining crisp malic acidity; xBloom flat-bottom avoided heavy fermentation mud. | U26: Unknown | V26: Gemini only | W26: =IF(OR(ISNUMBER(SEARCH("gesha",G26)),ISNUMBER(SEARCH("geisha",G26))),"⭐ GESHA","")
A27: 46148 | B27: Singapore | C27: Nylon Coffee Roasters | D27: Brazil Serra dos Ciganos | E27: Unknown | F27: Brazil | G27: Catucai 24/137 | H27: Natural | I27: Espresso Roast | J27: Flat White | K27: Unknown | L27: Unknown | M27: Unknown | N27: Unknown | O27: Unknown | P27: Unknown | Q27: Unknown | R27: Sultana; Dried Apricot; Praline; Roasted Hazelnut | S27: Good cup with pleasant lingering sweet aftertaste. | T27: Milk fats bound perfectly with natural processed espresso; Catucai 24/137 high-density bean structure created long, comforting finish. | U27: Unknown | V27: Gemini only | W27: =IF(OR(ISNUMBER(SEARCH("gesha",G27)),ISNUMBER(SEARCH("geisha",G27))),"⭐ GESHA","")
A28: 46149 | B28: Singapore | C28: Nylon Coffee Roasters | D28: Ethiopia Banko Gotiti | E28: Unknown | F28: Ethiopia | G28: Heirloom | H28: Washed | I28: Filter Roast | J28: xBloom (Flat-Bottom) | K28: Unknown | L28: Unknown | M28: 1:17 | N28: Unknown | O28: Unknown | P28: Mahlkönig EK Omnia | Q28: 8.5 | R28: Lemonade; Raspberry; Peach; Bergamot | S28: Lemon front, heavy melon mid-cup, fading into clean white tea finish. | T28: 1:17 lean ratio isolated volatile citric acids; xBloom flat-bottom geometry stabilized mid-cup sugars before clean tannin-forward white tea finish. | U28: Unknown | V28: Gemini only | W28: =IF(OR(ISNUMBER(SEARCH("gesha",G28)),ISNUMBER(SEARCH("geisha",G28))),"⭐ GESHA","")
A29: 46149 | B29: Singapore | C29: Nylon Coffee Roasters | D29: Nicaragua Buena Vista | E29: Unknown | F29: Nicaragua | G29: Parainema | H29: Natural Anaerobic | I29: Espresso Roast | J29: Single Espresso | K29: Unknown | L29: Unknown | M29: ~1:2 | N29: Unknown | O29: Unknown | P29: Unknown | Q29: Unknown | R29: Chiku; Stewed Cherry; Dried Apricot; Brazil Nut | S29: Thick, syrupy body. Highly fermented, savory/not sweet, very long lingering finish. | T29: Anaerobic fermentation metabolized sugars into complex savory esters; 9-bar pressure emulsification drove heavy oil-based viscosity and extended aftertaste. | U29: Unknown | V29: Gemini only | W29: =IF(OR(ISNUMBER(SEARCH("gesha",G29)),ISNUMBER(SEARCH("geisha",G29))),"⭐ GESHA","")
A30: 46150 | B30: Singapore | C30: Alchemist (Raffles Place) | D30: El Morito | E30: Unknown | F30: Colombia | G30: Marshell | H30: Washed | I30: Filter Roast | J30: V60 Pour-over (Conical) | K30: 15 | L30: 240 | M30: 1:16 | N30: Unknown | O30: Unknown | P30: Mahlkönig EK43S (98mm Flat Burr) | Q30: Unknown | R30: Yellow Plum; Orange; Cane Sugar | S30: Simultaneous citric-malic acid overlap with integrated cane sugar — smooth and refreshing with excellent mid-palate juiciness. Confirmed: I love this bean. | T30: EK43S 98mm flat burrs + V60 conical at 1:16 delivered perfect dual-acid integration (citric orange + malic plum) without single-note dominance. Sucrose extraction at 1:16 bridged acid structure into clean cane sugar finish. Marshell is an extremely rare Colombian varietal — natural mutation prized for simultaneous citric-malic acid duality. | U30: Solo visit — Alchemist Raffles Place | V30: Master CSV (hari_coffee_audit_master_2026) | W30: =IF(OR(ISNUMBER(SEARCH("gesha",G30)),ISNUMBER(SEARCH("geisha",G30))),"⭐ GESHA","")
A31: 46154 | B31: Singapore | C31: Kurasu | D31: Indonesia Frinsa Estate | E31: Frinsa Estate | F31: West Java, Indonesia | G31: Local Varietals | H31: Extended Fermentation Honey | I31: Light | J31: Pour-over (Hario Alpha — Flat-Bottom) | K31: 15 | L31: 225 | M31: 1:16 | N31: 80 → 95 → 80 | O31: Unknown | P31: Mahlkönig EK43S (98mm Flat Burr) | Q31: 9.5 | R31: Floral aroma; Stewed Strawberries; Grapefruit; Brown Sugar; Black Tea | S31: Floral taste with a sweet coating on the tongue that gradually sticks and fades off cleanly — sugar and tea aftertaste. Well-executed Indonesian honey with unusual clarity for the origin. | T31: Multi-temperature pour (80→95→80°C) with Hario Alpha flat-bottom perfectly managed heavy honey-process mucilage sugars — clear floral extraction at lower temps, dissolving jammy mucilage at peak heat, finishing cleanly. Extended fermentation honey adds structured sweetness without heavy ferment-funk. First Indonesian-mainland entry in archive (distinct from Bali entries). | U31: Solo visit — Kurasu Singapore | V31: Master CSV (hari_coffee_audit_master_2026) | W31: =IF(OR(ISNUMBER(SEARCH("gesha",G31)),ISNUMBER(SEARCH("geisha",G31))),"⭐ GESHA","")
A32: 46155 | B32: Singapore | C32: The Community Coffee (Hamilton) | D32: Jose Mancia Honduras | E32: Jose Mancia | F32: Honduras | G32: Typica | H32: Natural | I32: Filter Roast | J32: Pour-over (Hario Switch — Immersion/Percolation) | K32: 15 | L32: 255 | M32: 1:17 | N32: Unknown | O32: Unknown | P32: Mahlkönig EK43 (98mm Flat Burr) | Q32: 9 | R32: Kiwi; Oolong Tea; Chocolate Truffle | S32: Pretty good. Kiwi and oolong tea style — full bodied. Short finish with slight hints of chocolate. Clean and approachable natural without heavy fermentation noise. | T32: Typica inherent lipid clarity + raised-bed drying produced clean tea-structure body. EK43 98mm flat burrs + Hario Switch immersion phase stabilised full mouthfeel at lean 1:17. Short finish consistent with 15-days-off-roast volatile taper — kiwi and oolong top notes fade rapidly. Honduras Typica at altitude expresses tea-like clarity atypical of natural-process expectations. | U32: Solo visit — The Community Coffee Hamilton | V32: Master CSV (hari_coffee_audit_master_2026) | W32: =IF(OR(ISNUMBER(SEARCH("gesha",G32)),ISNUMBER(SEARCH("geisha",G32))),"⭐ GESHA","")
A33: 46157 | B33: Singapore | C33: Alchemist (Ocean Financial Centre) | D33: Ijen Laurina | E33: Ijen Plateau | F33: East Java, Indonesia | G33: Hybrid Laurina | H33: Anaerobic Natural | I33: Light | J33: V60 Pour-over (Conical) | K33: 15 | L33: 240 | M33: 1:16 | N33: 90 | O33: Unknown | P33: Mahlkönig EK43S (98mm Flat Burr) | Q33: 8.5 | R33: Hibiscus; Red Apple; Hawthorn | S33: Felt hibiscus hot. Mid temp showed apple paste. Cooled to a honeyed character. Full bodied. Textbook style flavours — definitely a good one. Clean progressive thermal arc. | T33: 90°C brew temp suppressed lactic ester over-extraction while preserving volatile anthocyanin hibiscus esters. Laurina low-caffeine mutation allows intrinsic sucrose to express as clean honeyed finish without alkaloid bitterness. Anaerobic Natural transformed malic acid into jammy apple paste mid-phase. First Hybrid Laurina varietal in archive — new genetic category unlocked. Hibiscus = anthocyanin; Apple paste = malic lactone; Honey = sucrose at sub-50°C. | U33: Solo visit — Alchemist Ocean Financial Centre | V33: Master CSV (hari_coffee_audit_master_2026) | W33: =IF(OR(ISNUMBER(SEARCH("gesha",G33)),ISNUMBER(SEARCH("geisha",G33))),"⭐ GESHA","")
A34: 46158 | B34: Singapore | C34: Fluid Collective | D34: El Obraje | E34: El Obraje | F34: Huila, Colombia | G34: Gesha | H34: Washed | I34: Light | J34: Flatbed Dripper (Flat-Bottom) | K34: 15 | L34: 230 | M34: 1:15.3 | N34: 92 | O34: Unknown | P34: Option-O Lagom P64 (64mm Flat Burr) | Q34: 14 | R34: Mango; Orange Blossom; Nectarine; Honey | S34: Damn the taste so nice — the orange nectarine finishing with that honey is terrific. Love this one. So far my favourite. Honey sweetness lingers and taste changes as temperature cools. Best Gesha washed in archive at time of logging. | T34: Lagom P64 64mm flat burrs deliver near-unimodal particle distribution — same hardware platform as Asylum Coffeehouse entries, enabling pure terroir delta comparison between Colombia Gesha (El Obraje, Huila) and Peru Gesha (Wilder Garcia, Jaén). 92°C at 1:15.3 maximised linalool floral ester retention while stabilising malic acid mango-nectarine backbone. Flat-bottom eliminated bypass and ensured even bed saturation — critical for preserving fragile Gesha aromatics. Honey finish = sucrose preserved at washed-process mucilage removal stage. | U34: Solo visit — FLUID Singapore | V34: Master CSV (hari_coffee_audit_master_2026) | W34: =IF(OR(ISNUMBER(SEARCH("gesha",G34)),ISNUMBER(SEARCH("geisha",G34))),"⭐ GESHA","")
A35: 46161 | B35: Singapore | C35: Pocket by Flip (Flip Coffee Roasters) | D35: Ecuador La Papaya | E35: La Papaya Farm | F35: Loja, Ecuador | G35: Geisha | H35: Washed | I35: Light | J35: Filter Hot — Flat-Bottom (Hario Alpha) | K35: 15 | L35: 225 | M35: 1:15 | N35: 92 → 75 → 92 | O35: Unknown | P35: Mahlkönig CORE (54mm Flat Burr) | Q35: 18 | R35: Fresh Apricot; Rooibos; Lemon Thyme; Toffee Apple | S35: Opening: tartaric apricot + rooibos aspalathin. Mid: thymol terpene coat — lipid-binding, persistent to midway. Cooling: malic apple shift + caramelised sucrose. Clean transparent fade. No linalool/jasmine — terpene-forward character distinct from Peru Geisha entries. Highest-altitude Geisha in archive at 2,100 MASL. | T35: Triple-temp cascade (92→75→92°C) on CORE 54mm flat burr + Hario Alpha flat-bottom preserved heat-sensitive thymol terpenes from 2,100 MASL Loja terroir. 75°C mid-pour is the critical terpene-stabilisation variable — thymol is lipid-binding and volatile above 80°C, so mid-temp pour is the architecture delivering the persistent midpalate coat. Ecuador Geisha = terpene-forward (Thymol/Aspalathin) clearly differentiated from linalool-forward Peru Geisha (Jasmine/Citric). First Ecuador-origin entry in archive. | U35: Solo visit — Pocket by Flip, 30 Stevens Road | V35: Master CSV (hari_coffee_audit_master_2026) | W35: =IF(OR(ISNUMBER(SEARCH("gesha",G35)),ISNUMBER(SEARCH("geisha",G35))),"⭐ GESHA","")
A36: 46168 | B36: Singapore | C36: Zerah Roasters | D36: El Diviso — Caturra Chiroso (Ester Bomb) | E36: El Diviso Farm | F36: Huila, Colombia | G36: Caturra Chiroso | H36: Yeast Anaerobic Natural | I36: Filter Roast | J36: Flat-Bottom Dripper | K36: 15 | L36: 240 | M36: 1:16 | N36: 92 | O36: 38g / Unknown seconds | P36: DF64 Gen 2 (64mm Flat Burr — aftermarket upgrade) | Q36: 12 | R36: Passionfruit; Plum Wine; Mango | S36: Goddamn the smell is intense. Flavor burst — acid or strong flavor, super punchy. Passionfruit with enhanced fruit, funky. Plums. After cooling — sugars came out. Interesting. Strong flavor gone. Overall: funky, fermentation-driven. Processing-dominant cup. Three completely different cups in one — ester detonation hot, funk phase mid, mango sweetness cool. | T36: Yeast strains WLPU07 + LALVIN 71B at 96hr fermentation, pH 3.72, 100% anaerobic sealed tank (1.2 bar, 23.4°C) produced extreme ester complexity: γ-decalactone (passionfruit lactone) dominant hot, tartaric esters + acetic acid (plum wine/funk) mid, fructose ester chains (mango sweetness) cold. 1:16 lean ratio was critical safety valve — prevented cloying ester overload and enabled three-phase thermal tracking. Flat-bottom geometry amplified body and even bed saturation. DF64 Gen 2 with aftermarket 64mm flat burrs: first DF64 platform entry in archive. Caturra Chiroso = elongated cell structure, Geisha-adjacent clarity potential overridden by fermentation intensity. Yeast Anaerobic Natural distinct process category from Wild Anaerobic. | U36: Solo visit — Zerah Roasters, Singapore, 26 May 2026. Barista explained fermentation process, flat-bottom geometry rationale, 1:16 ratio decision in detail. Warm educational session on 2nd floor cosy space. Barista recommended Glyph Supply Co (Jurong). | V36: Infographic (Entry #025 Ester Bomb) + Google Maps review + Google review authored by Hari | W36: =IF(OR(ISNUMBER(SEARCH("gesha",G36)),ISNUMBER(SEARCH("geisha",G36))),"⭐ GESHA","")
A37: 46183 | B37: Singapore | C37: Nylon Coffee Roasters | D37: Colombia Juan Martin | E37: Banexport | F37: Colombia | G37: Red Striped Bourbon | H37: Washed | I37: Filter Roast | J37: xBloom (Flat-Bottom) | K37: Unknown | L37: Unknown | M37: 1:17 | N37: Unknown | O37: Unknown | P37: Mahlkönig EK Omnia (98mm Flat Burr) | Q37: 7.5 | R37: Berry, Red Plum, Nectarine, Orange Tea | S37: Orange-type aromatic afterfeel when hot — bright and encapsulating. Clearly fruity character throughout. Mellows cleanly as it cools; sugars emerge distinctly at mid-cool phase. Nice and light overall — 1:17 lean ratio working well on this varietal. | T37: EK Omnia 98mm flat burrs + xBloom flat-bottom geometry maintained body integrity at 1:17 lean ratio. Retail bag on shelf dated 10 Jun 2026 but filter batch roast date unconfirmed — cup behaviour (clean sugar emergence, well-integrated stone fruit at cool phase) is consistent with a properly rested lot of 10–21 days post-roast. Red Striped Bourbon sucrose density confirmed by clean sweetness at cool phase. | U37: Solo visit — office lunch break, 13:15 | V37: Direct observation + bag photo (retail stock) | W37: =IF(OR(ISNUMBER(SEARCH("gesha",G37)),ISNUMBER(SEARCH("geisha",G37))),"⭐ GESHA","")
A38: 46186 | B38: Singapore | C38: Kurasu | D38: Rwanda Nkara Soil Project Lot 1204 | E38: Nkara Soil Project | F38: Rwanda | G38: Red Bourbon | H38: Fully Washed | I38: Filter Roast | J38: V60 Pour-over (Conical) | K38: Unknown | L38: Unknown | M38: Unknown | N38: Unknown | O38: Unknown | P38: Mahlkönig EK43 (98mm Flat Burr) | Q38: 9.27 | R38: Floral aroma, taste of mandarin orange, baked apple and grapefruit, brown sugar-like sweetness and accompanying aftertaste | S38: Strong aftertaste with slight bitterness noted. Baked apple taste dominates and persists across all phases. Sugars emerge clearly on cooling — brown sugar sweetness confirmed at cool phase. Rated average. Rwanda Nkara terroir pushes more citrus-floral (mandarin/grapefruit) vs prior Rwanda entry at Twenty Grams (Entry #024) which was peach/stone fruit dominant. | T38: EK43 98mm flat burrs paired with conical V60 geometry — key hardware distinction vs prior Kurasu Frinsa entry. V60 conical creates faster flow rate and higher bypass risk vs flat-bottom; the slight bitterness is consistent with conical geometry allowing fine particles to over-extract at the drain. Washed Red Bourbon at altitude delivers classic Rwandan citric-malic duality (mandarin + baked apple). Baked apple dominance = malic acid thermally stabilised — persists across full thermal arc unlike volatile citric top notes which fade. Brown sugar aftertaste is sucrose retention signature of Red Bourbon genetics. | U38: Solo visit — 13 Jun 2026 | V38: Direct observation + bean card photo | W38: =IF(OR(ISNUMBER(SEARCH("gesha",G38)),ISNUMBER(SEARCH("geisha",G38))),"⭐ GESHA","")
A39: 46187 | B39: Singapore | C39: Keryi Coffee | D39: Colombia Finca La Esmaralda | E39: Finca La Esmaralda | F39: Colombia | G39: Gesha | H39: Honey | I39: Light Roast | J39: Hario Switch (Immersion/Percolation Hybrid) | K39: 15 | L39: 210 | M39: 1:14 | N39: 91 → 78 | O39: 60g (~4:1) | P39: Ditting 98mm flat burr | Q39: 15 | R39: Citrus, white florals, lychee, sugar-cane sweetness | S39: Smooth body throughout. Lychee & white florals lead in the hot phase — fragile linalool terpenes survived the tight 1:14 concentration. Citrus surfaces mid-cool as perceived sweetness rises; honey-derived sweetness rounds the cool-phase finish into progressive smoothness. Rated highly — a fine, relaxing Gesha. Clarity held; upper Gesha tier (cf. El Obraje washed favourite, Hiu Los Lajones honey Panama). | T39: Ditting 98mm flat burrs deliver lab-grade narrow particle distribution with minimal fines — the key variable licensing an aggressive 1:14 ratio without astringency. Descending pour (91°C bloom/first pour → 78°C final) uses temperature as a brake on the extraction tail: high heat early extracts volatile terpenes, acids & sugars; the cool final pour reaches target volume while suppressing late-stage chlorogenic-acid bitterness. Hario Switch valve-closed immersion develops honey-process mucilage sweetness & body evenly before percolative drain adds finish definition — conical geometry runs against the flat-bottom affinity but suits this process. | U39: Solo relaxation visit — Sunday 14 Jun 2026, 11 AM; barista-led brew interview (grinder/ratio/temp confirmed) | V39: Direct observation + menu photo + barista interview | W39: =IF(OR(ISNUMBER(SEARCH("gesha",G39)),ISNUMBER(SEARCH("geisha",G39))),"⭐ GESHA","")
A40: 46192 | B40: Singapore | C40: Corner Corner | D40: Malaysia My Liberica | E40: My Liberica (Jason Liew), Kulai, Johor | F40: Malaysia, Kulai, Johor | G40: Liberica (Coffea liberica) | H40: JH Natural (Jekyll & Hyde controlled fermentation - proprietary My Liberica process) | I40: Light | J40: Pour Over (filter) | K40: 13 | L40: 190 | M40: 1:14.6 | N40: 90-92 (steady throughout) | O40: Unknown | P40: Timemore (conical Gold burr, coarse) | Q40: 13 | R40: Root beer / Tropical fruit punch / Raspberry candy / Rambutan / Longan / Sarsi (roaster: One Half) | S40: Interesting and approachable - 'not so funky but different for sure'; picked out longan-type fruit. First non-arabica capture in the archive; landed as a positive novelty rather than rejected. | T40: First Liberica (Coffea liberica) and first Malaysia/Johor origin in archive; near-sea-level farm (26-30 MASL). Low 13g dose at ~1:14.6 ratio with steady 90-92C and a conical Timemore Gold burr deliberately tames Liberica's smoky-woody funk into a cleaner, longan-forward cup; the small dose + generous water dilutes intensity for legibility. NOTE: barista verbally cited ~1:16, but stated 13g:190g computes to 1:14.6. | U40: Roaster: One Half (light-roast filter program). Corner Corner is a vinyl-record listening bar/cafe; walls of LPs, warm low lighting, Japanese-style carafe-and-cup serve. Friday 19 June 2026, ~15:15. Rated awesome by Hari. | V40: Field audit (Claude) | W40: =IF(OR(ISNUMBER(SEARCH("gesha",G40)),ISNUMBER(SEARCH("geisha",G40))),"⭐ GESHA","")
...

Sheet ☕ Dashboard
B1: ☕ THE HARI COFFEE ARCHIVE — 2026
B2: A Master Extraction Archivist's living record · Singapore · Bali · Mumbai · Johor Bahru
B4: 📊 ARCHIVE VITALS — live formulas, auto-update with every new entry
B6: TOTAL ENTRIES | C6: UNIQUE CAFÉS | D6: CITIES | E6: ORIGIN LOTS | F6: GESHA CUPS | G6: VARIETALS | H6: AVG SGD | I6: FIRST ENTRY | J6: LATEST ENTRY
B7: =COUNTA('Coffee Audit'!A2:A2000) | C7: =SUMPRODUCT(('Coffee Audit'!C2:C2000<>"")/COUNTIF('Coffee Audit'!C2:C2000,'Coffee Audit'!C2:C2000&"")) | D7: =SUMPRODUCT(('Coffee Audit'!B2:B2000<>"")/COUNTIF('Coffee Audit'!B2:B2000,'Coffee Audit'!B2:B2000&"")) | E7: =SUMPRODUCT(('Coffee Audit'!F2:F2000<>"")/COUNTIF('Coffee Audit'!F2:F2000,'Coffee Audit'!F2:F2000&"")) | F7: =COUNTIF('Coffee Audit'!W2:W2000,"⭐ GESHA") | G7: =SUMPRODUCT(('Coffee Audit'!G2:G2000<>"")/COUNTIF('Coffee Audit'!G2:G2000,'Coffee Audit'!G2:G2000&"")) | H7: =AVERAGEIF('Coffee Audit'!Q2:Q2000,">0") | I7: =TEXT(MIN('Coffee Audit'!A2:A2000),"DD MMM") | J7: =TEXT(MAX('Coffee Audit'!A2:A2000),"DD MMM YYYY")
B9: 📖 THE ARCHIVE THESIS
B10: Fifty-nine cups. Thirty-three cafés. Four cities. One palate, decoded in three thermal phases. This archive is a longitudinal study of a single palate: washed-process clarity over fermentation complexity, malic acid and linalool as the north stars, flat burrs and flat-bottom geometry as the preferred physics. Every entry is a field audit — hardware identified, parameters confirmed with the barista where offered, sensory record kept across HOT, MID-COOL and COOL. The data shows a palate that rewards precision: Gesha remains the apex varietal (12 entries), Colombia and Ethiopia the dominant origins, and the archive's verdicts consistently favour cups where process serves terroir rather than replacing it.
B16: 🏆 ARCHIVE HONOURS BOARD
B17: Honour | C17: Holder | D17: Detail
B18: Cup of the Year (to date) | C18: Fluid Collective — Gesha lineage | D18: Thermal-oscillation protocol; National Brewers Cup champion bar
B19: Friendliest Baristas (joint) | C19: Aqil — Zerah Roasters · Glenda — Abseil | D19: Joint #1 across all 59 audits
B20: Most Audited Café | C20: Nylon Coffee Roasters | D20: Reliability anchor of the archive
B21: Best Value Discovery | C21: Oaks Coffee Co. — Floripondio 90 Hours | D21: SGD 9 · Bolivia Pacamara Lactic Honey · café Day 4
B22: Boldest Process Encountered | C22: Finca El Diviso — Thermal Shock Anaerobic | D22: Nestor Lasso · palate threshold boundary confirmed
B23: Process Trilogy Completed | C23: Colombia Gesha — Washed/Honey/Natural | D23: Fluid Collective · Keryi · Homeground

Sheet 🧬 Palate DNA
B1: 🧬 PALATE DNA — PROCESS · GEOMETRY · RATIO
B2: Clarity > Complexity · washed-dominant · flat-bottom preferred · 1:15–1:17 band
B4: 🧪 PROCESS DISTRIBUTION — what the palate actually drank
B5: Process family | C5: Entries | D5: Share
B6: Washed | C6: =COUNTIF('Coffee Audit'!H2:H2000,"*Washed*") | D6: =C6/COUNTA('Coffee Audit'!H2:H2000)
B7: Natural | C7: =COUNTIF('Coffee Audit'!H2:H2000,"*Natural*") | D7: =C7/COUNTA('Coffee Audit'!H2:H2000)
B8: Honey | C8: =COUNTIF('Coffee Audit'!H2:H2000,"*Honey*") | D8: =C8/COUNTA('Coffee Audit'!H2:H2000)
B9: Anaerobic | C9: =COUNTIF('Coffee Audit'!H2:H2000,"*Anaerobic*") | D9: =C9/COUNTA('Coffee Audit'!H2:H2000)
B10: Lactic | C10: =COUNTIF('Coffee Audit'!H2:H2000,"*Lactic*") | D10: =C10/COUNTA('Coffee Audit'!H2:H2000)
B11: Thermal Shock | C11: =COUNTIF('Coffee Audit'!H2:H2000,"*Thermal Shock*") | D11: =C11/COUNTA('Coffee Audit'!H2:H2000)
B12: Wet-Hulled | C12: =COUNTIF('Coffee Audit'!H2:H2000,"*Wet-Hulled*") | D12: =C12/COUNTA('Coffee Audit'!H2:H2000)
B13: Experimental | C13: =COUNTIF('Coffee Audit'!H2:H2000,"*Experimental*") | D13: =C13/COUNTA('Coffee Audit'!H2:H2000)
B14: Note: families overlap (e.g. "Anaerobic Natural" counts in both) — this maps palate exposure, not exclusive buckets.
B22: 📐 BREWER GEOMETRY — the flat-bottom thesis
B23: Geometry | C23: Entries | D23: Archive verdict
B24: Flat-bottom / flatbed | C24: =COUNTIF('Coffee Audit'!J2:J2000,"*Flat*") | D24: Preferred — even bed saturation, zero bypass
B25: Conical (V60 family) | C25: =COUNTIF('Coffee Audit'!J2:J2000,"*V60*")+COUNTIF('Coffee Audit'!J2:J2000,"*Conical*") | D25: ⚠ Over-extraction risk flag — documented repeatedly
B26: Engineered conical (CT62) | C26: =COUNTIF('Coffee Audit'!J2:J2000,"*CT62*") | D26: Own category — 24-groove flow compensation earns exemption
B27: Immersion / hybrid | C27: =COUNTIF('Coffee Audit'!J2:J2000,"*Immersion*")+COUNTIF('Coffee Audit'!J2:J2000,"*Switch*")+COUNTIF('Coffee Audit'!J2:J2000,"*AeroPress*") | D27: Occasional — body over clarity
B28: Espresso-based | C28: =COUNTIF('Coffee Audit'!J2:J2000,"*Espresso*") | D28: Companion / milk calibration entries
B30: ⚖️ RATIO BAND — 1:15–1:17 optimal window
B31: Ratio | C31: Entries | D31: Chemistry note
B32: 1:13–1:14 (concentrated) | C32: =COUNTIF('Coffee Audit'!M2:M2000,"1:13*")+COUNTIF('Coffee Audit'!M2:M2000,"1:14*") | D32: Amplifies polyphenolic bitterness at cool phase; suppresses sucrose — documented at Double Shot & Equate
B33: 1:15 (archive default) | C33: =COUNTIF('Coffee Audit'!M2:M2000,"1:15*") | D33: Default assumption 15g/225g — sweet-spot density
B34: 1:16 | C34: =COUNTIF('Coffee Audit'!M2:M2000,"1:16*") | D34: Most common café service ratio in the archive
B35: 1:17 (lean) | C35: =COUNTIF('Coffee Audit'!M2:M2000,"1:17*") | D35: Risk: insufficient sucrose-ester mass vs CGA lactone bitterness on naturals

Sheet 🌍 Origin & Terroir
B1: 🌍 ORIGIN & TERROIR ATLAS
B2: Where the archive has travelled — by bean, not by boarding pass
B4: 🗺️ ORIGIN LEAGUE TABLE
B5: Origin | C5: Entries | D5: Share
B6: Colombia | C6: =COUNTIF('Coffee Audit'!F2:F2000,"*Colombia*") | D6: =C6/COUNTA('Coffee Audit'!F2:F2000)
B7: Ethiopia | C7: =COUNTIF('Coffee Audit'!F2:F2000,"*Ethiopia*") | D7: =C7/COUNTA('Coffee Audit'!F2:F2000)
B8: Panama | C8: =COUNTIF('Coffee Audit'!F2:F2000,"*Panama*") | D8: =C8/COUNTA('Coffee Audit'!F2:F2000)
B9: Kenya | C9: =COUNTIF('Coffee Audit'!F2:F2000,"*Kenya*") | D9: =C9/COUNTA('Coffee Audit'!F2:F2000)
B10: Bolivia | C10: =COUNTIF('Coffee Audit'!F2:F2000,"*Bolivia*") | D10: =C10/COUNTA('Coffee Audit'!F2:F2000)
B11: Honduras | C11: =COUNTIF('Coffee Audit'!F2:F2000,"*Honduras*") | D11: =C11/COUNTA('Coffee Audit'!F2:F2000)
B12: India | C12: =COUNTIF('Coffee Audit'!F2:F2000,"*India*") | D12: =C12/COUNTA('Coffee Audit'!F2:F2000)
B13: Indonesia | C13: =COUNTIF('Coffee Audit'!F2:F2000,"*Indonesia*") | D13: =C13/COUNTA('Coffee Audit'!F2:F2000)
B14: Peru | C14: =COUNTIF('Coffee Audit'!F2:F2000,"*Peru*") | D14: =C14/COUNTA('Coffee Audit'!F2:F2000)
B15: Brazil | C15: =COUNTIF('Coffee Audit'!F2:F2000,"*Brazil*") | D15: =C15/COUNTA('Coffee Audit'!F2:F2000)
B16: El Salvador | C16: =COUNTIF('Coffee Audit'!F2:F2000,"*El Salvador*") | D16: =C16/COUNTA('Coffee Audit'!F2:F2000)
B17: Myanmar | C17: =COUNTIF('Coffee Audit'!F2:F2000,"*Myanmar*") | D17: =C17/COUNTA('Coffee Audit'!F2:F2000)
B18: China | C18: =COUNTIF('Coffee Audit'!F2:F2000,"*China*") | D18: =C18/COUNTA('Coffee Audit'!F2:F2000)
B19: Ecuador | C19: =COUNTIF('Coffee Audit'!F2:F2000,"*Ecuador*") | D19: =C19/COUNTA('Coffee Audit'!F2:F2000)
B20: Rwanda | C20: =COUNTIF('Coffee Audit'!F2:F2000,"*Rwanda*") | D20: =C20/COUNTA('Coffee Audit'!F2:F2000)
B22: ⭐ THE GESHA REGISTER — apex varietal tracker
B23: Metric | C23: Value
B24: Total Gesha/Geisha entries | C24: =COUNTIF('Coffee Audit'!W2:W2000,"⭐ GESHA")
B25: Washed Gesha | C25: =SUMPRODUCT(('Coffee Audit'!W2:W2000="⭐ GESHA")*(ISNUMBER(SEARCH("washed",'Coffee Audit'!H2:H2000))))
B26: Honey Gesha | C26: =SUMPRODUCT(('Coffee Audit'!W2:W2000="⭐ GESHA")*(ISNUMBER(SEARCH("honey",'Coffee Audit'!H2:H2000))))
B27: Natural Gesha | C27: =SUMPRODUCT(('Coffee Audit'!W2:W2000="⭐ GESHA")*(ISNUMBER(SEARCH("natural",'Coffee Audit'!H2:H2000))))
B28: Avg Gesha price (SGD) | C28: =ROUND(AVERAGEIFS('Coffee Audit'!Q2:Q2000,'Coffee Audit'!W2:W2000,"⭐ GESHA",'Coffee Audit'!Q2:Q2000,">0"),2)
B29: Botanical note: "Gesha" (Gesha forest, Ethiopia) is the correct spelling; "Geisha" is the Panamanian commercial transliteration. The archive tracks both.
B31: 🎯 REMAINING VARIETAL TARGETS
B32: Eugenioides | C32: ❌ MISSING — highest-priority varietal target
B33: Laurina | C33: ✅ Captured — Entry #025
B34: Sudan Rume | C34: ✅ Captured — Entry #038
B35: Aji Bourbon | C35: ✅ Captured — Entry #059 (Oaks, Finca El Diviso)
B36: Pacamara | C36: ✅ Captured — Entry #049 (Oaks, Floripondio)

Sheet ⚙️ Hardware & Extraction
B1: ⚙️ HARDWARE & EXTRACTION PHYSICS
B2: Flat burrs, flat beds, and the physics of clarity
B4: 🔩 GRINDER PLATFORM REGISTER
B5: Platform family | C5: Entries | D5: Note
B6: Option-O Lagom (P64/P80) | C6: =COUNTIF('Coffee Audit'!P2:P2000,"*Lagom*") | D6: Preferred precision platforms — P80 debuted at Oaks (Entry #049)
B7: EK43 / Mahlkönig | C7: =COUNTIF('Coffee Audit'!P2:P2000,"*EK43*")+COUNTIF('Coffee Audit'!P2:P2000,"*Mahlk*") | D7: Café workhorse — 98mm vertical flat
B8: Timemore Sculptor | C8: =COUNTIF('Coffee Audit'!P2:P2000,"*Sculptor*") | D8: 064/078 series
B9: DF series | C9: =COUNTIF('Coffee Audit'!P2:P2000,"*DF*") | D9: DF83V at Zerah — 83mm flat
B10: 120mm hybrid/flat | C10: =COUNTIF('Coffee Audit'!P2:P2000,"*120*") | D10: Kyuukei & Maxi — large-format clarity
B11: Unknown / unrecorded | C11: =COUNTIF('Coffee Audit'!P2:P2000,"Unknown") | D11: Early entries pre-hardware-protocol
B13: 🌡️ TEMPERATURE DOCTRINE
B14: Protocol | C14: Where & why
B15: 88°C constant | C15: LAB-ferment ester preservation — Oaks protocol for lactic honey
B16: 90–93°C standard | C16: Washed-lot default across the archive
B17: Thermal oscillation 70→90→70 | C17: Fluid Collective signature — barista-confirmed across all visits
B18: Dual-temp 90+70 | C18: Lume Café honey-Geisha aromatics/body split
B20: 📜 EXTRACTION LAWS — patterns the archive has proven
B21: 1. Flat-bottom geometry outperforms conical for this palate — conical V60 carries a standing over-extraction risk flag.
B22: 2. 1:13–1:14 concentration amplifies polyphenolic bitterness at cool phase and suppresses sucrose (Entries #032, #055).
B23: 3. 1:17 lean on naturals fails to build sucrose-ester mass against CGA lactone bitterness at cool phase.
B24: 4. Barista confirmation overrides visual inference for hardware ID — always.
B25: 5. Large flat burrs (78–98mm) are non-negotiable for oversized varietals (Pacamara, Maragogipe lineage).
B26: 6. Process intensity ceilings exist: Thermal Shock Anaerobic (Entry #059) confirmed the upper boundary of palate tolerance.

Sheet 💰 Price & Value
B1: 💰 PRICE & VALUE INTELLIGENCE
B2: What clarity costs in Singapore, 2026
B4: 💵 PRICE VITALS (SGD, filter entries with recorded price)
B6: AVERAGE | C6: MEDIAN | D6: MIN | E6: MAX | F6: GESHA AVG | G6: NON-GESHA AVG
B7: =AVERAGEIF('Coffee Audit'!Q2:Q2000,">0") | C7: =MEDIAN('Coffee Audit'!Q2:Q2000) | D7: =SMALL('Coffee Audit'!Q2:Q2000,1) | E7: =MAX('Coffee Audit'!Q2:Q2000) | F7: =ROUND(AVERAGEIFS('Coffee Audit'!Q2:Q2000,'Coffee Audit'!W2:W2000,"⭐ GESHA",'Coffee Audit'!Q2:Q2000,">0"),2) | G7: =ROUND(AVERAGEIFS('Coffee Audit'!Q2:Q2000,'Coffee Audit'!W2:W2000,"<>⭐ GESHA",'Coffee Audit'!Q2:Q2000,">0"),2)
B9: 📈 PRICE BAND DISTRIBUTION
B10: Band (SGD) | C10: Entries
B11: ≤ 7 | C11: =COUNTIFS('Coffee Audit'!Q2:Q2000,">0",'Coffee Audit'!Q2:Q2000,"<=7")
B12: 7.01 – 9 | C12: =COUNTIFS('Coffee Audit'!Q2:Q2000,">7",'Coffee Audit'!Q2:Q2000,"<=9")
B13: 9.01 – 12 | C13: =COUNTIFS('Coffee Audit'!Q2:Q2000,">9",'Coffee Audit'!Q2:Q2000,"<=12")
B14: 12.01 – 15 | C14: =COUNTIFS('Coffee Audit'!Q2:Q2000,">12",'Coffee Audit'!Q2:Q2000,"<=15")
B15: 15+ | C15: =COUNTIFS('Coffee Audit'!Q2:Q2000,">15")
B17: 🏅 VALUE VERDICTS
B18: Best value in the archive | C18: Oaks Coffee Co. — Floripondio 90 Hours · SGD 9 (Bolivia Pacamara Lactic Honey, 1600 MASL)
B19: Premium ceiling | C19: Pocket by Flip — SGD 18 Gesha (highest recorded)
B20: Gesha premium | C20: Gesha entries average ~40–50% above non-Gesha — the apex tax is real and consistently paid willingly
B21: Sweet spot | C21: SGD 9–12 band delivers the archive's highest verdict-per-dollar density

Sheet 📅 Archive Timeline
B1: 📅 ARCHIVE TIMELINE & CITY HEATMAP
B2: The 2026 journey, month by month
B4: 📈 ENTRIES PER MONTH — 2026
B6: Month | C6: Jan | D6: Feb | E6: Mar | F6: Apr | G6: May | H6: Jun | I6: Jul | J6: Aug | K6: Sep | L6: Oct | M6: Nov | N6: Dec
B7: Entries | C7: =COUNTIFS('Coffee Audit'!A2:A2000,">="&DATE(2026,1,1),'Coffee Audit'!A2:A2000,"<"&DATE(2026,2,1)) | D7: =COUNTIFS('Coffee Audit'!A2:A2000,">="&DATE(2026,2,1),'Coffee Audit'!A2:A2000,"<"&DATE(2026,3,1)) | E7: =COUNTIFS('Coffee Audit'!A2:A2000,">="&DATE(2026,3,1),'Coffee Audit'!A2:A2000,"<"&DATE(2026,4,1)) | F7: =COUNTIFS('Coffee Audit'!A2:A2000,">="&DATE(2026,4,1),'Coffee Audit'!A2:A2000,"<"&DATE(2026,5,1)) | G7: =COUNTIFS('Coffee Audit'!A2:A2000,">="&DATE(2026,5,1),'Coffee Audit'!A2:A2000,"<"&DATE(2026,6,1)) | H7: =COUNTIFS('Coffee Audit'!A2:A2000,">="&DATE(2026,6,1),'Coffee Audit'!A2:A2000,"<"&DATE(2026,7,1)) | I7: =COUNTIFS('Coffee Audit'!A2:A2000,">="&DATE(2026,7,1),'Coffee Audit'!A2:A2000,"<"&DATE(2026,8,1)) | J7: =COUNTIFS('Coffee Audit'!A2:A2000,">="&DATE(2026,8,1),'Coffee Audit'!A2:A2000,"<"&DATE(2026,9,1)) | K7: =COUNTIFS('Coffee Audit'!A2:A2000,">="&DATE(2026,9,1),'Coffee Audit'!A2:A2000,"<"&DATE(2026,10,1)) | L7: =COUNTIFS('Coffee Audit'!A2:A2000,">="&DATE(2026,10,1),'Coffee Audit'!A2:A2000,"<"&DATE(2026,11,1)) | M7: =COUNTIFS('Coffee Audit'!A2:A2000,">="&DATE(2026,11,1),'Coffee Audit'!A2:A2000,"<"&DATE(2026,12,1)) | N7: =COUNTIFS('Coffee Audit'!A2:A2000,">="&DATE(2026,12,1),'Coffee Audit'!A2:A2000,"<"&DATE(2027,1,1))
B24: 🔥 CITY × MONTH HEATMAP — conditional colour scale, auto-updates
B26: City | C26: Jan | D26: Feb | E26: Mar | F26: Apr | G26: May | H26: Jun | I26: Jul | J26: Aug | K26: Sep | L26: Oct | M26: Nov | N26: Dec
B27: Singapore | C27: =COUNTIFS('Coffee Audit'!A2:A2000,">="&DATE(2026,1,1),'Coffee Audit'!A2:A2000,"<"&DATE(2026,2,1),'Coffee Audit'!B2:B2000,"*Singapore*") | D27: =COUNTIFS('Coffee Audit'!A2:A2000,">="&DATE(2026,2,1),'Coffee Audit'!A2:A2000,"<"&DATE(2026,3,1),'Coffee Audit'!B2:B2000,"*Singapore*") | E27: =COUNTIFS('Coffee Audit'!A2:A2000,">="&DATE(2026,3,1),'Coffee Audit'!A2:A2000,"<"&DATE(2026,4,1),'Coffee Audit'!B2:B2000,"*Singapore*") | F27: =COUNTIFS('Coffee Audit'!A2:A2000,">="&DATE(2026,4,1),'Coffee Audit'!A2:A2000,"<"&DATE(2026,5,1),'Coffee Audit'!B2:B2000,"*Singapore*") | G27: =COUNTIFS('Coffee Audit'!A2:A2000,">="&DATE(2026,5,1),'Coffee Audit'!A2:A2000,"<"&DATE(2026,6,1),'Coffee Audit'!B2:B2000,"*Singapore*") | H27: =COUNTIFS('Coffee Audit'!A2:A2000,">="&DATE(2026,6,1),'Coffee Audit'!A2:A2000,"<"&DATE(2026,7,1),'Coffee Audit'!B2:B2000,"*Singapore*") | I27: =COUNTIFS('Coffee Audit'!A2:A2000,">="&DATE(2026,7,1),'Coffee Audit'!A2:A2000,"<"&DATE(2026,8,1),'Coffee Audit'!B2:B2000,"*Singapore*") | J27: =COUNTIFS('Coffee Audit'!A2:A2000,">="&DATE(2026,8,1),'Coffee Audit'!A2:A2000,"<"&DATE(2026,9,1),'Coffee Audit'!B2:B2000,"*Singapore*") | K27: =COUNTIFS('Coffee Audit'!A2:A2000,">="&DATE(2026,9,1),'Coffee Audit'!A2:A2000,"<"&DATE(2026,10,1),'Coffee Audit'!B2:B2000,"*Singapore*") | L27: =COUNTIFS('Coffee Audit'!A2:A2000,">="&DATE(2026,10,1),'Coffee Audit'!A2:A2000,"<"&DATE(2026,11,1),'Coffee Audit'!B2:B2000,"*Singapore*") | M27: =COUNTIFS('Coffee Audit'!A2:A2000,">="&DATE(2026,11,1),'Coffee Audit'!A2:A2000,"<"&DATE(2026,12,1),'Coffee Audit'!B2:B2000,"*Singapore*") | N27: =COUNTIFS('Coffee Audit'!A2:A2000,">="&DATE(2026,12,1),'Coffee Audit'!A2:A2000,"<"&DATE(2027,1,1),'Coffee Audit'!B2:B2000,"*Singapore*")
B28: Ubud, Bali | C28: =COUNTIFS('Coffee Audit'!A2:A2000,">="&DATE(2026,1,1),'Coffee Audit'!A2:A2000,"<"&DATE(2026,2,1),'Coffee Audit'!B2:B2000,"*Ubud*") | D28: =COUNTIFS('Coffee Audit'!A2:A2000,">="&DATE(2026,2,1),'Coffee Audit'!A2:A2000,"<"&DATE(2026,3,1),'Coffee Audit'!B2:B2000,"*Ubud*") | E28: =COUNTIFS('Coffee Audit'!A2:A2000,">="&DATE(2026,3,1),'Coffee Audit'!A2:A2000,"<"&DATE(2026,4,1),'Coffee Audit'!B2:B2000,"*Ubud*") | F28: =COUNTIFS('Coffee Audit'!A2:A2000,">="&DATE(2026,4,1),'Coffee Audit'!A2:A2000,"<"&DATE(2026,5,1),'Coffee Audit'!B2:B2000,"*Ubud*") | G28: =COUNTIFS('Coffee Audit'!A2:A2000,">="&DATE(2026,5,1),'Coffee Audit'!A2:A2000,"<"&DATE(2026,6,1),'Coffee Audit'!B2:B2000,"*Ubud*") | H28: =COUNTIFS('Coffee Audit'!A2:A2000,">="&DATE(2026,6,1),'Coffee Audit'!A2:A2000,"<"&DATE(2026,7,1),'Coffee Audit'!B2:B2000,"*Ubud*") | I28: =COUNTIFS('Coffee Audit'!A2:A2000,">="&DATE(2026,7,1),'Coffee Audit'!A2:A2000,"<"&DATE(2026,8,1),'Coffee Audit'!B2:B2000,"*Ubud*") | J28: =COUNTIFS('Coffee Audit'!A2:A2000,">="&DATE(2026,8,1),'Coffee Audit'!A2:A2000,"<"&DATE(2026,9,1),'Coffee Audit'!B2:B2000,"*Ubud*") | K28: =COUNTIFS('Coffee Audit'!A2:A2000,">="&DATE(2026,9,1),'Coffee Audit'!A2:A2000,"<"&DATE(2026,10,1),'Coffee Audit'!B2:B2000,"*Ubud*") | L28: =COUNTIFS('Coffee Audit'!A2:A2000,">="&DATE(2026,10,1),'Coffee Audit'!A2:A2000,"<"&DATE(2026,11,1),'Coffee Audit'!B2:B2000,"*Ubud*") | M28: =COUNTIFS('Coffee Audit'!A2:A2000,">="&DATE(2026,11,1),'Coffee Audit'!A2:A2000,"<"&DATE(2026,12,1),'Coffee Audit'!B2:B2000,"*Ubud*") | N28: =COUNTIFS('Coffee Audit'!A2:A2000,">="&DATE(2026,12,1),'Coffee Audit'!A2:A2000,"<"&DATE(2027,1,1),'Coffee Audit'!B2:B2000,"*Ubud*")
B29: Mumbai | C29: =COUNTIFS('Coffee Audit'!A2:A2000,">="&DATE(2026,1,1),'Coffee Audit'!A2:A2000,"<"&DATE(2026,2,1),'Coffee Audit'!B2:B2000,"*Mumbai*") | D29: =COUNTIFS('Coffee Audit'!A2:A2000,">="&DATE(2026,2,1),'Coffee Audit'!A2:A2000,"<"&DATE(2026,3,1),'Coffee Audit'!B2:B2000,"*Mumbai*") | E29: =COUNTIFS('Coffee Audit'!A2:A2000,">="&DATE(2026,3,1),'Coffee Audit'!A2:A2000,"<"&DATE(2026,4,1),'Coffee Audit'!B2:B2000,"*Mumbai*") | F29: =COUNTIFS('Coffee Audit'!A2:A2000,">="&DATE(2026,4,1),'Coffee Audit'!A2:A2000,"<"&DATE(2026,5,1),'Coffee Audit'!B2:B2000,"*Mumbai*") | G29: =COUNTIFS('Coffee Audit'!A2:A2000,">="&DATE(2026,5,1),'Coffee Audit'!A2:A2000,"<"&DATE(2026,6,1),'Coffee Audit'!B2:B2000,"*Mumbai*") | H29: =COUNTIFS('Coffee Audit'!A2:A2000,">="&DATE(2026,6,1),'Coffee Audit'!A2:A2000,"<"&DATE(2026,7,1),'Coffee Audit'!B2:B2000,"*Mumbai*") | I29: =COUNTIFS('Coffee Audit'!A2:A2000,">="&DATE(2026,7,1),'Coffee Audit'!A2:A2000,"<"&DATE(2026,8,1),'Coffee Audit'!B2:B2000,"*Mumbai*") | J29: =COUNTIFS('Coffee Audit'!A2:A2000,">="&DATE(2026,8,1),'Coffee Audit'!A2:A2000,"<"&DATE(2026,9,1),'Coffee Audit'!B2:B2000,"*Mumbai*") | K29: =COUNTIFS('Coffee Audit'!A2:A2000,">="&DATE(2026,9,1),'Coffee Audit'!A2:A2000,"<"&DATE(2026,10,1),'Coffee Audit'!B2:B2000,"*Mumbai*") | L29: =COUNTIFS('Coffee Audit'!A2:A2000,">="&DATE(2026,10,1),'Coffee Audit'!A2:A2000,"<"&DATE(2026,11,1),'Coffee Audit'!B2:B2000,"*Mumbai*") | M29: =COUNTIFS('Coffee Audit'!A2:A2000,">="&DATE(2026,11,1),'Coffee Audit'!A2:A2000,"<"&DATE(2026,12,1),'Coffee Audit'!B2:B2000,"*Mumbai*") | N29: =COUNTIFS('Coffee Audit'!A2:A2000,">="&DATE(2026,12,1),'Coffee Audit'!A2:A2000,"<"&DATE(2027,1,1),'Coffee Audit'!B2:B2000,"*Mumbai*")
B30: Johor Bahru | C30: =COUNTIFS('Coffee Audit'!A2:A2000,">="&DATE(2026,1,1),'Coffee Audit'!A2:A2000,"<"&DATE(2026,2,1),'Coffee Audit'!B2:B2000,"*Johor Bahru*") | D30: =COUNTIFS('Coffee Audit'!A2:A2000,">="&DATE(2026,2,1),'Coffee Audit'!A2:A2000,"<"&DATE(2026,3,1),'Coffee Audit'!B2:B2000,"*Johor Bahru*") | E30: =COUNTIFS('Coffee Audit'!A2:A2000,">="&DATE(2026,3,1),'Coffee Audit'!A2:A2000,"<"&DATE(2026,4,1),'Coffee Audit'!B2:B2000,"*Johor Bahru*") | F30: =COUNTIFS('Coffee Audit'!A2:A2000,">="&DATE(2026,4,1),'Coffee Audit'!A2:A2000,"<"&DATE(2026,5,1),'Coffee Audit'!B2:B2000,"*Johor Bahru*") | G30: =COUNTIFS('Coffee Audit'!A2:A2000,">="&DATE(2026,5,1),'Coffee Audit'!A2:A2000,"<"&DATE(2026,6,1),'Coffee Audit'!B2:B2000,"*Johor Bahru*") | H30: =COUNTIFS('Coffee Audit'!A2:A2000,">="&DATE(2026,6,1),'Coffee Audit'!A2:A2000,"<"&DATE(2026,7,1),'Coffee Audit'!B2:B2000,"*Johor Bahru*") | I30: =COUNTIFS('Coffee Audit'!A2:A2000,">="&DATE(2026,7,1),'Coffee Audit'!A2:A2000,"<"&DATE(2026,8,1),'Coffee Audit'!B2:B2000,"*Johor Bahru*") | J30: =COUNTIFS('Coffee Audit'!A2:A2000,">="&DATE(2026,8,1),'Coffee Audit'!A2:A2000,"<"&DATE(2026,9,1),'Coffee Audit'!B2:B2000,"*Johor Bahru*") | K30: =COUNTIFS('Coffee Audit'!A2:A2000,">="&DATE(2026,9,1),'Coffee Audit'!A2:A2000,"<"&DATE(2026,10,1),'Coffee Audit'!B2:B2000,"*Johor Bahru*") | L30: =COUNTIFS('Coffee Audit'!A2:A2000,">="&DATE(2026,10,1),'Coffee Audit'!A2:A2000,"<"&DATE(2026,11,1),'Coffee Audit'!B2:B2000,"*Johor Bahru*") | M30: =COUNTIFS('Coffee Audit'!A2:A2000,">="&DATE(2026,11,1),'Coffee Audit'!A2:A2000,"<"&DATE(2026,12,1),'Coffee Audit'!B2:B2000,"*Johor Bahru*") | N30: =COUNTIFS('Coffee Audit'!A2:A2000,">="&DATE(2026,12,1),'Coffee Audit'!A2:A2000,"<"&DATE(2027,1,1),'Coffee Audit'!B2:B2000,"*Johor Bahru*")
B32: 🧭 CHAPTER NARRATIVE
B33: Jan — Bali Origin | C33: The archive begins at Seniman, Ubud — three cups, one habit born.
B34: Feb–Mar — Calibration | C34: Kenya Kiamugumo AA at Kyuukei sets the washed-clarity measuring stick; Mumbai chapter opens.
B35: Apr — Acceleration | C35: Gesha register opens in earnest; JB cross-border audit; ratio chemistry lessons logged.
B36: May–Jun — Depth | C36: Trilogy hunting, hardware literacy peaks, watchlist targets cleared one by one.
B37: Jul — The Discovery Month | C37: Oaks Coffee Co. found on Day 4 of operations; Bolivia/Pacamara/Lactic-Honey/P80 firsts; Abseil & the CT62 classification; mock-judge debut at Homeground.

Sheet 🏙️ Café Directory
B1: 🏙️ CAFÉ DIRECTORY — 33 VENUES · 4 CITIES
B2: Live-verified across SuperGrok · ChatGPT · Gemini · Archive direct observation · July 2026
B4: 🌏 BY CITY — COVERAGE
B6: City | C6: Entries | D6: Cafés | E6: Coverage | F6: Note
B7: Singapore | C7: =COUNTIF('Coffee Audit'!B2:B2000,"*Singapore*") | D7: =SUMPRODUCT(('Coffee Audit'!B2:B2000="Singapore")/COUNTIF('Coffee Audit'!B2:B2000,'Coffee Audit'!B2:B2000&"")) | E7: 28/33 cafés | F7: Primary market
B8: Ubud, Bali | C8: =COUNTIF('Coffee Audit'!B2:B2000,"*Bali*") | D8: 1 | E8: 1 café | F8: Archive origin chapter
B9: Mumbai | C9: =COUNTIF('Coffee Audit'!B2:B2000,"*Mumbai*") | D9: 2 | E9: 2 cafés | F9: Expansion frontier
B10: Johor Bahru | C10: =COUNTIF('Coffee Audit'!B2:B2000,"*Johor*") | D10: 1 | E10: 1 café | F10: Cross-border audit
B12: ☕ COMPLETE VERIFIED DIRECTORY
B14: Café | C14: City | D14: Entries | E14: Gesha | F14: Avg SGD | G14: Verified Address | H14: Instagram | I14: Website | J14: Confidence | K14: Notes
B15: Nylon Coffee Roasters | C15: Singapore | D15: =COUNTIF('Coffee Audit'!C2:C2000,B15) | E15: =SUMPRODUCT(('Coffee Audit'!C2:C2000=B15)*('Coffee Audit'!W2:W2000="⭐ GESHA")) | F15: =IFERROR(ROUND(AVERAGEIFS('Coffee Audit'!Q2:Q2000,'Coffee Audit'!C2:C2000,B15,'Coffee Audit'!Q2:Q2000,">0"),2),"—") | G15: 4 Everton Park, #01-40, Singapore | H15: @nyloncoffeeroasters | I15: nyloncoffee.sg | J15: ✅ HIGH | K15: Reliability anchor · 5 visits
B16: Asylum Coffeehouse | C16: Singapore | D16: =COUNTIF('Coffee Audit'!C2:C2000,B16) | E16: =SUMPRODUCT(('Coffee Audit'!C2:C2000=B16)*('Coffee Audit'!W2:W2000="⭐ GESHA")) | F16: =IFERROR(ROUND(AVERAGEIFS('Coffee Audit'!Q2:Q2000,'Coffee Audit'!C2:C2000,B16,'Coffee Audit'!Q2:Q2000,">0"),2),"—") | G16: 311 Jalan Besar, Singapore 208970 | H16: Unknown | I16: Unknown | J16: ✅ HIGH | K16: 4 visits · 2 Gesha entries
B17: Seniman Coffee Studio | C17: Ubud, Bali | D17: =COUNTIF('Coffee Audit'!C2:C2000,B17) | E17: =SUMPRODUCT(('Coffee Audit'!C2:C2000=B17)*('Coffee Audit'!W2:W2000="⭐ GESHA")) | F17: =IFERROR(ROUND(AVERAGEIFS('Coffee Audit'!Q2:Q2000,'Coffee Audit'!C2:C2000,B17,'Coffee Audit'!Q2:Q2000,">0"),2),"—") | G17: Jl. Sriwedari, Ubud, Bali | H17: @senimancoffee | I17: senimancoffee.com | J17: ◐ MEDIUM | K17: Archive origin venue
