Workbook

Sheet Coffee Audit
A1: Date | B1: City | C1: Cafe_Name | D1: Coffee_Name | E1: Producer_Farm | F1: Origin | G1: Varietal | H1: Process | I1: Roast_Level | J1: Brew_Method | K1: Dose_g | L1: Yield_g | M1: Ratio | N1: Water_Temp_C | O1: Bloom | P1: Grinder | Q1: Price_SGD | R1: Official_Notes | S1: Your_Verdict | T1: Technical_Enrichment | U1: Visit_Context | V1: Source | W1: Gesha_Alert
A2: 46025 | B2: Ubud, Bali | C2: Seniman Coffee Studio | D2: Bali Karana Kintamanis | E2: Unknown | F2: Kintamani, Bali | G2: Unknown | H2: Natural | I2: Light | J2: Filter | K2: Unknown | L2: Unknown | M2: Unknown | N2: Unknown | O2: Unknown | P2: Unknown | Q2: Unknown | R2: Clean citrus; floral | S2: Excellent clarity for a natural process; clean citrus and floral notes. | T2: Natural processing contributed mild fruit-forward esters with relatively clean finish; foundational exposure to local Indonesian origins. | U2: Bali family trip | V2: Merged (Gemini + ChatGPT) | W2: =IF(OR(ISNUMBER(SEARCH("gesha",G2)),ISNUMBER(SEARCH("geisha",G2))),"⭐ GESHA","")
A3: 46026 | B3: Ubud, Bali | C3: Seniman Coffee Studio | D3: Sulawesi Toraja | E3: Unknown | F3: Sulawesi, Indonesia | G3: Unknown | H3: Wet-Hulled | I3: Medium | J3: Pour-over | K3: Unknown | L3: Unknown | M3: Unknown | N3: Unknown | O3: Unknown | P3: Unknown | Q3: Unknown | R3: Cocoa; earthy structures | S3: Heavy body with rich cocoa and earthy notes; low acidity; dense mouthfeel. | T3: Classic Giling Basah wet-hulled process emphasized earthy compounds and syrupy mouthfeel; structural density confirmed. | U3: Bali family trip | V3: Merged (Gemini + ChatGPT) | W3: =IF(OR(ISNUMBER(SEARCH("gesha",G3)),ISNUMBER(SEARCH("geisha",G3))),"⭐ GESHA","")
A4: 46026 | B4: Ubud, Bali | C4: Seniman Coffee Studio | D4: House Blend | E4: Unknown | F4: Unknown | G4: Unknown | H4: Unknown | I4: Espresso Roast | J4: Piccolo | K4: Unknown | L4: Unknown | M4: Unknown | N4: Unknown | O4: Unknown | P4: Unknown | Q4: Unknown | R4: Balanced | S4: Great milk integration; standard espresso + milk calibration. | T4: Baseline milk pairing; milk fats softened acidity and amplified sweetness and body. | U4: Bali family trip | V4: Merged (Gemini + ChatGPT) | W4: =IF(OR(ISNUMBER(SEARCH("gesha",G4)),ISNUMBER(SEARCH("geisha",G4))),"⭐ GESHA","")
A5: 46063 | B5: Singapore | C5: Kyuukei Coffee | D5: Kenya Kiamugumo AA | E5: New Ngariama Farmer's Cooperative Society | F5: Kiamugumo, Murang'a County, Kenya | G5: SL28 / SL34 | H5: Washed | I5: Unknown | J5: Pour-over (Flat-Bottom) | K5: 15 | L5: 240 | M5: 1:16 | N5: 93 | O5: Unknown | P5: 120mm Hybrid Burr | Q5: 8 | R5: Blackcurrant, Lemon, Citrus Zest, Mineral Finish | S5: Extremely clean and structured — classic Kenyan profile. Bright blackcurrant acidity layered with lemon and light white grape sweetness. Clarity was the standout: no fermentation noise, no muddiness — precise, well-executed extraction. Compelling demonstration of how a well-processed washed coffee performs when roasted and brewed correctly. Phosphoric acid signature fully confirmed across all phases. | T5: 120mm hybrid burr grinder delivered uniform particle distribution; flat-bottom pour-over geometry ensured even extraction across the full puck. 93°C water temp and 1:16 lean ratio preserved SL28/SL34 phosphoric acid clarity without over-extracting into bitterness. Brew time 2:45 consistent with controlled drawdown on flat-bottom geometry. Kenyan phosphoric acid and anthocyanin-driven blackcurrant notes are varietal signatures of Scott Laboratories SL28/SL34 genetics. | U5: Solo visit — early archive period, first Kyūkei filter audit | V5: Direct observation + infographic + Google review (10 Feb 2026) | W5: =IF(OR(ISNUMBER(SEARCH("gesha",G5)),ISNUMBER(SEARCH("geisha",G5))),"⭐ GESHA","")
A6: 46082 | B6: Mumbai | C6: Subko Coffee Roasters | D6: Project Pearl Ratnagiri | E6: Ratnagiri Estate | F6: India | G6: Unknown | H6: Anaerobic Natural | I6: Light (Agtron 89) | J6: Filter | K6: Unknown | L6: Unknown | M6: Unknown | N6: Unknown | O6: Unknown | P6: Unknown | Q6: Unknown | R6: Unknown | S6: Clean and balanced; interesting but restrained anaerobic expression. | T6: Very light roast (Agtron 89) suppressed ester development despite anaerobic process; muted expected fermented intensity. | U6: Mumbai café exploration | V6: Merged (Gemini + ChatGPT) | W6: =IF(OR(ISNUMBER(SEARCH("gesha",G6)),ISNUMBER(SEARCH("geisha",G6))),"⭐ GESHA","")
A7: 46089 | B7: Mumbai | C7: Grey Soul Coffee Roasters | D7: Raspberry in Loop - Zoya Estate | E7: Zoya Estate | F7: India | G7: Unknown | H7: Multi-stage Anaerobic | I7: Medium | J7: Filter | K7: Unknown | L7: Unknown | M7: Unknown | N7: Unknown | O7: Unknown | P7: Unknown | Q7: Unknown | R7: Chocolate | S7: Heavy body; over-smoothed expression muted brightness and terroir. | T7: Higher development in medium roast reduced aggressive fruit acidity; heavy multi-stage fermentation suppressed terroir expression. | U7: Mumbai café exploration | V7: Merged (Gemini + ChatGPT) | W7: =IF(OR(ISNUMBER(SEARCH("gesha",G7)),ISNUMBER(SEARCH("geisha",G7))),"⭐ GESHA","")
A8: 46099 | B8: Singapore | C8: Narrative Coffee Stand | D8: Finca La Siberia | E8: Unknown | F8: El Salvador | G8: Pacamara | H8: Natural | I8: Light | J8: Pour-over | K8: Unknown | L8: Unknown | M8: Unknown | N8: Unknown | O8: Unknown | P8: Unknown | Q8: Unknown | R8: Unknown | S8: Stewed apples; Apricot; Pu'er tea — Aanya's first specialty filter experience. | T8: Natural Pacamara generated beginner-friendly fruit esters and approachable sweetness; large Pacamara bean size aided even extraction. | U8: Father-daughter coffee exploration | V8: ChatGPT only | W8: =IF(OR(ISNUMBER(SEARCH("gesha",G8)),ISNUMBER(SEARCH("geisha",G8))),"⭐ GESHA","")
A9: 46099 | B9: Singapore | C9: Narrative Coffee Stand | D9: El Puente | E9: Unknown | F9: Honduras | G9: Catuai | H9: Washed | I9: Medium-Light | J9: Espresso | K9: Unknown | L9: Unknown | M9: Unknown | N9: Unknown | O9: Unknown | P9: Unknown | Q9: Unknown | R9: Unknown | S9: Black cherry; Apricot; Pecan — ordered for espresso contrast. | T9: Washed Central American espresso balanced nutty sweetness and fruit acidity; Catuai's consistent cell structure aided uniform extraction. | U9: Father-daughter coffee exploration | V9: ChatGPT only | W9: =IF(OR(ISNUMBER(SEARCH("gesha",G9)),ISNUMBER(SEARCH("geisha",G9))),"⭐ GESHA","")
A10: 46099 | B10: Singapore | C10: ASK Coffee Roastery | D10: Honduras Masaguara (S13) | E10: Unknown | F10: Honduras | G10: Catuai / Caturra | H10: Washed Co-Ferment | I10: Light | J10: Pour-over | K10: Unknown | L10: Unknown | M10: Unknown | N10: Unknown | O10: Unknown | P10: Unknown | Q10: 15 | R10: Lychee; Brandy; Honeydew; Milk Chocolate | S10: Premium but memorable; highly complex tropical profile. | T10: Co-fermentation amplified tropical ester complexity; co-ferment substrates introduced lychee lactones and brandy-like ethyl esters. | U10: Father-daughter coffee exploration | V10: ChatGPT only | W10: =IF(OR(ISNUMBER(SEARCH("gesha",G10)),ISNUMBER(SEARCH("geisha",G10))),"⭐ GESHA","")
A11: 46099 | B11: Singapore | C11: ASK Coffee Roastery | D11: House Blend | E11: Unknown | F11: Unknown | G11: Unknown | H11: Unknown | I11: Unknown | J11: Magic (Ristretto Milk) | K11: Unknown | L11: Unknown | M11: Unknown | N11: Unknown | O11: Unknown | P11: Unknown | Q11: Unknown | R11: Unknown | S11: Contrast milk calibration; excellent concentrated cocoa expression. | T11: Ristretto milk extraction increased sweetness density and concentrated cocoa compounds through reduced water content. | U11: Father-daughter coffee exploration | V11: ChatGPT only | W11: =IF(OR(ISNUMBER(SEARCH("gesha",G11)),ISNUMBER(SEARCH("geisha",G11))),"⭐ GESHA","")
A12: 46103 | B12: Singapore | C12: Apartment (Selegie Rd) | D12: Colombia Don Gallego - Wush Wush | E12: Don Gallego | F12: Colombia | G12: Wush Wush | H12: Washed | I12: Light | J12: Pour-over (Flat-Bottom) | K12: Unknown | L12: Unknown | M12: 1:17 | N12: Unknown | O12: Unknown | P12: Unknown | Q12: Unknown | R12: Tea-like | S12: Incredible tea-like clarity; transparent floral expression. | T12: Lean 1:17 ratio maximized aromatic separation; Wush Wush's Ethiopian-lineage genetics produced delicate phenolic and floral complexity. | U12: Solo specialty calibration | V12: Merged (Gemini + ChatGPT) | W12: =IF(OR(ISNUMBER(SEARCH("gesha",G12)),ISNUMBER(SEARCH("geisha",G12))),"⭐ GESHA","")
A13: 46105 | B13: Singapore | C13: Kyuukei Coffee | D13: Kenya Ndiaini AA | E13: Unknown | F13: Kenya | G13: SL28 / SL34 / Ruiru 11 | H13: Washed | I13: Unknown | J13: Pour-over | K13: Unknown | L13: Unknown | M13: Unknown | N13: Unknown | O13: Unknown | P13: Unknown | Q13: 9 | R13: Redcurrant; Elderflower; Lemon; Apricot | S13: Acidic and interesting; well balanced; high clarity. | T13: Ruiru 11 introduced structural body alongside classic SL28/SL34 brightness; further Kenyan terroir depth confirmed. | U13: Solo specialty calibration | V13: Merged (Gemini + ChatGPT) | W13: =IF(OR(ISNUMBER(SEARCH("gesha",G13)),ISNUMBER(SEARCH("geisha",G13))),"⭐ GESHA","")
A14: 46106 | B14: Singapore | C14: Agora Coffee | D14: Nicaragua Matagalpa - Finca La Virgen | E14: Finca La Virgen | F14: Nicaragua | G14: Unknown | H14: Fully Washed | I14: Espresso Roast | J14: Flat White | K14: Unknown | L14: Unknown | M14: Unknown | N14: Unknown | O14: Unknown | P14: Unknown | Q14: Unknown | R14: Caramel; Chocolate; Red Apple | S14: Solid milk beverage; clean apple acidity preserved in milk integration. | T14: Fully washed Central American profile preserved clean malic acidity in milk; espresso roast development amplified caramel Maillard notes. | U14: Solo specialty calibration | V14: Merged (Gemini + ChatGPT) | W14: =IF(OR(ISNUMBER(SEARCH("gesha",G14)),ISNUMBER(SEARCH("geisha",G14))),"⭐ GESHA","")
A15: 46108 | B15: Singapore | C15: Agora Coffee | D15: Ethiopia Yirgacheffe Beloya | E15: Beloya | F15: Yirgacheffe, Ethiopia | G15: Heirloom | H15: Natural | I15: Filter Roast | J15: V60 | K15: 15 | L15: 220 | M15: 1:14.6 | N15: Unknown | O15: Unknown | P15: Mahlkönig EK43 | Q15: Unknown | R15: Blackcurrant; Strawberry; White Floral | S15: Bright, floral, and distinct strawberry; classic natural Ethiopian profile. | T15: EK43 98mm flat burrs reduced fines and preserved clarity despite natural processing; 1:14.6 ratio retained fruity body. | U15: Solo specialty calibration | V15: Merged (Gemini + ChatGPT) | W15: =IF(OR(ISNUMBER(SEARCH("gesha",G15)),ISNUMBER(SEARCH("geisha",G15))),"⭐ GESHA","")
A16: 46109 | B16: Singapore | C16: Tiong Hoe Specialty Coffee | D16: Brazil Mogiana | E16: Unknown | F16: Mogiana, Brazil | G16: Unknown | H16: Natural | I16: Medium | J16: Pour-over | K16: 15 | L16: 225 | M16: 1:15 | N16: Unknown | O16: Unknown | P16: Unknown | Q16: 8 | R16: Red Dates; Chocolates; Honey | S16: Chocolate-heavy and satisfying; classic dense Brazilian profile. | T16: Tighter 1:15 ratio increased body and amplified Maillard-derived caramel sweetness; medium roast caramelized sugars without losing origin character. | U16: Solo specialty calibration | V16: Merged (Gemini + ChatGPT) | W16: =IF(OR(ISNUMBER(SEARCH("gesha",G16)),ISNUMBER(SEARCH("geisha",G16))),"⭐ GESHA","")
A17: 46109 | B17: Singapore | C17: Tiong Hoe Specialty Coffee | D17: Smoky Quartz Blend | E17: Unknown | F17: Brazil + India | G17: Unknown | H17: Unknown | I17: Unknown | J17: Piccolo Latte | K17: Unknown | L17: Unknown | M17: Unknown | N17: Unknown | O17: Unknown | P17: Unknown | Q17: 5.1 | R17: Dark Chocolates; Hazelnut; Smoky | S17: Strong milk side calibration; excellent concentrated cocoa expression. | T17: Low milk volume in piccolo format concentrated cocoa and hazelnut compounds; cross-origin blend leveraged Indian robusta structural density. | U17: Solo specialty calibration | V17: ChatGPT only | W17: =IF(OR(ISNUMBER(SEARCH("gesha",G17)),ISNUMBER(SEARCH("geisha",G17))),"⭐ GESHA","")
A18: 46110 | B18: Singapore | C18: Asylum Coffeehouse | D18: Peru Cajamarca Gesha (Iced) | E18: Wilder Garcia | F18: Cajamarca, Peru | G18: Gesha | H18: Washed | I18: Medium | J18: Iced Pour-over | K18: 15 | L18: 240 | M18: 1:16 | N18: 92.5 | O18: Unknown | P18: Option-O Lagom P64 | Q18: 11 | R18: Jasmine; Caramel; Lime; Cacao Nibs | S18: Super floral and elegant; flash-chilled expression of Gesha purity. | T18: Flash-chilled extraction via Option-O Lagom P64 preserved volatile floral monoterpenes (linalool); cold dilution stabilized aromatic compounds. | U18: Solo specialty calibration | V18: ChatGPT only | W18: =IF(OR(ISNUMBER(SEARCH("gesha",G18)),ISNUMBER(SEARCH("geisha",G18))),"⭐ GESHA","") -> ⭐ GESHA
A19: 46113 | B19: Singapore | C19: Maxi Coffee Bar | D19: La Laja | E19: James Fernandez | F19: Cauca, Colombia | G19: Sudan Rume | H19: Washed | I19: Light | J19: Pour-over (Flat-Bottom) | K19: 15 | L19: 230 | M19: 1:15.3 | N19: 90-92 | O19: Unknown | P19: FM Grinder 120mm Flat Burr / Timemore Sculptor 078 | Q19: 9 | R19: Raspberry; Nectarine; Floral | S19: Nectarine and raspberry extremely clear; barista sophistication superb; technical milestone. | T19: 120mm flat burr geometry maximized uniform particle distribution; flat-bottom brewer enhanced sweetness while preserving Sudan Rume's rare genetic clarity. | U19: CBD lunch calibration | V19: Merged (Gemini + ChatGPT) | W19: =IF(OR(ISNUMBER(SEARCH("gesha",G19)),ISNUMBER(SEARCH("geisha",G19))),"⭐ GESHA","")
A20: 46113 | B20: Singapore | C20: Lume Café | D20: Corpachi Panama Geisha | E20: Corpachi | F20: Boquerón, Chiriquí, Panama | G20: Geisha | H20: Red Honey | I20: Filter Roast | J20: V60 | K20: Unknown | L20: Unknown | M20: 1:15 | N20: 90 + 70 | O20: Unknown | P20: Mahlkönig EK43 | Q20: 12 | R20: Mandarin Candy; Jasmine; Apricot | S20: Clearly perceived apricot and structured sweetness. | T20: Dual-temperature extraction balanced aromatics and body in honey-process Geisha; red honey partial mucilage retention amplified structured sweetness. | U20: Rainy CBD lunch calibration | V20: ChatGPT only | W20: =IF(OR(ISNUMBER(SEARCH("gesha",G20)),ISNUMBER(SEARCH("geisha",G20))),"⭐ GESHA","") -> ⭐ GESHA
A21: 46117 | B21: Singapore | C21: Asylum Coffeehouse | D21: Castillo Watermelon (Jairo Arcila) | E21: Jairo Arcila | F21: Armenia, Quindío, Colombia | G21: Castillo | H21: Washed Co-Ferment (Watermelon Anaerobic) | I21: Unknown | J21: Pour-over (V60) | K21: 15 | L21: 225 | M21: 1:15 | N21: 90 + 70 | O21: Unknown | P21: Mahlkönig EK43 | Q21: 12.5 | R21: Watermelon; Mint; Lime; Chocolate | S21: Distinct fruit-forward expression; sweetness layered rather than sharp; experimental but controlled. | T21: Watermelon co-fermentation enhanced volatile ester complexity; dual-temperature extraction preserved layered aromatic architecture. | U21: Father-daughter coffee session | V21: Merged (Gemini + ChatGPT) | W21: =IF(OR(ISNUMBER(SEARCH("gesha",G21)),ISNUMBER(SEARCH("geisha",G21))),"⭐ GESHA","")
A22: 46117 | B22: Singapore | C22: Asylum Coffeehouse | D22: Peru Gesha (Wilder Garcia) | E22: Wilder Garcia | F22: Jaén, Peru | G22: Gesha | H22: Washed | I22: Filter Roast | J22: Pour-over (V60) | K22: 15 | L22: 225 | M22: 1:15 | N22: 90 + 70 | O22: Unknown | P22: Mahlkönig EK43 | Q22: 12.5 | R22: Jasmine; Caramel; Lime; Cacao Nibs | S22: Clean, structured, high-clarity cup; apricot-like sweetness and excellent structure. | T22: Dual-temperature extraction engineered aromatic separation and body control; Gesha genetics delivered intrinsic phenolic complexity with minimal processing interference. | U22: Father-daughter coffee session | V22: Merged (Gemini + ChatGPT) | W22: =IF(OR(ISNUMBER(SEARCH("gesha",G22)),ISNUMBER(SEARCH("geisha",G22))),"⭐ GESHA","") -> ⭐ GESHA
A23: 46120 | B23: Singapore | C23: Maxi Coffee Bar | D23: La Villa #1 | E23: Eduard Gaviria | F23: Huila, Colombia | G23: Papayo | H23: Natural | I23: Unknown | J23: Pour-over (Flat-Bottom) | K23: 15 | L23: 225 | M23: 1:15 | N23: Unknown | O23: Unknown | P23: Timemore Sculptor 078 | Q23: 9 | R23: Stewed Forest Berries; Grape; Black Forest Cake | S23: Dense fruit profile with rounded sweetness. | T23: Flat-bottom geometry and tight 1:15 ratio emphasized body; Papayo varietal's high sugar content amplified by natural processing into rich fruit-cake profile. | U23: Lunch catch-up with Yichen | V23: ChatGPT only | W23: =IF(OR(ISNUMBER(SEARCH("gesha",G23)),ISNUMBER(SEARCH("geisha",G23))),"⭐ GESHA","")
A24: 46130 | B24: Johor Bahru | C24: Clod Coffee Bar & Roasters | D24: Hacienda La Florida | E24: Unknown | F24: Unknown | G24: Typica Mejorado | H24: Anaerobic Washed | I24: Unknown | J24: Origami (Conical) | K24: 18 | L24: 277 | M24: 1:15.4 | N24: Unknown | O24: 42g / 30s (1:2.3) | P24: Mahlkönig EK Omnia | Q24: 11.08 | R24: Lemon verbena; Red plum; Citronella; Hibiscus | S24: Excellent. Lime when hot, distinct plum as it cooled. | T24: EK Omnia precision grind and Origami conical drove extreme clarity; thermal phase shift perfectly isolated citric-to-malic acid transition (lime → plum). | U24: Unknown | V24: Gemini only | W24: =IF(OR(ISNUMBER(SEARCH("gesha",G24)),ISNUMBER(SEARCH("geisha",G24))),"⭐ GESHA","")
A25: 46136 | B25: Singapore | C25: Agora Coffee | D25: Brazil Santuário Sul | E25: Unknown | F25: Carmo de Minas, Brazil | G25: Unknown | H25: Natural Fermentation | I25: Light-Medium | J25: V60 | K25: 16 | L25: 224 | M25: 1:14 | N25: 95 | O25: Unknown | P25: Mahlkönig EK43 | Q25: Unknown | R25: Blackcurrant; Black Cherry; Dark Chocolate | S25: Full body; prominent blackcurrant; clear chocolaty finish. | T25: Tight 1:14 ratio engineered maximum body; EK43 98mm burrs maintained clarity to keep fermented natural fruit clean and non-bitter. | U25: Midday specialty calibration | V25: Merged (Gemini + ChatGPT) | W25: =IF(OR(ISNUMBER(SEARCH("gesha",G25)),ISNUMBER(SEARCH("geisha",G25))),"⭐ GESHA","")
A26: 46148 | B26: Singapore | C26: Nylon Coffee Roasters | D26: Brazil FAF Organic | E26: Unknown | F26: Brazil | G26: Arara | H26: Natural | I26: Filter Roast | J26: xBloom (Flat-Bottom) | K26: Unknown | L26: Unknown | M26: 1:17 | N26: Unknown | O26: Unknown | P26: Mahlkönig EK Omnia | Q26: 7.5 | R26: Red Apple; Cherry; Raisin; Milk Chocolate | S26: Solid body with crisp green apple (malic) front, resolving into smooth milk chocolate finish. | T26: High-quality Arara natural processing yielded excellent structural body while maintaining crisp malic acidity; xBloom flat-bottom avoided heavy fermentation mud. | U26: Unknown | V26: Gemini only | W26: =IF(OR(ISNUMBER(SEARCH("gesha",G26)),ISNUMBER(SEARCH("geisha",G26))),"⭐ GESHA","")
A27: 46148 | B27: Singapore | C27: Nylon Coffee Roasters | D27: Brazil Serra dos Ciganos | E27: Unknown | F27: Brazil | G27: Catucai 24/137 | H27: Natural | I27: Espresso Roast | J27: Flat White | K27: Unknown | L27: Unknown | M27: Unknown | N27: Unknown | O27: Unknown | P27: Unknown | Q27: Unknown | R27: Sultana; Dried Apricot; Praline; Roasted Hazelnut | S27: Good cup with pleasant lingering sweet aftertaste. | T27: Milk fats bound perfectly with natural processed espresso; Catucai 24/137 high-density bean structure created long, comforting finish. | U27: Unknown | V27: Gemini only | W27: =IF(OR(ISNUMBER(SEARCH("gesha",G27)),ISNUMBER(SEARCH("geisha",G27))),"⭐ GESHA","")
A28: 46149 | B28: Singapore | C28: Nylon Coffee Roasters | D28: Ethiopia Banko Gotiti | E28: Unknown | F28: Ethiopia | G28: Heirloom | H28: Washed | I28: Filter Roast | J28: xBloom (Flat-Bottom) | K28: Unknown | L28: Unknown | M28: 1:17 | N28: Unknown | O28: Unknown | P28: Mahlkönig EK Omnia | Q28: 8.5 | R28: Lemonade; Raspberry; Peach; Bergamot | S28: Lemon front, heavy melon mid-cup, fading into clean white tea finish. | T28: 1:17 lean ratio isolated volatile citric acids; xBloom flat-bottom geometry stabilized mid-cup sugars before clean tannin-forward white tea finish. | U28: Unknown | V28: Gemini only | W28: =IF(OR(ISNUMBER(SEARCH("gesha",G28)),ISNUMBER(SEARCH("geisha",G28))),"⭐ GESHA","")
A29: 46149 | B29: Singapore | C29: Nylon Coffee Roasters | D29: Nicaragua Buena Vista | E29: Unknown | F29: Nicaragua | G29: Parainema | H29: Natural Anaerobic | I29: Espresso Roast | J29: Single Espresso | K29: Unknown | L29: Unknown | M29: ~1:2 | N29: Unknown | O29: Unknown | P29: Unknown | Q29: Unknown | R29: Chiku; Stewed Cherry; Dried Apricot; Brazil Nut | S29: Thick, syrupy body. Highly fermented, savory/not sweet, very long lingering finish. | T29: Anaerobic fermentation metabolized sugars into complex savory esters; 9-bar pressure emulsification drove heavy oil-based viscosity and extended aftertaste. | U29: Unknown | V29: Gemini only | W29: =IF(OR(ISNUMBER(SEARCH("gesha",G29)),ISNUMBER(SEARCH("geisha",G29))),"⭐ GESHA","")
A30: 46150 | B30: Singapore | C30: Alchemist (Raffles Place) | D30: El Morito | E30: Unknown | F30: Colombia | G30: Marshell | H30: Washed | I30: Filter Roast | J30: V60 Pour-over (Conical) | K30: 15 | L30: 240 | M30: 1:16 | N30: Unknown | O30: Unknown | P30: Mahlkönig EK43S (98mm Flat Burr) | Q30: Unknown | R30: Yellow Plum; Orange; Cane Sugar | S30: Simultaneous citric-malic acid overlap with integrated cane sugar — smooth and refreshing with excellent mid-palate juiciness. Confirmed: I love this bean. | T30: EK43S 98mm flat burrs + V60 conical at 1:16 delivered perfect dual-acid integration (citric orange + malic plum) without single-note dominance. Sucrose extraction at 1:16 bridged acid structure into clean cane sugar finish. Marshell is an extremely rare Colombian varietal — natural mutation prized for simultaneous citric-malic acid duality. | U30: Solo visit — Alchemist Raffles Place | V30: Master CSV (hari_coffee_audit_master_2026) | W30: =IF(OR(ISNUMBER(SEARCH("gesha",G30)),ISNUMBER(SEARCH("geisha",G30))),"⭐ GESHA","")
A31: 46154 | B31: Singapore | C31: Kurasu | D31: Indonesia Frinsa Estate | E31: Frinsa Estate | F31: West Java, Indonesia | G31: Local Varietals | H31: Extended Fermentation Honey | I31: Light | J31: Pour-over (Hario Alpha — Flat-Bottom) | K31: 15 | L31: 225 | M31: 1:16 | N31: 80 → 95 → 80 | O31: Unknown | P31: Mahlkönig EK43S (98mm Flat Burr) | Q31: 9.5 | R31: Floral aroma; Stewed Strawberries; Grapefruit; Brown Sugar; Black Tea | S31: Floral taste with a sweet coating on the tongue that gradually sticks and fades off cleanly — sugar and tea aftertaste. Well-executed Indonesian honey with unusual clarity for the origin. | T31: Multi-temperature pour (80→95→80°C) with Hario Alpha flat-bottom perfectly managed heavy honey-process mucilage sugars — clear floral extraction at lower temps, dissolving jammy mucilage at peak heat, finishing cleanly. Extended fermentation honey adds structured sweetness without heavy ferment-funk. First Indonesian-mainland entry in archive (distinct from Bali entries). | U31: Solo visit — Kurasu Singapore | V31: Master CSV (hari_coffee_audit_master_2026) | W31: =IF(OR(ISNUMBER(SEARCH("gesha",G31)),ISNUMBER(SEARCH("geisha",G31))),"⭐ GESHA","")
A32: 46155 | B32: Singapore | C32: The Community Coffee (Hamilton) | D32: Jose Mancia Honduras | E32: Jose Mancia | F32: Honduras | G32: Typica | H32: Natural | I32: Filter Roast | J32: Pour-over (Hario Switch — Immersion/Percolation) | K32: 15 | L32: 255 | M32: 1:17 | N32: Unknown | O32: Unknown | P32: Mahlkönig EK43 (98mm Flat Burr) | Q32: 9 | R32: Kiwi; Oolong Tea; Chocolate Truffle | S32: Pretty good. Kiwi and oolong tea style — full bodied. Short finish with slight hints of chocolate. Clean and approachable natural without heavy fermentation noise. | T32: Typica inherent lipid clarity + raised-bed drying produced clean tea-structure body. EK43 98mm flat burrs + Hario Switch immersion phase stabilised full mouthfeel at lean 1:17. Short finish consistent with 15-days-off-roast volatile taper — kiwi and oolong top notes fade rapidly. Honduras Typica at altitude expresses tea-like clarity atypical of natural-process expectations. | U32: Solo visit — The Community Coffee Hamilton | V32: Master CSV (hari_coffee_audit_master_2026) | W32: =IF(OR(ISNUMBER(SEARCH("gesha",G32)),ISNUMBER(SEARCH("geisha",G32))),"⭐ GESHA","")
A33: 46157 | B33: Singapore | C33: Alchemist (Ocean Financial Centre) | D33: Ijen Laurina | E33: Ijen Plateau | F33: East Java, Indonesia | G33: Hybrid Laurina | H33: Anaerobic Natural | I33: Light | J33: V60 Pour-over (Conical) | K33: 15 | L33: 240 | M33: 1:16 | N33: 90 | O33: Unknown | P33: Mahlkönig EK43S (98mm Flat Burr) | Q33: 8.5 | R33: Hibiscus; Red Apple; Hawthorn | S33: Felt hibiscus hot. Mid temp showed apple paste. Cooled to a honeyed character. Full bodied. Textbook style flavours — definitely a good one. Clean progressive thermal arc. | T33: 90°C brew temp suppressed lactic ester over-extraction while preserving volatile anthocyanin hibiscus esters. Laurina low-caffeine mutation allows intrinsic sucrose to express as clean honeyed finish without alkaloid bitterness. Anaerobic Natural transformed malic acid into jammy apple paste mid-phase. First Hybrid Laurina varietal in archive — new genetic category unlocked. Hibiscus = anthocyanin; Apple paste = malic lactone; Honey = sucrose at sub-50°C. | U33: Solo visit — Alchemist Ocean Financial Centre | V33: Master CSV (hari_coffee_audit_master_2026) | W33: =IF(OR(ISNUMBER(SEARCH("gesha",G33)),ISNUMBER(SEARCH("geisha",G33))),"⭐ GESHA","")
A34: 46158 | B34: Singapore | C34: Fluid Collective | D34: El Obraje | E34: El Obraje | F34: Huila, Colombia | G34: Gesha | H34: Washed | I34: Light | J34: Flatbed Dripper (Flat-Bottom) | K34: 15 | L34: 230 | M34: 1:15.3 | N34: 92 | O34: Unknown | P34: Option-O Lagom P64 (64mm Flat Burr) | Q34: 14 | R34: Mango; Orange Blossom; Nectarine; Honey | S34: Damn the taste so nice — the orange nectarine finishing with that honey is terrific. Love this one. So far my favourite. Honey sweetness lingers and taste changes as temperature cools. Best Gesha washed in archive at time of logging. | T34: Lagom P64 64mm flat burrs deliver near-unimodal particle distribution — same hardware platform as Asylum Coffeehouse entries, enabling pure terroir delta comparison between Colombia Gesha (El Obraje, Huila) and Peru Gesha (Wilder Garcia, Jaén). 92°C at 1:15.3 maximised linalool floral ester retention while stabilising malic acid mango-nectarine backbone. Flat-bottom eliminated bypass and ensured even bed saturation — critical for preserving fragile Gesha aromatics. Honey finish = sucrose preserved at washed-process mucilage removal stage. | U34: Solo visit — FLUID Singapore | V34: Master CSV (hari_coffee_audit_master_2026) | W34: =IF(OR(ISNUMBER(SEARCH("gesha",G34)),ISNUMBER(SEARCH("geisha",G34))),"⭐ GESHA","") -> ⭐ GESHA
A35: 46161 | B35: Singapore | C35: Pocket by Flip (Flip Coffee Roasters) | D35: Ecuador La Papaya | E35: La Papaya Farm | F35: Loja, Ecuador | G35: Geisha | H35: Washed | I35: Light | J35: Filter Hot — Flat-Bottom (Hario Alpha) | K35: 15 | L35: 225 | M35: 1:15 | N35: 92 → 75 → 92 | O35: Unknown | P35: Mahlkönig CORE (54mm Flat Burr) | Q35: 18 | R35: Fresh Apricot; Rooibos; Lemon Thyme; Toffee Apple | S35: Opening: tartaric apricot + rooibos aspalathin. Mid: thymol terpene coat — lipid-binding, persistent to midway. Cooling: malic apple shift + caramelised sucrose. Clean transparent fade. No linalool/jasmine — terpene-forward character distinct from Peru Geisha entries. Highest-altitude Geisha in archive at 2,100 MASL. | T35: Triple-temp cascade (92→75→92°C) on CORE 54mm flat burr + Hario Alpha flat-bottom preserved heat-sensitive thymol terpenes from 2,100 MASL Loja terroir. 75°C mid-pour is the critical terpene-stabilisation variable — thymol is lipid-binding and volatile above 80°C, so mid-temp pour is the architecture delivering the persistent midpalate coat. Ecuador Geisha = terpene-forward (Thymol/Aspalathin) clearly differentiated from linalool-forward Peru Geisha (Jasmine/Citric). First Ecuador-origin entry in archive. | U35: Solo visit — Pocket by Flip, 30 Stevens Road | V35: Master CSV (hari_coffee_audit_master_2026) | W35: =IF(OR(ISNUMBER(SEARCH("gesha",G35)),ISNUMBER(SEARCH("geisha",G35))),"⭐ GESHA","") -> ⭐ GESHA
A36: 46168 | B36: Singapore | C36: Zerah Roasters | D36: El Diviso — Caturra Chiroso (Ester Bomb) | E36: El Diviso Farm | F36: Huila, Colombia | G36: Caturra Chiroso | H36: Yeast Anaerobic Natural | I36: Filter Roast | J36: Flat-Bottom Dripper | K36: 15 | L36: 240 | M36: 1:16 | N36: 92 | O36: 38g / Unknown seconds | P36: DF64 Gen 2 (64mm Flat Burr — aftermarket upgrade) | Q36: 12 | R36: Passionfruit; Plum Wine; Mango | S36: Goddamn the smell is intense. Flavor burst — acid or strong flavor, super punchy. Passionfruit with enhanced fruit, funky. Plums. After cooling — sugars came out. Interesting. Strong flavor gone. Overall: funky, fermentation-driven. Processing-dominant cup. Three completely different cups in one — ester detonation hot, funk phase mid, mango sweetness cool. | T36: Yeast strains WLPU07 + LALVIN 71B at 96hr fermentation, pH 3.72, 100% anaerobic sealed tank (1.2 bar, 23.4°C) produced extreme ester complexity: γ-decalactone (passionfruit lactone) dominant hot, tartaric esters + acetic acid (plum wine/funk) mid, fructose ester chains (mango sweetness) cold. 1:16 lean ratio was critical safety valve — prevented cloying ester overload and enabled three-phase thermal tracking. Flat-bottom geometry amplified body and even bed saturation. DF64 Gen 2 with aftermarket 64mm flat burrs: first DF64 platform entry in archive. Caturra Chiroso = elongated cell structure, Geisha-adjacent clarity potential overridden by fermentation intensity. Yeast Anaerobic Natural distinct process category from Wild Anaerobic. | U36: Solo visit — Zerah Roasters, Singapore, 26 May 2026. Barista explained fermentation process, flat-bottom geometry rationale, 1:16 ratio decision in detail. Warm educational session on 2nd floor cosy space. Barista recommended Glyph Supply Co (Jurong). | V36: Infographic (Entry #025 Ester Bomb) + Google Maps review + Google review authored by Hari | W36: =IF(OR(ISNUMBER(SEARCH("gesha",G36)),ISNUMBER(SEARCH("geisha",G36))),"⭐ GESHA","")
A37: 46183 | B37: Singapore | C37: Nylon Coffee Roasters | D37: Colombia Juan Martin | E37: Banexport | F37: Colombia | G37: Red Striped Bourbon | H37: Washed | I37: Filter Roast | J37: xBloom (Flat-Bottom) | K37: Unknown | L37: Unknown | M37: 1:17 | N37: Unknown | O37: Unknown | P37: Mahlkönig EK Omnia (98mm Flat Burr) | Q37: 7.5 | R37: Berry, Red Plum, Nectarine, Orange Tea | S37: Orange-type aromatic afterfeel when hot — bright and encapsulating. Clearly fruity character throughout. Mellows cleanly as it cools; sugars emerge distinctly at mid-cool phase. Nice and light overall — 1:17 lean ratio working well on this varietal. | T37: EK Omnia 98mm flat burrs + xBloom flat-bottom geometry maintained body integrity at 1:17 lean ratio. Retail bag on shelf dated 10 Jun 2026 but filter batch roast date unconfirmed — cup behaviour (clean sugar emergence, well-integrated stone fruit at cool phase) is consistent with a properly rested lot of 10–21 days post-roast. Red Striped Bourbon sucrose density confirmed by clean sweetness at cool phase. | U37: Solo visit — office lunch break, 13:15 | V37: Direct observation + bag photo (retail stock) | W37: =IF(OR(ISNUMBER(SEARCH("gesha",G37)),ISNUMBER(SEARCH("geisha",G37))),"⭐ GESHA","")
A38: 46186 | B38: Singapore | C38: Kurasu | D38: Rwanda Nkara Soil Project Lot 1204 | E38: Nkara Soil Project | F38: Rwanda | G38: Red Bourbon | H38: Fully Washed | I38: Filter Roast | J38: V60 Pour-over (Conical) | K38: Unknown | L38: Unknown | M38: Unknown | N38: Unknown | O38: Unknown | P38: Mahlkönig EK43 (98mm Flat Burr) | Q38: 9.27 | R38: Floral aroma, taste of mandarin orange, baked apple and grapefruit, brown sugar-like sweetness and accompanying aftertaste | S38: Strong aftertaste with slight bitterness noted. Baked apple taste dominates and persists across all phases. Sugars emerge clearly on cooling — brown sugar sweetness confirmed at cool phase. Rated average. Rwanda Nkara terroir pushes more citrus-floral (mandarin/grapefruit) vs prior Rwanda entry at Twenty Grams (Entry #024) which was peach/stone fruit dominant. | T38: EK43 98mm flat burrs paired with conical V60 geometry — key hardware distinction vs prior Kurasu Frinsa entry. V60 conical creates faster flow rate and higher bypass risk vs flat-bottom; the slight bitterness is consistent with conical geometry allowing fine particles to over-extract at the drain. Washed Red Bourbon at altitude delivers classic Rwandan citric-malic duality (mandarin + baked apple). Baked apple dominance = malic acid thermally stabilised — persists across full thermal arc unlike volatile citric top notes which fade. Brown sugar aftertaste is sucrose retention signature of Red Bourbon genetics. | U38: Solo visit — 13 Jun 2026 | V38: Direct observation + bean card photo | W38: =IF(OR(ISNUMBER(SEARCH("gesha",G38)),ISNUMBER(SEARCH("geisha",G38))),"⭐ GESHA","")
A39: 46187 | B39: Singapore | C39: Keryi Coffee | D39: Colombia Finca La Esmaralda | E39: Finca La Esmaralda | F39: Colombia | G39: Gesha | H39: Honey | I39: Light Roast | J39: Hario Switch (Immersion/Percolation Hybrid) | K39: 15 | L39: 210 | M39: 1:14 | N39: 91 → 78 | O39: 60g (~4:1) | P39: Ditting 98mm flat burr | Q39: 15 | R39: Citrus, white florals, lychee, sugar-cane sweetness | S39: Smooth body throughout. Lychee & white florals lead in the hot phase — fragile linalool terpenes survived the tight 1:14 concentration. Citrus surfaces mid-cool as perceived sweetness rises; honey-derived sweetness rounds the cool-phase finish into progressive smoothness. Rated highly — a fine, relaxing Gesha. Clarity held; upper Gesha tier (cf. El Obraje washed favourite, Hiu Los Lajones honey Panama). | T39: Ditting 98mm flat burrs deliver lab-grade narrow particle distribution with minimal fines — the key variable licensing an aggressive 1:14 ratio without astringency. Descending pour (91°C bloom/first pour → 78°C final) uses temperature as a brake on the extraction tail: high heat early extracts volatile terpenes, acids & sugars; the cool final pour reaches target volume while suppressing late-stage chlorogenic-acid bitterness. Hario Switch valve-closed immersion develops honey-process mucilage sweetness & body evenly before percolative drain adds finish definition — conical geometry runs against the flat-bottom affinity but suits this process. | U39: Solo relaxation visit — Sunday 14 Jun 2026, 11 AM; barista-led brew interview (grinder/ratio/temp confirmed) | V39: Direct observation + menu photo + barista interview | W39: =IF(OR(ISNUMBER(SEARCH("gesha",G39)),ISNUMBER(SEARCH("geisha",G39))),"⭐ GESHA","") -> ⭐ GESHA
A40: 46192 | B40: Singapore | C40: Corner Corner | D40: Malaysia My Liberica | E40: My Liberica (Jason Liew), Kulai, Johor | F40: Malaysia, Kulai, Johor | G40: Liberica (Coffea liberica) | H40: JH Natural (Jekyll & Hyde controlled fermentation - proprietary My Liberica process) | I40: Light | J40: Pour Over (filter) | K40: 13 | L40: 190 | M40: 1:14.6 | N40: 90-92 (steady throughout) | O40: Unknown | P40: Timemore (conical Gold burr, coarse) | Q40: 13 | R40: Root beer / Tropical fruit punch / Raspberry candy / Rambutan / Longan / Sarsi (roaster: One Half) | S40: Interesting and approachable - 'not so funky but different for sure'; picked out longan-type fruit. First non-arabica capture in the archive; landed as a positive novelty rather than rejected. | T40: First Liberica (Coffea liberica) and first Malaysia/Johor origin in archive; near-sea-level farm (26-30 MASL). Low 13g dose at ~1:14.6 ratio with steady 90-92C and a conical Timemore Gold burr deliberately tames Liberica's smoky-woody funk into a cleaner, longan-forward cup; the small dose + generous water dilutes intensity for legibility. NOTE: barista verbally cited ~1:16, but stated 13g:190g computes to 1:14.6. | U40: Roaster: One Half (light-roast filter program). Corner Corner is a vinyl-record listening bar/cafe; walls of LPs, warm low lighting, Japanese-style carafe-and-cup serve. Friday 19 June 2026, ~15:15. Rated awesome by Hari. | V40: Field audit (Claude) | W40: =IF(OR(ISNUMBER(SEARCH("gesha",G40)),ISNUMBER(SEARCH("geisha",G40))),"⭐ GESHA","")
...

Sheet ☕ Dashboard
B1: ☕ THE HARI COFFEE ARCHIVE — 2026
B2: Master Extraction Archivist · Singapore · Bali · Mumbai · Johor Bahru · Field-audited, three-phase palate record
B4: ARCHIVE VITALS — live formulas, auto-update with every new entry
B6: TOTAL ENTRIES | C6: UNIQUE CAFÉS | D6: CITIES | E6: ORIGINS | F6: ⭐ GESHA CUPS | G6: VARIETALS | H6: AVG PRICE | I6: FIRST ENTRY | J6: LATEST ENTRY
B7: =COUNTA('Coffee Audit'!A2:A2000) -> 59 | C7: =SUMPRODUCT(('Coffee Audit'!C2:C2000<>"")/COUNTIF('Coffee Audit'!C2:C2000,'Coffee Audit'!C2:C2000&"")) -> 33 | D7: 4 | E7: 18 | F7: =COUNTIF('Coffee Audit'!W2:W2000,"⭐ GESHA") -> 12 | G7: =SUMPRODUCT(('Coffee Audit'!G2:G2000<>"")/COUNTIF('Coffee Audit'!G2:G2000,'Coffee Audit'!G2:G2000&"")) -> 38 | H7: =IFERROR("S$"&TEXT(AVERAGEIF('Coffee Audit'!Q2:Q2000,">0"),"0.00"),"—") -> S$10.99 | I7: =TEXT(MIN('Coffee Audit'!A2:A2000),"DD MMM YYYY") -> 03 Jan 2026 | J7: =TEXT(MAX('Coffee Audit'!A2:A2000),"DD MMM YYYY") -> 10 Jul 2026
B8: field-audited cups | C8: across 4 cities | D8: SG · Bali · Mumbai · JB | E8: origin countries | F8: 12% of archive | G8: unique varieties logged | H8: SGD per cup | I8: archive opened | J8: most recent audit
B11: ⭐ GESHA / GEISHA HALL OF FAME — The Apex Varietal · All 12 archive cups | H11: 🏆 TOP CAFÉS BY VISITS — 59 entries · 33 venues · 4 cities
B12: # | C12: Café | D12: Origin | E12: Process | F12: Price | H12: Café | I12: Visits | J12: Avg SGD | K12: City | L12: Note
B13: 1 | C13: Asylum Coffeehouse | D13: Peru · Cajamarca | E13: Washed | F13: S$11.00 | H13: Nylon Coffee Roasters | I13: 6 | J13: S$7.83 | K13: Singapore | L13: ⭐ Reliability anchor
B14: 2 | C14: Lume Café | D14: Panama · Boquerón | E14: Red Honey | F14: S$12.00 | H14: Asylum Coffeehouse | I14: 4 | J14: S$12.50 | K14: Singapore | L14: 2 Gesha entries
B15: 3 | C15: Asylum Coffeehouse | D15: Peru · Jaén | E15: Washed | F15: S$12.50 | H15: Fluid Collective | I15: 3 | J15: S$11.33 | K15: Singapore | L15: 🏆 Cup of the Year
B16: 4 | C16: Fluid Collective | D16: Colombia · Huila | E16: Washed | F16: S$14.00 | H16: Seniman Coffee Studio | I16: 3 | J16: — | K16: Ubud, Bali | L16: Archive origin chapter
B17: 5 | C17: Pocket by Flip (Flip Coffee Roasters) | D17: Ecuador · Loja | E17: Washed | F17: S$18.00 | H17: Kyuukei Coffee | I17: 3 | J17: S$8.67 | K17: Singapore
B18: 6 | C18: Keryi Coffee | D18: Colombia | E18: Honey | F18: S$15.00 | H18: Agora Coffee | I18: 3 | J18: — | K18: Singapore
B19: 7 | C19: Equate | D19: Colombia · Huila | E19: Washed | F19: S$13.00 | H19: Zerah Roasters | I19: 2 | J19: S$10.50 | K19: Singapore | L19: Top barista: Aqil #1
B20: 8 | C20: Homeground Coffee Roasters | D20: Colombia · Valle | E20: Natural | F20: S$19.00 | H20: Homeground Coffee Roasters | I20: 2 | J20: S$14.50 | K20: Singapore | L20: 1 Gesha entry
B21: 9 | C21: Cowpresso Coffee Roasters | D21: Colombia · Valle | E21: Natural | F21: S$9.90 | H21: Keryi Coffee | I21: 2 | J21: S$14.00 | K21: Singapore | L21: 1 Gesha entry
B22: 10 | C22: Pinhole Coffee Bar | D22: Colombia · Huila | E22: Honey | F22: S$15.00 | H22: Maxi Coffee Bar | I22: 2 | J22: S$9.00 | K22: Singapore
B23: 11 | C23: Double Shot Coffee | D23: Panama · Boquete | E23: Natural | F23: S$16.00
B24: 12 | C24: Abseil | D24: Colombia | E24: Washed | F24: S$21.00
B25: 19% of 59 cups are Gesha/Geisha — the archive's apex varietal. Avg Gesha price S$14.70 vs non-Gesha S$9.59 (+53% premium). Colombia Gesha Process Trilogy ✅ complete: Washed (Fluid), Honey (Keryi+Pinhole), Natural (Homeground+Cowpresso).
B27: 🍯 PALATE PROCESS FINGERPRINT — 41% washed dominance signals Clarity > Complexity | H27: 🌍 ORIGIN INTELLIGENCE — 18 origins · Colombia leads at 30%
B28: Process | C28: Cups | D28: % Archive | E28: Palate Signal | F28: Affinity | H28: Origin | I28: Entries | J28: % Archive | K28: Gesha? | L28: Palate fit
B29: Washed | C29: =COUNTIF('Coffee Audit'!H2:H2000,"*Washed*")-COUNTIF('Coffee Audit'!H2:H2000,"*Anaerobic*") -> 18 | D29: 41% | E29: Malic acid clarity · jasmine lift · clean finish | F29: ★★★★★ | H29: Colombia | I29: =COUNTIF('Coffee Audit'!F2:F2000,"*Colombia*") -> 18 | J29: 30% | K29: ⭐ ×6 | L29: HIGHEST — malic clarity + Gesha depth
B30: Natural | C30: =COUNTIF('Coffee Audit'!H2:H2000,"*Natural*")-COUNTIF('Coffee Audit'!H2:H2000,"*Anaerobic*") -> 12 | D30: 24% | E30: Stone fruit · berry complexity · terroir expression | F30: ★★★★ | H30: Ethiopia | I30: =COUNTIF('Coffee Audit'!F2:F2000,"*Ethiopia*") -> 7 | J30: 13% | K30: — | L30: HIGH — linalool florals · heirloom terroir
B31: Honey | C31: =COUNTIF('Coffee Audit'!H2:H2000,"*Honey*") -> 6 | D31: 9% | E31: Mucilage sweetness bridge · ketone fruit layer | F31: ★★★★ | H31: Brazil | I31: =COUNTIF('Coffee Audit'!F2:F2000,"*Brazil*") -> 5 | J31: 9% | K31: — | L31: MED — body + sweetness baseline
B32: Anaerobic Natural | C32: =COUNTIF('Coffee Audit'!H2:H2000,"*Anaerobic Nat*")+COUNTIF('Coffee Audit'!H2:H2000,"*Natural Anaerobic*") -> 6 | D32: 9% | E32: Controlled funk · ester complexity · tropical edge | F32: ★★★ | H32: Indonesia | I32: =COUNTIF('Coffee Audit'!F2:F2000,"*Indonesia*") -> 3 | J32: 7% | K32: — | L32: MED — wet-hulled texture study
B33: Experimental Ferment | C33: =COUNTIF('Coffee Audit'!H2:H2000,"*Co-Ferment*")+COUNTIF('Coffee Audit'!H2:H2000,"*Mosto*")+COUNTIF('Coffee Audit'!H2:H2000,"*Yeast*") -> 4 | D33: 6% | E33: Edge cases: yeast, mosto, co-ferment | F33: ★★ Exploratory | H33: Honduras | I33: =COUNTIF('Coffee Audit'!F2:F2000,"*Honduras*") -> 3 | J33: 6% | K33: ⭐ ×1 | L33: MED-HIGH — malic stone fruit
B34: Wet-Hulled (Giling) | C34: =COUNTIF('Coffee Audit'!H2:H2000,"*Wet*") -> 1 | D34: 2% | E34: Earthy · Indonesian terroir · syrupy body | F34: ★ | H34: Peru | I34: =COUNTIF('Coffee Audit'!F2:F2000,"*Peru*") -> 3 | J34: 6% | K34: ⭐ ×2 | L34: HIGH — washed Gesha clarity
B35: Thermal Shock Anaerobic | C35: =COUNTIF('Coffee Audit'!H2:H2000,"*Thermal*") -> 1 | D35: 2% | E35: Extreme ester intensity — palate ceiling confirmed | F35: ★ (boundary) | H35: Kenya | I35: =COUNTIF('Coffee Audit'!F2:F2000,"*Kenya*") -> 2 | J35: 4% | K35: — | L35: HIGH — phosphoric acid · blackcurrant
B36: Lactic Honey | C36: =COUNTIF('Coffee Audit'!H2:H2000,"*Lactic*") -> 1 | D36: 2% | E36: Soft lactic creaminess · glycerol body · tropical arc | F36: ★★★ | H36: Panama | I36: =COUNTIF('Coffee Audit'!F2:F2000,"*Panama*") -> 2 | J36: 4% | K36: ⭐ ×2 | L36: HIGHEST — Gesha heartland
H37: Ecuador | I37: =COUNTIF('Coffee Audit'!F2:F2000,"*Ecuador*") -> 1 | J37: 2% | K37: ⭐ ×1 | L37: HIGHEST — #1 palate DNA fit (Loja Gesha)
H38: Bolivia | I38: =COUNTIF('Coffee Audit'!F2:F2000,"*Bolivia*") -> 2 | J38: 3% | K38: — | L38: HIGH — lactic honey + Pacamara clarity
B40: ⚖️ BREW RATIO INTELLIGENCE — 1:15–1:17 Palate DNA Band · Avg ratio 1:15.7 | H40: 🏅 ARCHIVE HONOURS BOARD — Season 2026
B41: Ratio Band | C41: Entries | D41: In Band? | E41: Chemistry Note | H41: Honour | I41: Holder | J41: Detail
B42: <1:13 | C42: 1 | D42: ⚠️ Edge | E42: Espresso-style concentrations — not filter | H42: 🏆 Cup of the Year | I42: Fluid Collective — El Obraje Washed Gesha | J42: S$14 · Colombia · linalool apex · best Gesha in archive
B43: 1:13–1:14 | C43: 1 | D43: ⚠️ Dense | E43: Polyphenolic bitterness at cool phase (Entry #055 Double Shot) | H43: 👤 Barista #1 (joint) | I43: Aqil — Zerah Roasters | J43: Most knowledgeable & warmest barista engagement
B44: 1:14–1:15 | C44: 7 | D44: ⚠️ Edge | E44: Compressed aromatic headspace — sucrose underdeveloped vs acid | H44: 👤 Barista #1 (joint) | I44: Glenda — Abseil | J44: Technical depth + exceptional hospitality
B45: 1:15–1:17 ✅ | C45: 34 | D45: ✅ OPTIMAL | E45: Core extraction philosophy — 58% of logged entries | H45: 📍 Best Discovery | I45: Oaks Coffee Co. (Day 4 of opening) | J45: Bolivia Pacamara Lactic Honey · S$9 · 5 archive firsts
B46: >1:17 | C46: 0 | D46: — | E46: Dilutes acid structure — CGA lactone risk on Naturals | H46: 🧫 Best Process Arc | I46: Floripondio 90 Hours — Oaks Coffee Co. | J46: Mango → sugar clarity → nectarine · 3-act thermal arc
...

Sheet 🧬 Palate DNA
B1: 🧬 PALATE DNA FINGERPRINT
B2: What 59 cups reveal about one palate — malic acid · linalool · flat-bottom geometry · washed clarity
B4: 📖 THE PALATE THESIS
B5: CLARITY OVER COMPLEXITY. Across 59 cups and 7 months, one pattern dominates: 41% of all entries are Washed process. The palate responds strongest to malic acid (stone fruit, nectarine) and linalool esters (jasmine, bergamot). Gesha/Geisha accounts for 20% of all cups — the apex varietal ordered with deliberate frequency. Flat-bottom geometry outperforms conical in 100% of documented side-by-side comparisons. The 1:15–1:17 ratio band covers 58% of all logged extractions. The archive is not a random tasting record. It is a calibrated instrument.
B10: 🍯 PROCESS PREFERENCE SPECTRUM — Clarity dominates across 59 entries | H10: 🌡️ TEMPERATURE PROTOCOLS — 88–93°C sweet spot
B11: Process | C11: Entries | D11: % | E11: Palate Signal | F11: Affinity | H11: Protocol | I11: Entries | J11: Context
B12: Washed | C12: 22 | D12: 41% | E12: Malic acid clarity · jasmine lift · clean thermal arcs | F12: ★★★★★ Primary | H12: 85–89°C | I12: 1 | J12: Delicate / Nordic style — Abseil 88°C constant for LAB ester preservation
B13: Natural | C13: 12 | D13: 24% | E13: Stone fruit · berry complexity · terroir depth | F13: ★★★★ Secondary | H13: 90–91°C | I13: 9 | J13: Clean balanced extraction — Keryi descending protocol
B14: Honey | C14: 4 | D14: 9% | E14: Mucilage sweetness bridge · ketone fruit layer | F14: ★★★★ Bridge | H14: 92–94°C ⭐ | I14: 7 | J14: Sweet spot — dominant single-temp protocol in Singapore cafés
B15: Anaerobic Natural | C15: 4 | D15: 9% | E15: Controlled funk · ester complexity · tropical esters | F15: ★★★ Experimental | H15: 95°C | I15: 3 | J15: Full extraction — bold washed profiles · Apartment Jalan Riang
B16: Experimental Ferment | C16: 3 | D16: 6% | E16: Yeast / mosto / co-ferment — frontier zone | F16: ★★ Exploratory | H16: 70→90→70°C 🏆 | I16: 7 | J16: Fluid Collective signature oscillation — highest-rated cups in archive
B17: Lactic Honey | C17: 1 | D17: 2% | E17: Soft lactic body · glycerol · creamy mouthfeel | F17: ★★★ Discovery | H17: 90→70°C (descending) | I17: 4 | J17: Keryi / Pinhole / Double Shot — terpene preservation on honey/gesha
B18: Thermal Shock Anaerobic | C18: 1 | D18: 2% | E18: Intensity ceiling confirmed at Entry #059 | F18: ★ Boundary | H18: 80→95→80°C | I18: 1 | J18: Kurasu Frinsa — honey process mucilage management
B19: Wet-Hulled | C19: 1 | D19: 2% | E19: Indonesian terroir · syrupy body · one-off | F19: ★ Reference | H19: 88°C constant | I19: 1 | J19: Oaks — LAB lactic ester preservation (Bolivia Pacamara)
B21: ⭐ COLOMBIA GESHA PROCESS TRILOGY — Completed 2026 · Three processes · One verdict | H21: ⚖️ RATIO BAND ANALYSIS — 1:15–1:17 Optimal Window
B22: Process | C22: Café | D22: Sensory Arc | E22: Verdict | H22: Band | I22: Count | J22: Status | K22: Chemistry Note
B23: Washed ⭐ | C23: Fluid Collective (El Obraje) | D23: Mango · Orange Blossom · Nectarine · Honey — linalool apex | E23: CUP OF THE YEAR | H23: <1:13 | I23: 1 | J23: ⚠️ Espresso | K23: Concentration removes filter brewing purpose
B24: Honey | C24: Keryi Coffee (Finca La Esmaralda) | D24: Jasmine · Caramel · Stone Fruit · Tangerine — smooth arc | E24: EXCELLENT | H24: 1:13–1:14 | I24: 1 | J24: ⚠️ Dense | K24: Polyphenolic bitterness amplified · sucrose suppressed (Entry #055)
B25: Honey | C25: Pinhole Coffee Bar (Santa Barbara #1) | D25: Bergamot · Lychee · Mandarin · Honey — cold-cup revelation | E25: VERY GOOD | H25: 1:14–1:15 | I25: 7 | J25: ⚠️ Edge | K25: Aromatic headspace compressed vs optimal
B26: Natural | C26: Homeground (Inmaculada Estate) | D26: Hibiscus · Pomegranate · Darjeeling Tea — relaxing depth | E26: EXCELLENT | H26: 1:15–1:17 ✅ | I26: 34 | J26: ✅ OPTIMAL | K26: Core extraction philosophy — 58% of all logged entries
B27: Natural | C27: Cowpresso (Las Nubes) | D27: Lychee · Berry · Tropical — aggressive Natural expression | E27: GOOD | H27: >1:17 | I27: 0 | J27: — | K27: CGA lactone risk on Naturals — confirmed Entry #056 Nylon
B28: Archive verdict on the Colombia Gesha Trilogy: Washed = genetic purity (apex). Honey = sweetness amplified. Natural = fermentation over clarity. Washed remains unmatched. | H28: Unknown | I28: 16 | J28: — | K28: Early entries pre-hardware protocol · improving each visit

Sheet 🌍 Origin & Terroir
B1: 🌍 ORIGIN & TERROIR ATLAS
B2: Where the archive has travelled — 18 origins · Colombia leads at 30% · 12 Gesha entries across 6 countries
B4: 🗺️ ORIGIN LEAGUE TABLE — live formula, auto-updates with new entries | H4: ⭐ GESHA REGISTER — The Apex Varietal · 12 archive entries
B5: Origin | C5: Entries | D5: Share | E5: Gesha? | F5: Palate DNA Fit | H5: Metric | I5: Value
B6: Colombia | C6: =COUNTIF('Coffee Audit'!F2:F2000,"*Colombia*") -> 18 | D6: 30% | E6: =COUNTIF('Coffee Audit'!G2:G2000,"*Gesha*") -> 9 | F6: HIGHEST — malic + Gesha depth | H6: Total Gesha/Geisha entries | I6: =COUNTIF('Coffee Audit'!W2:W2000,"⭐ GESHA") -> 12
B7: Ethiopia | C7: =COUNTIF('Coffee Audit'!F2:F2000,"*Ethiopia*") -> 7 | D7: 13% | E7: — | F7: HIGH — linalool florals · heirloom terroir | H7: Washed Gesha | I7: =SUMPRODUCT(('Coffee Audit'!W2:W2000="⭐ GESHA")*(ISNUMBER(SEARCH("washed",'Coffee Audit'!H2:H2000)))) -> 6
B8: Brazil | C8: =COUNTIF('Coffee Audit'!F2:F2000,"*Brazil*") -> 5 | D8: 9% | E8: — | F8: MED — body · Maillard sweetness baseline | H8: Honey Gesha | I8: =SUMPRODUCT(('Coffee Audit'!W2:W2000="⭐ GESHA")*(ISNUMBER(SEARCH("honey",'Coffee Audit'!H2:H2000)))) -> 3
B9: Honduras | C9: =COUNTIF('Coffee Audit'!F2:F2000,"*Honduras*") -> 3 | D9: 6% | E9: =COUNTIF('Coffee Audit'!G2:G2000,"*Gesha*") -> 9 | F9: HIGH — malic stone fruit · clean finish | H9: Natural Gesha | I9: =SUMPRODUCT(('Coffee Audit'!W2:W2000="⭐ GESHA")*(ISNUMBER(SEARCH("natural",'Coffee Audit'!H2:H2000)))) -> 3
B10: Indonesia | C10: =COUNTIF('Coffee Audit'!F2:F2000,"*Indonesia*") -> 3 | D10: 6% | E10: — | F10: MED — wet-hulled texture study | H10: Avg Gesha price (SGD) | I10: S$14.70
B11: Peru | C11: =COUNTIF('Coffee Audit'!F2:F2000,"*Peru*") -> 3 | D11: 6% | E11: ⭐ ×2 | F11: HIGH — washed Gesha clarity (Wilder Garcia) | H11: Avg non-Gesha price (SGD) | I11: S$9.59
B12: Kenya | C12: =COUNTIF('Coffee Audit'!F2:F2000,"*Kenya*") -> 2 | D12: 4% | E12: — | F12: HIGH — phosphoric acid · blackcurrant benchmark | H12: Gesha price premium | I12: +53%
B13: Panama | C13: =COUNTIF('Coffee Audit'!F2:F2000,"*Panama*") -> 2 | D13: 4% | E13: ⭐ ×2 | F13: HIGHEST — Gesha heartland (Kotowa · Corpachi) | H13: Origins with Gesha entry | I13: Colombia · Peru · Panama · Ecuador · Honduras
B14: Nicaragua | C14: =COUNTIF('Coffee Audit'!F2:F2000,"*Nicaragua*") -> 2 | D14: 4% | E14: — | F14: MED — clean washed + anaerobic contrast | H14: Highest-priced Gesha | I14: S$21 — El Sauce (Abseil)
B15: Bolivia | C15: =COUNTIF('Coffee Audit'!F2:F2000,"*Bolivia*") -> 2 | D15: 3% | E15: — | F15: HIGH — Lactic Honey Pacamara · new frontier | H15: Best-value Gesha | I15: S$9.90 — Las Nubes (Cowpresso)
B16: Ecuador | C16: =COUNTIF('Coffee Audit'!F2:F2000,"*Ecuador*") -> 1 | D16: 2% | E16: ⭐ ×1 | F16: HIGHEST — #1 palate fit (Loja Gesha) | H16: Archive verdict — apex process | I16: Washed (genetic purity over fermentation)
B17: India | C17: =COUNTIF('Coffee Audit'!F2:F2000,"*India*") -> 3 | D17: 4% | E17: — | F17: MED — anaerobic exploration · Subko/Grey Soul
B18: Malaysia | C18: =COUNTIF('Coffee Audit'!F2:F2000,"*Malaysia*") -> 1 | D18: 2% | E18: — | F18: REF — Liberica · archive first non-Arabica
B19: China | C19: =COUNTIF('Coffee Audit'!F2:F2000,"*China*") -> 1 | D19: 2% | E19: — | F19: REF — Yunnan Purple Leaf Caturra · surprise entry
B20: Rwanda | C20: =COUNTIF('Coffee Audit'!F2:F2000,"*Rwanda*") -> 1 | D20: 2% | E20: — | F20: MED — baked apple · citric-malic duality
B21: Myanmar | C21: =COUNTIF('Coffee Audit'!F2:F2000,"*Myanmar*") -> 1 | D21: 2% | E21: — | F21: REF — batch-brew study · Catimor lineage
B22: El Salvador | C22: =COUNTIF('Coffee Audit'!F2:F2000,"*Salvador*") -> 1 | D22: 2% | E22: — | F22: MED — Pacamara Natural · Aanya's first filter
B24: 🎯 VARIETAL TARGET REGISTER — what's been captured & what remains
B25: Varietal | C25: Status | D25: Archive Entry | E25: Process Encountered | F25: Note
B26: Gesha/Geisha | C26: ✅ CAPTURED | D26: Multiple — Entry #017 onward | E26: Washed · Honey · Natural · Anaerobic Washed | F26: Apex varietal · 12 entries
B27: Pacamara | C27: ✅ CAPTURED | D27: Entry #049 — Oaks Coffee Co. | E27: Lactic Honey (90hr) | F27: First Bolivia · first Pacamara
B28: Aji Bourbon | C28: ✅ CAPTURED | D28: Entry #059 — Oaks Coffee Co. | E28: Thermal Shock Anaerobic Natural | F28: Finca El Diviso · Nestor Lasso
B29: Sudan Rume | C29: ✅ CAPTURED | D29: Entry #018 — Maxi Coffee Bar | E29: Washed | F29: Yellow variant also at Asylum #038
B30: Pink Bourbon | C30: ✅ CAPTURED | D30: Entry #048 — Zerah Roasters | E30: Washed | F30: Finca Villarazo · DF83V debut
B31: Wush Wush | C31: ✅ CAPTURED | D31: Entry #011 — Apartment Selegie | E31: Washed | F31: Tea-like clarity standout
B32: Hybrid Laurina | C32: ✅ CAPTURED | D32: Entry #035 — Alchemist OFC | E32: Anaerobic Natural | F32: Low-caffeine mutation
B33: Caturra Chiroso | C33: ✅ CAPTURED | D33: Entry #025 — Zerah Roasters | E33: Yeast Anaerobic Natural | F33: Elongated Gesha-adjacent cell
B34: Liberica | C34: ✅ CAPTURED | D34: Entry #039 — Corner Corner | E34: JH Natural | F34: Archive's only non-Arabica
B35: Purple Leaf Caturra | C35: ✅ CAPTURED | D35: Entry #036 — Apartment | E35: Double Washed | F35: China Yunnan · anthocyanin clarity
B36: Typica Mejorado | C36: ✅ CAPTURED | D36: Entry #023 — Clod Coffee Bar | E36: Anaerobic Washed | F36: JB cross-border audit
... B39: Sidra | C39: ❌ MISSING | D39: — | E39: — | F39: Watchlist — Fahrenheit Coffee target

Sheet ⚙️ Hardware
B1: ⚙️ HARDWARE & EXTRACTION PHYSICS
B2: Flat burrs · flat beds · the physics of clarity · precision instruments for a precision palate
B4: 🔩 GRINDER PLATFORM REGISTER — flat burr platforms deliver the archive's best cups
B5: Platform | C5: Entries | D5: Burr Size | E5: Palate Impact | F5: Archive Entries
B6: Option-O Lagom P80 | C6: 2 | D6: 80mm flat | E6: First P80 in archive — Entry #049 Oaks. Unimodal PSD on oversized Pacamara beans. | F6: Oaks Coffee Co. ×2
B7: Option-O Lagom P64 | C7: 8 | D7: 64mm flat | E7: Preferred precision platform — Fluid, Asylum, Abseil. Minimal fines. | F7: Fluid · Asylum · Zerah · Abseil
B8: Mahlkönig EK43/EK43S | C8: 12 | D8: 98mm flat | E8: Café workhorse — widest flat burr in archive. High throughput, competition heritage. | F8: Homeground · Lume · Keryi · Agora
B9: Mahlkönig EK Omnia | C9: 4 | D9: 98mm flat | E9: EK43 successor — Nylon standard grinder across all 6 visits. | F9: Nylon Coffee Roasters ×4
B10: Ditting (63.5/98mm) | C10: 2 | D10: 63.5–98mm flat | E10: Lab-grade narrow PSD — Double Shot + Keryi. Licensed aggressive ratios. | F10: Double Shot · Keryi Coffee
B11: DF83V (83mm flat) | C11: 1 | D11: 83mm flat | E11: First DF83 in archive — Zerah Pink Bourbon. Zero fines at 83mm. | F11: Zerah Roasters
B12: Timemore Sculptor 078 | C12: 2 | D12: 78mm flat | E12: Compact 78mm — Maxi Coffee Bar · mid-range precision tier. | F12: Maxi Coffee Bar ×2
B13: FM 120mm Hybrid | C13: 2 | D13: 120mm hybrid | E13: Largest burr in archive — extreme fines reduction for SL28/SL34 Kenya. | F13: Kyuukei Coffee × 2
B14: Mazzer MM (83mm) | C14: 1 | D14: 83mm flat | E14: PPP Funan — wider fines than 98mm reference. Over-extraction documented. | F14: PPP Coffee (Funan)
B15: Timemore Conical Gold | C15: 1 | D15: Conical | E15: Corner Corner — Liberica. Only conical burr in archive. Softer extraction. | F15: Corner Corner
B17: ☕ BREWER GEOMETRY ANALYSIS — flat-bottom wins every documented comparison
B18: Geometry | C18: Entries | D18: Archive Status | E18: Chemistry Note
B19: Flat-Bottom (Origami/OREA/April/xBloom/Alpha/Switch) | C19: 28 | D19: ✅ PRIMARY PREFERENCE | E19: Even bed saturation · zero bypass · full contact geometry. Delivers archive's highest-rated cups consistently.
B20: CT62 (Engineered Conical — 24-groove flow compensation) | C20: 1 | D20: ✅ EXEMPTED | E20: Entry #057 Abseil. 12 long + 12 short grooves regulate flow rate = flat-bottom equivalent extraction consistency.
B21: Standard Conical (V60) | C21: 7 | D21: ⚠️ OVER-EXTRACTION FLAG | E21: Documented over-extraction pattern at Agora (Beloya), Kurasu (Rwanda), PPP (Suke Quto), Cowpresso. Fine particle apex creates CGA bitterness.
B22: Automated (xBloom batch) | C22: 4 | D22: ⚠️ METHODOLOGY NOTE | E22: xBloom at Nylon — flat-bottom geometry, but automation removes barista pour adjustment. Clips thermal arc expressiveness.
B23: Immersion-assist (Hario Switch/Deep27) | C23: 5 | D23: ✅ SECONDARY PREFERENCE | E23: Full bed saturation in immersion phase before drawdown. Strong on honey process (Keryi). Deep27 debut Entry #047 Kyuukei.
B24: Automated Tap Dispenser | C24: 1 | D24: ❌ REJECTED CONCEPT | E24: Entry #045 — 2050 Coffee. Hari's verdict: automation and pourover are philosophically incompatible. Not a return target.
B26: 📜 SIX EXTRACTION LAWS — empirically proven across 59 field audits
B27: Law 1: Flat-bottom geometry outperforms conical for this palate. Every conical V60 entry carries a standing over-extraction risk flag in this archive.
B28: Law 2: 1:13–1:14 concentration amplifies polyphenolic bitterness at cool phase and suppresses sucrose emergence. Documented at Double Shot (Entry #055) and Equate (Entry #039).
B29: Law 3: 1:17 lean on Natural-process coffees risks CGA lactone bitterness at cool phase by failing to build adequate sucrose-ester mass. Confirmed at Nylon (Entry #056).
B30: Law 4: Barista confirmation overrides visual inference for hardware identification — always. This is the archive's primary source hierarchy rule.
B31: Law 5: Large flat burrs (63–98mm) are non-negotiable for oversized varietals (Pacamara, Maragogipe-lineage). P80 80mm confirmed at Oaks Entry #049.
B32: Law 6: Thermal Shock Anaerobic Natural (Finca El Diviso, Entry #059) confirmed the archive's upper intensity threshold. Fermentation signal dominated all three thermal phases without evolution — process-preference misalignment ceiling established.

Sheet 🏙️ Café Directory
B1: 🏙️ CAFÉ DIRECTORY — 33 VENUES · 4 CITIES
B2: Live-verified July 2026 · SuperGrok · ChatGPT · Gemini · direct observation · four-tier confidence rating
B4: 🌏 CITY COVERAGE OVERVIEW
B5: City | C5: Entries | D5: Cafés | E5: Coverage | F5: Character
B6: Singapore | C6: =COUNTIF('Coffee Audit'!B2:B2000,"*Singapore*") -> 53 | D6: 31 | E6: 94% | F6: Roaster-owned specialty scene · transparent parameters · competition hardware standard
B7: Ubud, Bali | C7: =COUNTIF('Coffee Audit'!B2:B2000,"*Bali*") -> 3 | D7: 1 | E7: 3% | F7: Archive origin chapter — Seniman Coffee Studio
B8: Mumbai | C8: =COUNTIF('Coffee Audit'!B2:B2000,"*Mumbai*") -> 2 | D8: 2 | E8: 2% | F8: India frontier chapter — Subko + Grey Soul
B9: Johor Bahru | C9: =COUNTIF('Coffee Audit'!B2:B2000,"*Johor*") -> 1 | D9: 1 | E9: 2% | F9: Cross-border audit — Clod Coffee Bar & Roasters
B11: ☕ COMPLETE VERIFIED DIRECTORY — 33 venues · live entry counts · verified addresses
B12: Café | C12: City | D12: Entries | E12: Gesha | F12: Avg | G12: Verified Address | H12: Instagram | I12: Website | J12: Conf. | K12: Notes
B13: Nylon Coffee Roasters | C13: Singapore | D13: =COUNTIF('Coffee Audit'!C2:C2000,B13) -> 6 | E13: =SUMPRODUCT(('Coffee Audit'!C2:C2000=B13)*('Coffee Audit'!W2:W2000="⭐ GESHA")) -> 0 | F13: =IFERROR(TEXT(AVERAGEIFS('Coffee Audit'!Q2:Q2000,'Coffee Audit'!C2:C2000,B13,'Coffee Audit'!Q2:Q2000,">0"),"S$0.00"),"—") -> 0$0.00 | G13: 4 Everton Park, #01-40 | H13: @nyloncoffeeroasters | I13: nyloncoffee.sg | J13: ✅ HIGH | K13: Reliability anchor · 6 visits
