Workbook

Sheet Coffee Audit
A1: Date | B1: City | C1: Cafe_Name | D1: Coffee_Name | E1: Producer_Farm | F1: Origin | G1: Varietal | H1: Process | I1: Roast_Level | J1: Brew_Method | K1: Dose_g | L1: Yield_g | M1: Ratio | N1: Water_Temp_C | O1: Bloom | P1: Grinder | Q1: Price_SGD | R1: Official_Notes | S1: Your_Verdict | T1: Technical_Enrichment | U1: Visit_Context | V1: Source | W1: Gesha_Alert | X1: Address
A2: 46025 | B2: Ubud, Bali | C2: Seniman Coffee Studio | D2: Bali Karana Kintamanis | E2: Unknown | F2: Kintamani, Bali | G2: Unknown | H2: Natural | I2: Light | J2: Filter | K2: Unknown | L2: Unknown | M2: Unknown | N2: Unknown | O2: Unknown | P2: Unknown | Q2: Unknown | R2: Clean citrus; floral | S2: Excellent clarity for a natural process; clean citrus and floral notes. | T2: Natural processing contributed mild fruit-forward esters with relatively clean finish; foundational exposure to local Indonesian origins. | U2: Bali family trip | V2: Merged (Gemini + ChatGPT) | W2: =IF(OR(ISNUMBER(SEARCH("gesha",G2)),ISNUMBER(SEARCH("geisha",G2))),"⭐ GESHA","") | X2: Jl. Sri Wedari No.5, Ubud, Gianyar, Bali 80571, Indonesia
A3: 46026 | B3: Ubud, Bali | C3: Seniman Coffee Studio | D3: Sulawesi Toraja | E3: Unknown | F3: Sulawesi, Indonesia | G3: Unknown | H3: Wet-Hulled | I3: Medium | J3: Pour-over | K3: Unknown | L3: Unknown | M3: Unknown | N3: Unknown | O3: Unknown | P3: Unknown | Q3: Unknown | R3: Cocoa; earthy structures | S3: Heavy body with rich cocoa and earthy notes; low acidity; dense mouthfeel. | T3: Classic Giling Basah wet-hulled process emphasized earthy compounds and syrupy mouthfeel; structural density confirmed. | U3: Bali family trip | V3: Merged (Gemini + ChatGPT) | W3: =IF(OR(ISNUMBER(SEARCH("gesha",G3)),ISNUMBER(SEARCH("geisha",G3))),"⭐ GESHA","") | X3: Jl. Sri Wedari No.5, Ubud, Gianyar, Bali 80571, Indonesia
A4: 46026 | B4: Ubud, Bali | C4: Seniman Coffee Studio | D4: House Blend | E4: Unknown | F4: Unknown | G4: Unknown | H4: Unknown | I4: Espresso Roast | J4: Piccolo | K4: Unknown | L4: Unknown | M4: Unknown | N4: Unknown | O4: Unknown | P4: Unknown | Q4: Unknown | R4: Balanced | S4: Great milk integration; standard espresso + milk calibration. | T4: Baseline milk pairing; milk fats softened acidity and amplified sweetness and body. | U4: Bali family trip | V4: Merged (Gemini + ChatGPT) | W4: =IF(OR(ISNUMBER(SEARCH("gesha",G4)),ISNUMBER(SEARCH("geisha",G4))),"⭐ GESHA","") | X4: Jl. Sri Wedari No.5, Ubud, Gianyar, Bali 80571, Indonesia
A5: 46063 | B5: Singapore | C5: Kyuukei Coffee | D5: Kenya Kiamugumo AA | E5: New Ngariama Farmer's Cooperative Society | F5: Kiamugumo, Murang'a County, Kenya | G5: SL28 / SL34 | H5: Washed | I5: Unknown | J5: Pour-over (Flat-Bottom) | K5: 15 | L5: 240 | M5: 1:16 | N5: 93 | O5: Unknown | P5: 120mm Hybrid Burr | Q5: 8 | R5: Blackcurrant, Lemon, Citrus Zest, Mineral Finish | S5: Extremely clean and structured — classic Kenyan profile. Bright blackcurrant acidity layered with lemon and light white grape sweetness. Clarity was the standout: no fermentation noise, no muddiness — precise, well-executed extraction. Compelling demonstration of how a well-processed washed coffee performs when roasted and brewed correctly. Phosphoric acid signature fully confirmed across all phases. | T5: 120mm hybrid burr grinder delivered uniform particle distribution; flat-bottom pour-over geometry ensured even extraction across the full puck. 93°C water temp and 1:16 lean ratio preserved SL28/SL34 phosphoric acid clarity without over-extracting into bitterness. Brew time 2:45 consistent with controlled drawdown on flat-bottom geometry. Kenyan phosphoric acid and anthocyanin-driven blackcurrant notes are varietal signatures of Scott Laboratories SL28/SL34 genetics. | U5: Solo visit — early archive period, first Kyūkei filter audit | V5: Direct observation + infographic + Google review (10 Feb 2026) | W5: =IF(OR(ISNUMBER(SEARCH("gesha",G5)),ISNUMBER(SEARCH("geisha",G5))),"⭐ GESHA","") | X5: 121 Bukit Merah Lane 1, #01-06, Singapore 150121
A6: 46082 | B6: Mumbai | C6: Subko Coffee Roasters | D6: Project Pearl Ratnagiri | E6: Ratnagiri Estate | F6: India | G6: Unknown | H6: Anaerobic Natural | I6: Light (Agtron 89) | J6: Filter | K6: Unknown | L6: Unknown | M6: Unknown | N6: Unknown | O6: Unknown | P6: Unknown | Q6: Unknown | R6: Unknown | S6: Clean and balanced; interesting but restrained anaerobic expression. | T6: Very light roast (Agtron 89) suppressed ester development despite anaerobic process; muted expected fermented intensity. | U6: Mumbai café exploration | V6: Merged (Gemini + ChatGPT) | W6: =IF(OR(ISNUMBER(SEARCH("gesha",G6)),ISNUMBER(SEARCH("geisha",G6))),"⭐ GESHA","") | X6: Mary Lodge, 21A Chapel Rd, Ranwar, Bandra West, Mumbai 400050, India
A7: 46089 | B7: Mumbai | C7: Grey Soul Coffee Roasters | D7: Raspberry in Loop - Zoya Estate | E7: Zoya Estate | F7: India | G7: Unknown | H7: Multi-stage Anaerobic | I7: Medium | J7: Filter | K7: Unknown | L7: Unknown | M7: Unknown | N7: Unknown | O7: Unknown | P7: Unknown | Q7: Unknown | R7: Chocolate | S7: Heavy body; over-smoothed expression muted brightness and terroir. | T7: Higher development in medium roast reduced aggressive fruit acidity; heavy multi-stage fermentation suppressed terroir expression. | U7: Mumbai café exploration | V7: Merged (Gemini + ChatGPT) | W7: =IF(OR(ISNUMBER(SEARCH("gesha",G7)),ISNUMBER(SEARCH("geisha",G7))),"⭐ GESHA","") | X7: Dr Ambedkar Rd, Pali Village, Bandra West, Mumbai 400050, India
A8: 46099 | B8: Singapore | C8: Narrative Coffee Stand | D8: Finca La Siberia | E8: Unknown | F8: El Salvador | G8: Pacamara | H8: Natural | I8: Light | J8: Pour-over | K8: Unknown | L8: Unknown | M8: Unknown | N8: Unknown | O8: Unknown | P8: Unknown | Q8: Unknown | R8: Unknown | S8: Stewed apples; Apricot; Pu'er tea — Aanya's first specialty filter experience. | T8: Natural Pacamara generated beginner-friendly fruit esters and approachable sweetness; large Pacamara bean size aided even extraction. | U8: Father-daughter coffee exploration | V8: ChatGPT only | W8: =IF(OR(ISNUMBER(SEARCH("gesha",G8)),ISNUMBER(SEARCH("geisha",G8))),"⭐ GESHA","") | X8: Blk 231 Bain St, #01-05, Singapore 180231
A9: 46099 | B9: Singapore | C9: Narrative Coffee Stand | D9: El Puente | E9: Unknown | F9: Honduras | G9: Catuai | H9: Washed | I9: Medium-Light | J9: Espresso | K9: Unknown | L9: Unknown | M9: Unknown | N9: Unknown | O9: Unknown | P9: Unknown | Q9: Unknown | R9: Unknown | S9: Black cherry; Apricot; Pecan — ordered for espresso contrast. | T9: Washed Central American espresso balanced nutty sweetness and fruit acidity; Catuai's consistent cell structure aided uniform extraction. | U9: Father-daughter coffee exploration | V9: ChatGPT only | W9: =IF(OR(ISNUMBER(SEARCH("gesha",G9)),ISNUMBER(SEARCH("geisha",G9))),"⭐ GESHA","") | X9: Blk 231 Bain St, #01-05, Singapore 180231
A10: 46099 | B10: Singapore | C10: ASK Coffee Roastery | D10: Honduras Masaguara (S13) | E10: Unknown | F10: Honduras | G10: Catuai / Caturra | H10: Washed Co-Ferment | I10: Light | J10: Pour-over | K10: Unknown | L10: Unknown | M10: Unknown | N10: Unknown | O10: Unknown | P10: Unknown | Q10: 15 | R10: Lychee; Brandy; Honeydew; Milk Chocolate | S10: Premium but memorable; highly complex tropical profile. | T10: Co-fermentation amplified tropical ester complexity; co-ferment substrates introduced lychee lactones and brandy-like ethyl esters. | U10: Father-daughter coffee exploration | V10: ChatGPT only | W10: =IF(OR(ISNUMBER(SEARCH("gesha",G10)),ISNUMBER(SEARCH("geisha",G10))),"⭐ GESHA","") | X10: 32 Seah St, Singapore 188388
A11: 46099 | B11: Singapore | C11: ASK Coffee Roastery | D11: House Blend | E11: Unknown | F11: Unknown | G11: Unknown | H11: Unknown | I11: Unknown | J11: Magic (Ristretto Milk) | K11: Unknown | L11: Unknown | M11: Unknown | N11: Unknown | O11: Unknown | P11: Unknown | Q11: Unknown | R11: Unknown | S11: Contrast milk calibration; excellent concentrated cocoa expression. | T11: Ristretto milk extraction increased sweetness density and concentrated cocoa compounds through reduced water content. | U11: Father-daughter coffee exploration | V11: ChatGPT only | W11: =IF(OR(ISNUMBER(SEARCH("gesha",G11)),ISNUMBER(SEARCH("geisha",G11))),"⭐ GESHA","") | X11: 32 Seah St, Singapore 188388
A12: 46103 | B12: Singapore | C12: Apartment (Selegie Rd) | D12: Colombia Don Gallego - Wush Wush | E12: Don Gallego | F12: Colombia | G12: Wush Wush | H12: Washed | I12: Light | J12: Pour-over (Flat-Bottom) | K12: Unknown | L12: Unknown | M12: 1:17 | N12: Unknown | O12: Unknown | P12: Unknown | Q12: Unknown | R12: Tea-like | S12: Incredible tea-like clarity; transparent floral expression. | T12: Lean 1:17 ratio maximized aromatic separation; Wush Wush's Ethiopian-lineage genetics produced delicate phenolic and floral complexity. | U12: Solo specialty calibration | V12: Merged (Gemini + ChatGPT) | W12: =IF(OR(ISNUMBER(SEARCH("gesha",G12)),ISNUMBER(SEARCH("geisha",G12))),"⭐ GESHA","") | X12: 139 Selegie Rd, #01-01, Singapore 188309
A13: 46105 | B13: Singapore | C13: Kyuukei Coffee | D13: Kenya Ndiaini AA | E13: Unknown | F13: Kenya | G13: SL28 / SL34 / Ruiru 11 | H13: Washed | I13: Unknown | J13: Pour-over | K13: Unknown | L13: Unknown | M13: Unknown | N13: Unknown | O13: Unknown | P13: Unknown | Q13: 9 | R13: Redcurrant; Elderflower; Lemon; Apricot | S13: Acidic and interesting; well balanced; high clarity. | T13: Ruiru 11 introduced structural body alongside classic SL28/SL34 brightness; further Kenyan terroir depth confirmed. | U13: Solo specialty calibration | V13: Merged (Gemini + ChatGPT) | W13: =IF(OR(ISNUMBER(SEARCH("gesha",G13)),ISNUMBER(SEARCH("geisha",G13))),"⭐ GESHA","") | X13: 121 Bukit Merah Lane 1, #01-06, Singapore 150121
A14: 46106 | B14: Singapore | C14: Agora Coffee | D14: Nicaragua Matagalpa - Finca La Virgen | E14: Finca La Virgen | F14: Nicaragua | G14: Unknown | H14: Fully Washed | I14: Espresso Roast | J14: Flat White | K14: Unknown | L14: Unknown | M14: Unknown | N14: Unknown | O14: Unknown | P14: Unknown | Q14: Unknown | R14: Caramel; Chocolate; Red Apple | S14: Solid milk beverage; clean apple acidity preserved in milk integration. | T14: Fully washed Central American profile preserved clean malic acidity in milk; espresso roast development amplified caramel Maillard notes. | U14: Solo specialty calibration | V14: Merged (Gemini + ChatGPT) | W14: =IF(OR(ISNUMBER(SEARCH("gesha",G14)),ISNUMBER(SEARCH("geisha",G14))),"⭐ GESHA","") | X14: 31 Club St, #01-02, Singapore 069468
A15: 46108 | B15: Singapore | C15: Agora Coffee | D15: Ethiopia Yirgacheffe Beloya | E15: Beloya | F15: Yirgacheffe, Ethiopia | G15: Heirloom | H15: Natural | I15: Filter Roast | J15: V60 | K15: 15 | L15: 220 | M15: 1:14.6 | N15: Unknown | O15: Unknown | P15: Mahlkönig EK43 | Q15: Unknown | R15: Blackcurrant; Strawberry; White Floral | S15: Bright, floral, and distinct strawberry; classic natural Ethiopian profile. | T15: EK43 98mm flat burrs reduced fines and preserved clarity despite natural processing; 1:14.6 ratio retained fruity body. | U15: Solo specialty calibration | V15: Merged (Gemini + ChatGPT) | W15: =IF(OR(ISNUMBER(SEARCH("gesha",G15)),ISNUMBER(SEARCH("geisha",G15))),"⭐ GESHA","") | X15: 31 Club St, #01-02, Singapore 069468
A16: 46109 | B16: Singapore | C16: Tiong Hoe Specialty Coffee | D16: Brazil Mogiana | E16: Unknown | F16: Mogiana, Brazil | G16: Unknown | H16: Natural | I16: Medium | J16: Pour-over | K16: 15 | L16: 225 | M16: 1:15 | N16: Unknown | O16: Unknown | P16: Unknown | Q16: 8 | R16: Red Dates; Chocolates; Honey | S16: Chocolate-heavy and satisfying; classic dense Brazilian profile. | T16: Tighter 1:15 ratio increased body and amplified Maillard-derived caramel sweetness; medium roast caramelized sugars without losing origin character. | U16: Solo specialty calibration | V16: Merged (Gemini + ChatGPT) | W16: =IF(OR(ISNUMBER(SEARCH("gesha",G16)),ISNUMBER(SEARCH("geisha",G16))),"⭐ GESHA","") | X16: 1 Harbourfront Walk, VivoCity Fairprice Xtra, #B2-23, Singapore 098585
A17: 46109 | B17: Singapore | C17: Tiong Hoe Specialty Coffee | D17: Smoky Quartz Blend | E17: Unknown | F17: Brazil + India | G17: Unknown | H17: Unknown | I17: Unknown | J17: Piccolo Latte | K17: Unknown | L17: Unknown | M17: Unknown | N17: Unknown | O17: Unknown | P17: Unknown | Q17: 5.1 | R17: Dark Chocolates; Hazelnut; Smoky | S17: Strong milk side calibration; excellent concentrated cocoa expression. | T17: Low milk volume in piccolo format concentrated cocoa and hazelnut compounds; cross-origin blend leveraged Indian robusta structural density. | U17: Solo specialty calibration | V17: ChatGPT only | W17: =IF(OR(ISNUMBER(SEARCH("gesha",G17)),ISNUMBER(SEARCH("geisha",G17))),"⭐ GESHA","") | X17: 1 Harbourfront Walk, VivoCity Fairprice Xtra, #B2-23, Singapore 098585
A18: 46110 | B18: Singapore | C18: Asylum Coffeehouse | D18: Peru Cajamarca Gesha (Iced) | E18: Wilder Garcia | F18: Cajamarca, Peru | G18: Gesha | H18: Washed | I18: Medium | J18: Iced Pour-over | K18: 15 | L18: 240 | M18: 1:16 | N18: 92.5 | O18: Unknown | P18: Option-O Lagom P64 | Q18: 11 | R18: Jasmine; Caramel; Lime; Cacao Nibs | S18: Super floral and elegant; flash-chilled expression of Gesha purity. | T18: Flash-chilled extraction via Option-O Lagom P64 preserved volatile floral monoterpenes (linalool); cold dilution stabilized aromatic compounds. | U18: Solo specialty calibration | V18: ChatGPT only | W18: =IF(OR(ISNUMBER(SEARCH("gesha",G18)),ISNUMBER(SEARCH("geisha",G18))),"⭐ GESHA","") -> ⭐ GESHA | X18: 311 Jln Besar, Singapore 208970
A19: 46113 | B19: Singapore | C19: Maxi Coffee Bar | D19: La Laja | E19: James Fernandez | F19: Cauca, Colombia | G19: Sudan Rume | H19: Washed | I19: Light | J19: Pour-over (Flat-Bottom) | K19: 15 | L19: 230 | M19: 1:15.3 | N19: 90-92 | O19: Unknown | P19: FM Grinder 120mm Flat Burr / Timemore Sculptor 078 | Q19: 9 | R19: Raspberry; Nectarine; Floral | S19: Nectarine and raspberry extremely clear; barista sophistication superb; technical milestone. | T19: 120mm flat burr geometry maximized uniform particle distribution; flat-bottom brewer enhanced sweetness while preserving Sudan Rume's rare genetic clarity. | U19: CBD lunch calibration | V19: Merged (Gemini + ChatGPT) | W19: =IF(OR(ISNUMBER(SEARCH("gesha",G19)),ISNUMBER(SEARCH("geisha",G19))),"⭐ GESHA","") | X19: 64 Club St, Back Entrance, Singapore 069438
A20: 46113 | B20: Singapore | C20: Lume Café | D20: Corpachi Panama Geisha | E20: Corpachi | F20: Boquerón, Chiriquí, Panama | G20: Geisha | H20: Red Honey | I20: Filter Roast | J20: V60 | K20: Unknown | L20: Unknown | M20: 1:15 | N20: 90 + 70 | O20: Unknown | P20: Mahlkönig EK43 | Q20: 12 | R20: Mandarin Candy; Jasmine; Apricot | S20: Clearly perceived apricot and structured sweetness. | T20: Dual-temperature extraction balanced aromatics and body in honey-process Geisha; red honey partial mucilage retention amplified structured sweetness. | U20: Rainy CBD lunch calibration | V20: ChatGPT only | W20: =IF(OR(ISNUMBER(SEARCH("gesha",G20)),ISNUMBER(SEARCH("geisha",G20))),"⭐ GESHA","") -> ⭐ GESHA | X20: 108 Robinson Rd, #01-01, Singapore 068900
A21: 46117 | B21: Singapore | C21: Asylum Coffeehouse | D21: Castillo Watermelon (Jairo Arcila) | E21: Jairo Arcila | F21: Armenia, Quindío, Colombia | G21: Castillo | H21: Washed Co-Ferment (Watermelon Anaerobic) | I21: Unknown | J21: Pour-over (V60) | K21: 15 | L21: 225 | M21: 1:15 | N21: 90 + 70 | O21: Unknown | P21: Mahlkönig EK43 | Q21: 12.5 | R21: Watermelon; Mint; Lime; Chocolate | S21: Distinct fruit-forward expression; sweetness layered rather than sharp; experimental but controlled. | T21: Watermelon co-fermentation enhanced volatile ester complexity; dual-temperature extraction preserved layered aromatic architecture. | U21: Father-daughter coffee session | V21: Merged (Gemini + ChatGPT) | W21: =IF(OR(ISNUMBER(SEARCH("gesha",G21)),ISNUMBER(SEARCH("geisha",G21))),"⭐ GESHA","") | X21: 311 Jln Besar, Singapore 208970
A22: 46117 | B22: Singapore | C22: Asylum Coffeehouse | D22: Peru Gesha (Wilder Garcia) | E22: Wilder Garcia | F22: Jaén, Peru | G22: Gesha | H22: Washed | I22: Filter Roast | J22: Pour-over (V60) | K22: 15 | L22: 225 | M22: 1:15 | N22: 90 + 70 | O22: Unknown | P22: Mahlkönig EK43 | Q22: 12.5 | R22: Jasmine; Caramel; Lime; Cacao Nibs | S22: Clean, structured, high-clarity cup; apricot-like sweetness and excellent structure. | T22: Dual-temperature extraction engineered aromatic separation and body control; Gesha genetics delivered intrinsic phenolic complexity with minimal processing interference. | U22: Father-daughter coffee session | V22: Merged (Gemini + ChatGPT) | W22: =IF(OR(ISNUMBER(SEARCH("gesha",G22)),ISNUMBER(SEARCH("geisha",G22))),"⭐ GESHA","") -> ⭐ GESHA | X22: 311 Jln Besar, Singapore 208970
A23: 46120 | B23: Singapore | C23: Maxi Coffee Bar | D23: La Villa #1 | E23: Eduard Gaviria | F23: Huila, Colombia | G23: Papayo | H23: Natural | I23: Unknown | J23: Pour-over (Flat-Bottom) | K23: 15 | L23: 225 | M23: 1:15 | N23: Unknown | O23: Unknown | P23: Timemore Sculptor 078 | Q23: 9 | R23: Stewed Forest Berries; Grape; Black Forest Cake | S23: Dense fruit profile with rounded sweetness. | T23: Flat-bottom geometry and tight 1:15 ratio emphasized body; Papayo varietal's high sugar content amplified by natural processing into rich fruit-cake profile. | U23: Lunch catch-up with Yichen | V23: ChatGPT only | W23: =IF(OR(ISNUMBER(SEARCH("gesha",G23)),ISNUMBER(SEARCH("geisha",G23))),"⭐ GESHA","") | X23: 64 Club St, Back Entrance, Singapore 069438
A24: 46130 | B24: Johor Bahru | C24: Clod Coffee Bar & Roasters | D24: Hacienda La Florida | E24: Unknown | F24: Unknown | G24: Typica Mejorado | H24: Anaerobic Washed | I24: Unknown | J24: Origami (Conical) | K24: 18 | L24: 277 | M24: 1:15.4 | N24: Unknown | O24: 42g / 30s (1:2.3) | P24: Mahlkönig EK Omnia | Q24: 11.08 | R24: Lemon verbena; Red plum; Citronella; Hibiscus | S24: Excellent. Lime when hot, distinct plum as it cooled. | T24: EK Omnia precision grind and Origami conical drove extreme clarity; thermal phase shift perfectly isolated citric-to-malic acid transition (lime → plum). | U24: Unknown | V24: Gemini only | W24: =IF(OR(ISNUMBER(SEARCH("gesha",G24)),ISNUMBER(SEARCH("geisha",G24))),"⭐ GESHA","") | X24: 123 Jalan Beringin, Taman Melodies, 80250 Johor Bahru, Malaysia
A25: 46136 | B25: Singapore | C25: Agora Coffee | D25: Brazil Santuário Sul | E25: Unknown | F25: Carmo de Minas, Brazil | G25: Unknown | H25: Natural Fermentation | I25: Light-Medium | J25: V60 | K25: 16 | L25: 224 | M25: 1:14 | N25: 95 | O25: Unknown | P25: Mahlkönig EK43 | Q25: Unknown | R25: Blackcurrant; Black Cherry; Dark Chocolate | S25: Full body; prominent blackcurrant; clear chocolaty finish. | T25: Tight 1:14 ratio engineered maximum body; EK43 98mm burrs maintained clarity to keep fermented natural fruit clean and non-bitter. | U25: Midday specialty calibration | V25: Merged (Gemini + ChatGPT) | W25: =IF(OR(ISNUMBER(SEARCH("gesha",G25)),ISNUMBER(SEARCH("geisha",G25))),"⭐ GESHA","") | X25: 31 Club St, #01-02, Singapore 069468
A26: 46148 | B26: Singapore | C26: Nylon Coffee Roasters | D26: Brazil FAF Organic | E26: Unknown | F26: Brazil | G26: Arara | H26: Natural | I26: Filter Roast | J26: xBloom (Flat-Bottom) | K26: Unknown | L26: Unknown | M26: 1:17 | N26: Unknown | O26: Unknown | P26: Mahlkönig EK Omnia | Q26: 7.5 | R26: Red Apple; Cherry; Raisin; Milk Chocolate | S26: Solid body with crisp green apple (malic) front, resolving into smooth milk chocolate finish. | T26: High-quality Arara natural processing yielded excellent structural body while maintaining crisp malic acidity; xBloom flat-bottom avoided heavy fermentation mud. | U26: Unknown | V26: Gemini only | W26: =IF(OR(ISNUMBER(SEARCH("gesha",G26)),ISNUMBER(SEARCH("geisha",G26))),"⭐ GESHA","") | X26: 4 Everton Park, #01-40, Singapore 080004
A27: 46148 | B27: Singapore | C27: Nylon Coffee Roasters | D27: Brazil Serra dos Ciganos | E27: Unknown | F27: Brazil | G27: Catucai 24/137 | H27: Natural | I27: Espresso Roast | J27: Flat White | K27: Unknown | L27: Unknown | M27: Unknown | N27: Unknown | O27: Unknown | P27: Unknown | Q27: Unknown | R27: Sultana; Dried Apricot; Praline; Roasted Hazelnut | S27: Good cup with pleasant lingering sweet aftertaste. | T27: Milk fats bound perfectly with natural processed espresso; Catucai 24/137 high-density bean structure created long, comforting finish. | U27: Unknown | V27: Gemini only | W27: =IF(OR(ISNUMBER(SEARCH("gesha",G27)),ISNUMBER(SEARCH("geisha",G27))),"⭐ GESHA","") | X27: 4 Everton Park, #01-40, Singapore 080004
A28: 46149 | B28: Singapore | C28: Nylon Coffee Roasters | D28: Ethiopia Banko Gotiti | E28: Unknown | F28: Ethiopia | G28: Heirloom | H28: Washed | I28: Filter Roast | J28: xBloom (Flat-Bottom) | K28: Unknown | L28: Unknown | M28: 1:17 | N28: Unknown | O28: Unknown | P28: Mahlkönig EK Omnia | Q28: 8.5 | R28: Lemonade; Raspberry; Peach; Bergamot | S28: Lemon front, heavy melon mid-cup, fading into clean white tea finish. | T28: 1:17 lean ratio isolated volatile citric acids; xBloom flat-bottom geometry stabilized mid-cup sugars before clean tannin-forward white tea finish. | U28: Unknown | V28: Gemini only | W28: =IF(OR(ISNUMBER(SEARCH("gesha",G28)),ISNUMBER(SEARCH("geisha",G28))),"⭐ GESHA","") | X28: 4 Everton Park, #01-40, Singapore 080004
A29: 46149 | B29: Singapore | C29: Nylon Coffee Roasters | D29: Nicaragua Buena Vista | E29: Unknown | F29: Nicaragua | G29: Parainema | H29: Natural Anaerobic | I29: Espresso Roast | J29: Single Espresso | K29: Unknown | L29: Unknown | M29: ~1:2 | N29: Unknown | O29: Unknown | P29: Unknown | Q29: Unknown | R29: Chiku; Stewed Cherry; Dried Apricot; Brazil Nut | S29: Thick, syrupy body. Highly fermented, savory/not sweet, very long lingering finish. | T29: Anaerobic fermentation metabolized sugars into complex savory esters; 9-bar pressure emulsification drove heavy oil-based viscosity and extended aftertaste. | U29: Unknown | V29: Gemini only | W29: =IF(OR(ISNUMBER(SEARCH("gesha",G29)),ISNUMBER(SEARCH("geisha",G29))),"⭐ GESHA","") | X29: 4 Everton Park, #01-40, Singapore 080004
A30: 46150 | B30: Singapore | C30: Alchemist (Ocean Financial Centre) | D30: El Morito | E30: Unknown | F30: Colombia | G30: Marshell | H30: Washed | I30: Filter Roast | J30: V60 Pour-over (Conical) | K30: 15 | L30: 240 | M30: 1:16 | N30: Unknown | O30: Unknown | P30: Mahlkönig EK43S (98mm Flat Burr) | Q30: Unknown | R30: Yellow Plum; Orange; Cane Sugar | S30: Simultaneous citric-malic acid overlap with integrated cane sugar — smooth and refreshing with excellent mid-palate juiciness. Confirmed: I love this bean. | T30: EK43S 98mm flat burrs + V60 conical at 1:16 delivered perfect dual-acid integration (citric orange + malic plum) without single-note dominance. Sucrose extraction at 1:16 bridged acid structure into clean cane sugar finish. Marshell is an extremely rare Colombian varietal — natural mutation prized for simultaneous citric-malic acid duality. | U30: Solo visit — Alchemist Raffles Place | V30: Master CSV (hari_coffee_audit_master_2026) | W30: =IF(OR(ISNUMBER(SEARCH("gesha",G30)),ISNUMBER(SEARCH("geisha",G30))),"⭐ GESHA","") | X30: 10 Collyer Quay, #01-K1, Singapore 049315
A31: 46154 | B31: Singapore | C31: Kurasu | D31: Indonesia Frinsa Estate | E31: Frinsa Estate | F31: West Java, Indonesia | G31: Local Varietals | H31: Extended Fermentation Honey | I31: Light | J31: Pour-over (Hario Alpha — Flat-Bottom) | K31: 15 | L31: 225 | M31: 1:16 | N31: 80 → 95 → 80 | O31: Unknown | P31: Mahlkönig EK43S (98mm Flat Burr) | Q31: 9.5 | R31: Floral aroma; Stewed Strawberries; Grapefruit; Brown Sugar; Black Tea | S31: Floral taste with a sweet coating on the tongue that gradually sticks and fades off cleanly — sugar and tea aftertaste. Well-executed Indonesian honey with unusual clarity for the origin. | T31: Multi-temperature pour (80→95→80°C) with Hario Alpha flat-bottom perfectly managed heavy honey-process mucilage sugars — clear floral extraction at lower temps, dissolving jammy mucilage at peak heat, finishing cleanly. Extended fermentation honey adds structured sweetness without heavy ferment-funk. First Indonesian-mainland entry in archive (distinct from Bali entries). | U31: Solo visit — Kurasu Singapore | V31: Master CSV (hari_coffee_audit_master_2026) | W31: =IF(OR(ISNUMBER(SEARCH("gesha",G31)),ISNUMBER(SEARCH("geisha",G31))),"⭐ GESHA","") | X31: 261 Waterloo St, #01-24, Singapore 180261
A32: 46155 | B32: Singapore | C32: The Community Coffee (Hamilton) | D32: Jose Mancia Honduras | E32: Jose Mancia | F32: Honduras | G32: Typica | H32: Natural | I32: Filter Roast | J32: Pour-over (Hario Switch — Immersion/Percolation) | K32: 15 | L32: 255 | M32: 1:17 | N32: Unknown | O32: Unknown | P32: Mahlkönig EK43 (98mm Flat Burr) | Q32: 9 | R32: Kiwi; Oolong Tea; Chocolate Truffle | S32: Pretty good. Kiwi and oolong tea style — full bodied. Short finish with slight hints of chocolate. Clean and approachable natural without heavy fermentation noise. | T32: Typica inherent lipid clarity + raised-bed drying produced clean tea-structure body. EK43 98mm flat burrs + Hario Switch immersion phase stabilised full mouthfeel at lean 1:17. Short finish consistent with 15-days-off-roast volatile taper — kiwi and oolong top notes fade rapidly. Honduras Typica at altitude expresses tea-like clarity atypical of natural-process expectations. | U32: Solo visit — The Community Coffee Hamilton | V32: Master CSV (hari_coffee_audit_master_2026) | W32: =IF(OR(ISNUMBER(SEARCH("gesha",G32)),ISNUMBER(SEARCH("geisha",G32))),"⭐ GESHA","") | X32: 38 Hamilton Rd, Singapore 209208
A33: 46157 | B33: Singapore | C33: Alchemist (Ocean Financial Centre) | D33: Ijen Laurina | E33: Ijen Plateau | F33: East Java, Indonesia | G33: Hybrid Laurina | H33: Anaerobic Natural | I33: Light | J33: V60 Pour-over (Conical) | K33: 15 | L33: 240 | M33: 1:16 | N33: 90 | O33: Unknown | P33: Mahlkönig EK43S (98mm Flat Burr) | Q33: 8.5 | R33: Hibiscus; Red Apple; Hawthorn | S33: Felt hibiscus hot. Mid temp showed apple paste. Cooled to a honeyed character. Full bodied. Textbook style flavours — definitely a good one. Clean progressive thermal arc. | T33: 90°C brew temp suppressed lactic ester over-extraction while preserving volatile anthocyanin hibiscus esters. Laurina low-caffeine mutation allows intrinsic sucrose to express as clean honeyed finish without alkaloid bitterness. Anaerobic Natural transformed malic acid into jammy apple paste mid-phase. First Hybrid Laurina varietal in archive — new genetic category unlocked. Hibiscus = anthocyanin; Apple paste = malic lactone; Honey = sucrose at sub-50°C. | U33: Solo visit — Alchemist Ocean Financial Centre | V33: Master CSV (hari_coffee_audit_master_2026) | W33: =IF(OR(ISNUMBER(SEARCH("gesha",G33)),ISNUMBER(SEARCH("geisha",G33))),"⭐ GESHA","") | X33: 10 Collyer Quay, #01-K1, Singapore 049315
A34: 46158 | B34: Singapore | C34: Fluid Collective | D34: El Obraje | E34: El Obraje | F34: Huila, Colombia | G34: Gesha | H34: Washed | I34: Light | J34: Flatbed Dripper (Flat-Bottom) | K34: 15 | L34: 230 | M34: 1:15.3 | N34: 92 | O34: Unknown | P34: Option-O Lagom P64 (64mm Flat Burr) | Q34: 14 | R34: Mango; Orange Blossom; Nectarine; Honey | S34: Damn the taste so nice — the orange nectarine finishing with that honey is terrific. Love this one. So far my favourite. Honey sweetness lingers and taste changes as temperature cools. Best Gesha washed in archive at time of logging. | T34: Lagom P64 64mm flat burrs deliver near-unimodal particle distribution — same hardware platform as Asylum Coffeehouse entries, enabling pure terroir delta comparison between Colombia Gesha (El Obraje, Huila) and Peru Gesha (Wilder Garcia, Jaén). 92°C at 1:15.3 maximised linalool floral ester retention while stabilising malic acid mango-nectarine backbone. Flat-bottom eliminated bypass and ensured even bed saturation — critical for preserving fragile Gesha aromatics. Honey finish = sucrose preserved at washed-process mucilage removal stage. | U34: Solo visit — FLUID Singapore | V34: Master CSV (hari_coffee_audit_master_2026) | W34: =IF(OR(ISNUMBER(SEARCH("gesha",G34)),ISNUMBER(SEARCH("geisha",G34))),"⭐ GESHA","") -> ⭐ GESHA | X34: 24 Opal Cres, Singapore 328418
A35: 46161 | B35: Singapore | C35: Pocket by Flip (Flip Coffee Roasters) | D35: Ecuador La Papaya | E35: La Papaya Farm | F35: Loja, Ecuador | G35: Geisha | H35: Washed | I35: Light | J35: Filter Hot — Flat-Bottom (Hario Alpha) | K35: 15 | L35: 225 | M35: 1:15 | N35: 92 → 75 → 92 | O35: Unknown | P35: Mahlkönig CORE (54mm Flat Burr) | Q35: 18 | R35: Fresh Apricot; Rooibos; Lemon Thyme; Toffee Apple | S35: Opening: tartaric apricot + rooibos aspalathin. Mid: thymol terpene coat — lipid-binding, persistent to midway. Cooling: malic apple shift + caramelised sucrose. Clean transparent fade. No linalool/jasmine — terpene-forward character distinct from Peru Geisha entries. Highest-altitude Geisha in archive at 2,100 MASL. | T35: Triple-temp cascade (92→75→92°C) on CORE 54mm flat burr + Hario Alpha flat-bottom preserved heat-sensitive thymol terpenes from 2,100 MASL Loja terroir. 75°C mid-pour is the critical terpene-stabilisation variable — thymol is lipid-binding and volatile above 80°C, so mid-temp pour is the architecture delivering the persistent midpalate coat. Ecuador Geisha = terpene-forward (Thymol/Aspalathin) clearly differentiated from linalool-forward Peru Geisha (Jasmine/Citric). First Ecuador-origin entry in archive. | U35: Solo visit — Pocket by Flip, 30 Stevens Road | V35: Master CSV (hari_coffee_audit_master_2026) | W35: =IF(OR(ISNUMBER(SEARCH("gesha",G35)),ISNUMBER(SEARCH("geisha",G35))),"⭐ GESHA","") -> ⭐ GESHA | X35: 30 Stevens Rd, #01-08, Singapore 257840
A36: 46167 | B36: Singapore | C36: 20 Grams Coffee Roastery | D36: Rwanda Nyabihu — Red Bourbon | E36: Josue Dusengiyumva, Shyira Washing Station | F36: Nyabihu District, Rwanda | G36: Red Bourbon | H36: Washed | I36: Light (Nordic Roast) | J36: Pourover | K36: 17 | L36: 270 | M36: 1:16 | N36: Unknown | O36: Unknown | P36: Ditting 804 (Flat Burr) | Q36: 10 | R36: Hibiscus; Raspberry; Tropical Fruit | S36: Palate confirmed: peach, stone fruit, malic clarity. "Soft, peach-forward, malic clarity — light and approachable. First Rwanda origin entry. Terroir-pure expression of Nyabihu volcanic terroir." 4/5 stars. | T36: 1:16 lean ratio (vs 1:15 standard) suppresses body/TDS to amplify volatile aromatics — deliberate strategy to showcase Rwandan terroir delicacy. Malic-acid-dominant, smooth rounded onset consistent with washed Red Bourbon genetics. | U36: Twenty Grams Roastery, MacPherson — first Rwanda origin entry | V36: Field entry (infographic-derived) | W36: =IF(OR(ISNUMBER(SEARCH("gesha",G36)),ISNUMBER(SEARCH("geisha",G36))),"⭐ GESHA","") | X36: 14 Arumugam Rd, #01-05 LTC Building C, Singapore 409959
A37: 46167 | B37: Singapore | C37: 20 Grams Coffee Roastery | D37: Kenya Nyeri Hill — SL28 | E37: Nyeri Hill Factory | F37: Kiambu District, Kenya | G37: SL28 | H37: Washed | I37: Unknown | J37: Cortado (Espresso-based) | K37: Unknown | L37: Unknown | M37: ~1:1 (espresso/milk) | N37: Unknown | O37: N/A — espresso format | P37: Ditting Lab Sweet 403 | Q37: 9 | R37: Apple; Grape; Blackcurrant | S37: Palate confirmed: clean, nice, excellent lingering finish. "Clean, structured, with an exceptional lingering phosphoric finish — textbook SL28 Kenyan expression perfectly delivered in cortado format." 4/5 stars. | T37: 9-bar extraction emulsifies coffee lipids into the crema matrix; ~1:1 milk ratio softens entry while SL28's signature phosphoric acid structure dominates the finish — classic Kenyan cortado profile. | U37: Twenty Grams Roastery, MacPherson — same visit as Rwanda pourover | V37: Field entry (infographic-derived) | W37: =IF(OR(ISNUMBER(SEARCH("gesha",G37)),ISNUMBER(SEARCH("geisha",G37))),"⭐ GESHA","") | X37: 14 Arumugam Rd, #01-05 LTC Building C, Singapore 409959
A38: 46168 | B38: Singapore | C38: Zerah Roasters | D38: El Diviso — Caturra Chiroso (Ester Bomb) | E38: El Diviso Farm | F38: Huila, Colombia | G38: Caturra Chiroso | H38: Yeast Anaerobic Natural | I38: Filter Roast | J38: Flat-Bottom Dripper | K38: 15 | L38: 240 | M38: 1:16 | N38: 92 | O38: 38g / Unknown seconds | P38: DF64 Gen 2 (64mm Flat Burr — aftermarket upgrade) | Q38: 12 | R38: Passionfruit; Plum Wine; Mango | S38: Goddamn the smell is intense. Flavor burst — acid or strong flavor, super punchy. Passionfruit with enhanced fruit, funky. Plums. After cooling — sugars came out. Interesting. Strong flavor gone. Overall: funky, fermentation-driven. Processing-dominant cup. Three completely different cups in one — ester detonation hot, funk phase mid, mango sweetness cool. | T38: Yeast strains WLPU07 + LALVIN 71B at 96hr fermentation, pH 3.72, 100% anaerobic sealed tank (1.2 bar, 23.4°C) produced extreme ester complexity: γ-decalactone (passionfruit lactone) dominant hot, tartaric esters + acetic acid (plum wine/funk) mid, fructose ester chains (mango sweetness) cold. 1:16 lean ratio was critical safety valve — prevented cloying ester overload and enabled three-phase thermal tracking. Flat-bottom geometry amplified body and even bed saturation. DF64 Gen 2 with aftermarket 64mm flat burrs: first DF64 platform entry in archive. Caturra Chiroso = elongated cell structure, Geisha-adjacent clarity potential overridden by fermentation intensity. Yeast Anaerobic Natural distinct process category from Wild Anaerobic. | U38: Solo visit — Zerah Roasters, Singapore, 26 May 2026. Barista explained fermentation process, flat-bottom geometry rationale, 1:16 ratio decision in detail. Warm educational session on 2nd floor cosy space. Barista recommended Glyph Supply Co (Jurong). | V38: Infographic (Entry #025 Ester Bomb) + Google Maps review + Google review authored by Hari | W38: =IF(OR(ISNUMBER(SEARCH("gesha",G38)),ISNUMBER(SEARCH("geisha",G38))),"⭐ GESHA","") | X38: 465 North Bridge Rd, #02-5063, Singapore 188720
A39: 46183 | B39: Singapore | C39: Nylon Coffee Roasters | D39: Colombia Juan Martin | E39: Banexport | F39: Colombia | G39: Red Striped Bourbon | H39: Washed | I39: Filter Roast | J39: xBloom (Flat-Bottom) | K39: Unknown | L39: Unknown | M39: 1:17 | N39: Unknown | O39: Unknown | P39: Mahlkönig EK Omnia (98mm Flat Burr) | Q39: 7.5 | R39: Berry, Red Plum, Nectarine, Orange Tea | S39: Orange-type aromatic afterfeel when hot — bright and encapsulating. Clearly fruity character throughout. Mellows cleanly as it cools; sugars emerge distinctly at mid-cool phase. Nice and light overall — 1:17 lean ratio working well on this varietal. | T39: EK Omnia 98mm flat burrs + xBloom flat-bottom geometry maintained body integrity at 1:17 lean ratio. Retail bag on shelf dated 10 Jun 2026 but filter batch roast date unconfirmed — cup behaviour (clean sugar emergence, well-integrated stone fruit at cool phase) is consistent with a properly rested lot of 10–21 days post-roast. Red Striped Bourbon sucrose density confirmed by clean sweetness at cool phase. | U39: Solo visit — office lunch break, 13:15 | V39: Direct observation + bag photo (retail stock) | W39: =IF(OR(ISNUMBER(SEARCH("gesha",G39)),ISNUMBER(SEARCH("geisha",G39))),"⭐ GESHA","") | X39: 4 Everton Park, #01-40, Singapore 080004
A40: 46186 | B40: Singapore | C40: Kurasu | D40: Rwanda Nkara Soil Project Lot 1204 | E40: Nkara Soil Project | F40: Rwanda | G40: Red Bourbon | H40: Fully Washed | I40: Filter Roast | J40: V60 Pour-over (Conical) | K40: Unknown | L40: Unknown | M40: Unknown | N40: Unknown | O40: Unknown | P40: Mahlkönig EK43 (98mm Flat Burr) | Q40: 9.27 | R40: Floral aroma, taste of mandarin orange, baked apple and grapefruit, brown sugar-like sweetness and accompanying aftertaste | S40: Strong aftertaste with slight bitterness noted. Baked apple taste dominates and persists across all phases. Sugars emerge clearly on cooling — brown sugar sweetness confirmed at cool phase. Rated average. Rwanda Nkara terroir pushes more citrus-floral (mandarin/grapefruit) vs prior Rwanda entry at Twenty Grams (Entry #024) which was peach/stone fruit dominant. | T40: EK43 98mm flat burrs paired with conical V60 geometry — key hardware distinction vs prior Kurasu Frinsa entry. V60 conical creates faster flow rate and higher bypass risk vs flat-bottom; the slight bitterness is consistent with conical geometry allowing fine particles to over-extract at the drain. Washed Red Bourbon at altitude delivers classic Rwandan citric-malic duality (mandarin + baked apple). Baked apple dominance = malic acid thermally stabilised — persists across full thermal arc unlike volatile citric top notes which fade. Brown sugar aftertaste is sucrose retention signature of Red Bourbon genetics. | U40: Solo visit — 13 Jun 2026 | V40: Direct observation + bean card photo | W40: =IF(OR(ISNUMBER(SEARCH("gesha",G40)),ISNUMBER(SEARCH("geisha",G40))),"⭐ GESHA","") | X40: 261 Waterloo St, #01-24, Singapore 180261
...

Sheet ☕ Dashboard
B1: ☕ T H E H A R I C O F F E E A R C H I V E · 2 0 2 6
B2: Master Extraction Archivist · Singapore · Bali · Mumbai · Johor Bahru · Clarity over Complexity · three-phase thermal record
B4: ▸ ARCHIVE VITALS — every figure below is a live formula; add a row and the dashboard moves with it
B6: TOTAL ENTRIES | D6: UNIQUE CAFÉS | E6: CITIES | F6: ⭐ GESHA CUPS | G6: WASHED SHARE | H6: ARCHIVE SPEND | J6: AVG CUP | K6: AVG GESHA | L6: PEAK CUP | M6: ORIGINS
B7: =COUNTA('Coffee Audit'!A2:A2000) -> 96 | D7: =SUMPRODUCT(('Coffee Audit'!C2:C2000<>"")/COUNTIF('Coffee Audit'!C2:C2000,'Coffee Audit'!C2:C2000&"")) -> 46 | E7: =SUMPRODUCT(('Coffee Audit'!B2:B2000<>"")/COUNTIF('Coffee Audit'!B2:B2000,'Coffee Audit'!B2:B2000&"")) -> 4 | F7: =COUNTIF('Coffee Audit'!W2:W2000,"⭐ GESHA") -> 30 | G7: =TEXT(COUNTIF('Coffee Audit'!H2:H2000,"*Washed*")/COUNTA('Coffee Audit'!A2:A2000),"0%") -> 54% | H7: =SUM('Coffee Audit'!Q2:Q2000) -> 942.13 | J7: =AVERAGEIFS('Coffee Audit'!Q2:Q2000,'Coffee Audit'!Q2:Q2000,">0") -> 11.776625 | K7: =AVERAGEIFS('Coffee Audit'!Q2:Q2000,'Coffee Audit'!W2:W2000,"⭐ GESHA",'Coffee Audit'!Q2:Q2000,">0") -> 15.551 | L7: =MAX('Coffee Audit'!Q2:Q2000) -> 60 | M7: =SUMPRODUCT(('Coffee Audit'!F2:F2000<>"")/COUNTIF('Coffee Audit'!F2:F2000,'Coffee Audit'!F2:F2000&"")) -> 60
B8: field-audited cups | D8: venues audited | E8: SG · Bali · Mumbai · JB | F8: =TEXT(COUNTIF('Coffee Audit'!W2:W2000,"⭐ GESHA")/COUNTA('Coffee Audit'!A2:A2000),"0%")&" of archive" -> 31% of archive | G8: process-family share | H8: total S$ logged | J8: live | K8: live | L8: live | M8: live
B10: ▸ LATEST CUP IN THE ARCHIVE — auto-pulls the final row; never needs editing
B11: DATE | D11: CAFÉ | E11: COFFEE | F11: ORIGIN | G11: VARIETAL | H11: PROCESS | I11: RATIO | J11: TEMP °C | L11: PRICE
B12: =INDEX('Coffee Audit'!A2:A2000,COUNTA('Coffee Audit'!A2:A2000)) -> 46267 | D12: =INDEX('Coffee Audit'!C2:C2000,COUNTA('Coffee Audit'!A2:A2000)) -> Hiritsu Coffee Roastery | E12: =INDEX('Coffee Audit'!D2:D2000,COUNTA('Coffee Audit'!A2:A2000)) -> Bolivia Don Carlos Geisha Washed | F12: =INDEX('Coffee Audit'!F2:F2000,COUNTA('Coffee Audit'!A2:A2000)) -> Caranavi, La Paz, Bolivia | G12: =INDEX('Coffee Audit'!G2:G2000,COUNTA('Coffee Audit'!A2:A2000)) -> Geisha | H12: =INDEX('Coffee Audit'!H2:H2000,COUNTA('Coffee Audit'!A2:A2000)) -> Washed | I12: =INDEX('Coffee Audit'!M2:M2000,COUNTA('Coffee Audit'!A2:A2000)) -> 1:11.9 (16g : 190g water) | J12: =INDEX('Coffee Audit'!N2:N2000,COUNTA('Coffee Audit'!A2:A2000)) -> 92 | L12: =INDEX('Coffee Audit'!Q2:Q2000,COUNTA('Coffee Audit'!A2:A2000)) -> 12.18
B14: =" ⭐ GESHA / GEISHA HALL OF FAME — all "&COUNTIF('Coffee Audit'!W2:W2000,"⭐ GESHA")&" apex-varietal cups, ranked by price paid" -> ⭐ GESHA / GEISHA HALL OF FAME — all 30 apex-varietal cups, ranked by price paid
B15: # | C15: Café | D15: Origin · Farm | E15: Process | F15: Price | G15: Archive Flag
B16: 1 | C16: Pour.traits Roasters | D16: Panama · Finca Sophia Torcaza | E16: Washed | F16: 60 | G16: 👑 ARCHIVE #1
B17: 2 | C17: Fluid Collective | D17: Panama · Boot / Hartmann / Pohl | E17: Natural | F17: 32
B18: 3 | C18: Abseil | D18: Colombia · El Sauce | E18: Washed | F18: 21
B19: 4 | C19: Homeground Coffee Roasters | D19: Colombia · Valle (Inmaculada) | E19: Natural | F19: 19
B20: 5 | C20: ECHO (aery x Lim Junghwan) | D20: Panama · Boquete (Lerida Estate) | E20: Washed | F20: 18 | G20: 1 SEP · FIRST LERIDA · ZERO CITRUS
B21: 6 | C21: Pocket by Flip (Flip Coffee Roasters) | D21: Ecuador · Loja | E21: Washed | F21: 18
B22: 7 | C22: Sweet Blossom (Nas Jaafar) | D22: Colombia · Finca La Negrita | E22: Red Honey | F22: 16.2 | G22: 🆕 2 SEP · WBrC CHAMPION POUR · CITRUS SURVIVES HONEY
B23: 8 | C23: Double Shot Coffee | D23: Panama · Boquete (Kotowa) | E23: Natural | F23: 16
B24: 9 | C24: Mame (SIGEP Asia booth) | D24: Panama · Bambito Estate | E24: Washed | F24: 16
B25: 10 | C25: Sweet Blossom (Nas Jaafar) | D25: Guatemala · Huehuetenango (Finca El Injerto) | E25: Washed | F25: 16 | G25: 🆕 2 SEP · WBrC CHAMPION POUR · 1st GUATEMALA GESHA
B26: 11 | C26: KerYi Coffee | D26: Colombia · La Esmaralda | E26: Honey | F26: 15
B27: 12 | C27: Pinhole Coffee Bar | D27: Colombia · Huila | E27: Honey | F27: 15
B28: 13 | C28: Fluid Collective | D28: Colombia · El Obraje | E28: Washed | F28: 14 | G28: ★ 6-mo former #1
B29: 14 | C29: Equate Coffee | D29: Colombia · Huila | E29: Washed | F29: 13
B30: 15 | C30: Suzuki Cafe & Roastery | D30: Colombia · Quindío (Santa Mónica) | E30: Anaerobic Nat. | F30: 13
B31: 16 | C31: Asylum Coffeehouse | D31: Peru · Jaén | E31: Washed | F31: 12.5
B32: 17 | C32: Hiritsu Coffee Roastery | D32: Bolivia · Caranavi, La Paz (Don Carlos) | E32: Washed | F32: 12.18 | G32: 🆕 2 SEP · 1st BOLIVIA GESHA · ZERO CITRUS @1,600m
B33: 18 | C33: Equate Coffee | D33: Peru · Cajamarca | E33: Washed | F33: 12
B34: 19 | C34: Lume Café | D34: Panama · Boquerón | E34: Red Honey | F34: 12
B35: 20 | C35: Pocket by Flip (Flip Coffee Roasters) | D35: Peru · Jaén, Cajamarca (Wilder Garcia) | E35: Washed | F35: 12 | G35: 🆕 25 AUG · FIRST PERU-GESHA AT POCKET
B36: 21 | C36: Prodigal Roasters | D36: Peru · Finca Los Santos | E36: Natural | F36: 12
B37: 22 | C37: August Drip Coffee | D37: Panama · Boquete ("La Mariposa") | E37: Anaerobic Nat. | F37: 11.75 | G37: 22 AUG · FIRST JB GESHA
B38: 23 | C38: Asylum Coffeehouse | D38: Peru · Cajamarca | E38: Washed | F38: 11
B39: 24 | C39: Alchemist (Funan) | D39: Colombia · Valle (Las Margaritas) | E39: Honey | F39: 10.5 | G39: 29 JUL 2026
B40: 25 | C40: Asylum Coffeehouse | D40: Peru · Jaén, Cajamarca (Wilder Garcia) | E40: Washed | F40: 10 | G40: 1 SEP · 5th WILDER GARCIA
B41: 26 | C41: Nylon Coffee Roasters | D41: Peru · Jaén, Cajamarca (Wilder Garcia) | E41: Washed | F41: 10
B42: 27 | C42: Pour.traits Roasters | D42: Thailand · Chiang Rai (Sirinya) | E42: Anaerobic Nat. | F42: 10
B43: 28 | C43: Cowpresso Coffee Roasters | D43: Colombia · Valle (Las Nubes) | E43: Natural | F43: 9.9
B44: 29 | C44: Apartment (Selegie Rd) | D44: Peru · Wilder Garcia | E44: Washed | F44: 9.5
...

Sheet 🧬 Palate DNA
B1: 🧬 PALATE DNA FINGERPRINT
B2: ="What "&COUNTA('Coffee Audit'!A2:A2000)&" cups reveal about one palate — malic acid · linalool · flat-bottom geometry · washed clarity" -> What 96 cups reveal about one palate — malic acid · linalool · flat-bottom geometry · washed clarity
B4: 📖 THE PALATE THESIS
B5: ="CLARITY OVER COMPLEXITY. Across "&COUNTA('Coffee Audit'!A2:A2000)&" cups and seven months, one pattern dominates: "&TEXT(COUNTIF('Coffee Audit'!H2:H2000,"*Washed*")/COUNTA('Coffee Audit'!A2:A2000),"0%")&" of all entries fall in the Washed process family. The palate responds strongest to malic-acid stone fruit (white peach, nectarine, apricot, mandarin) and linalool/geraniol florals (jasmine, honeysuckle, orange blossom) carried on a clean, low-noise base. Fermentation-forward processing is logged as archive data, not as preference — the ceiling was formally confirmed at Entry #059. Gesha/Geisha remains the apex varietal at "&COUNTIF('Coffee Audit'!W2:W2000,"⭐ GESHA")&" cups ("&TEXT(COUNTIF('Coffee Audit'!W2:W2000,"⭐ GESHA")/COUNTA('Coffee Audit'!A2:A2000),"0%")&"), commanding a "&TEXT(AVERAGEIFS('Coffee Audit'!Q2:Q2000,'Coffee Audit'!W2:W2000,"⭐ GESHA",'Coffee Audit'!Q2:Q2000,">0")/AVERAGEIFS('Coffee Audit'!Q2:Q2000,'Coffee Audit'!W2:W2000,"",'Coffee Audit'!Q2:Q2000,">0")-1,"0%")&" premium over everything else." -> CLARITY OVER COMPLEXITY. Across 96 cups and seven months, one pattern dominates: 54% of all entries fall in the Washed process family. The palate responds strongest to malic-acid stone fruit (white peach, nectarine, apricot, mandarin) and linalool/geraniol florals (jasmine, honeysuckle, orange blossom) carried on a clean, low-noise base. Fermentation-forward processing is logged as archive data, not as preference — the ceiling was formally confirmed at Entry #059. Gesha/Geisha remains the apex varietal at 30 cups (31%), commanding a 63% premium over everything else.
B10: =" 🍯 PROCESS PREFERENCE SPECTRUM — live across "&COUNTA('Coffee Audit'!A2:A2000)&" entries" -> 🍯 PROCESS PREFERENCE SPECTRUM — live across 96 entries | H10: 🌡️ TEMPERATURE PROTOCOLS — 88–93°C sweet spot
B11: Process | C11: Entries | D11: % | E11: Palate Signal | F11: Affinity | H11: Protocol | I11: Entries | J11: Context
B12: Washed | C12: =COUNTIF('Coffee Audit'!H2:H2000,"*Washed*") -> 52 | D12: =TEXT(COUNTIF('Coffee Audit'!H2:H2000,"*Washed*")/COUNTA('Coffee Audit'!A2:A2000),"0%") -> 54% | E12: Malic acid clarity · jasmine lift · clean thermal arcs | F12: ★★★★★ Primary | H12: 85–89°C | I12: =SUMPRODUCT(('Coffee Audit'!A2:A2000<>"")*((ISNUMBER(SEARCH("85",'Coffee Audit'!N2:N2000))+ISNUMBER(SEARCH("86",'Coffee Audit'!N2:N2000))+ISNUMBER(SEARCH("87",'Coffee Audit'!N2:N2000))+ISNUMBER(SEARCH("88",'Coffee Audit'!N2:N2000))+ISNUMBER(SEARCH("89",'Coffee Audit'!N2:N2000)))>0)) -> 5 | J12: Delicate / Nordic style — Abseil 88°C constant for LAB ester preservation
B13: Natural | C13: =COUNTIF('Coffee Audit'!H2:H2000,"*Natural*") -> 32 | D13: =TEXT(COUNTIF('Coffee Audit'!H2:H2000,"*Natural*")/COUNTA('Coffee Audit'!A2:A2000),"0%") -> 33% | E13: Stone fruit · berry complexity · terroir depth | F13: ★★★★ Secondary | H13: 90–91°C | I13: =SUMPRODUCT(('Coffee Audit'!A2:A2000<>"")*((ISNUMBER(SEARCH("90",'Coffee Audit'!N2:N2000))+ISNUMBER(SEARCH("91",'Coffee Audit'!N2:N2000)))>0)) -> 22 | J13: Clean balanced extraction — Keryi descending protocol
B14: Honey | C14: =COUNTIF('Coffee Audit'!H2:H2000,"*Honey*") -> 8 | D14: =TEXT(COUNTIF('Coffee Audit'!H2:H2000,"*Honey*")/COUNTA('Coffee Audit'!A2:A2000),"0%") -> 8% | E14: Mucilage sweetness bridge · ketone fruit layer | F14: ★★★★ Bridge | H14: 92–94°C ⭐ | I14: =SUMPRODUCT(('Coffee Audit'!A2:A2000<>"")*((ISNUMBER(SEARCH("92",'Coffee Audit'!N2:N2000))+ISNUMBER(SEARCH("93",'Coffee Audit'!N2:N2000))+ISNUMBER(SEARCH("94",'Coffee Audit'!N2:N2000)))>0)) -> 33 | J14: Sweet spot — dominant single-temp protocol in Singapore cafés
B15: Anaerobic | C15: =COUNTIF('Coffee Audit'!H2:H2000,"*Anaerobic*") -> 14 | D15: =TEXT(COUNTIF('Coffee Audit'!H2:H2000,"*Anaerobic*")/COUNTA('Coffee Audit'!A2:A2000),"0%") -> 15% | E15: Controlled funk · ester complexity · tropical esters | F15: ★★★ Experimental | H15: 95°C | I15: =SUMPRODUCT(('Coffee Audit'!A2:A2000<>"")*((ISNUMBER(SEARCH("95",'Coffee Audit'!N2:N2000)))>0)) -> 6 | J15: Full extraction — bold washed profiles · Apartment Jalan Riang
B16: Co-Ferment / Yeast / Mosto | C16: =COUNTIF('Coffee Audit'!H2:H2000,"*Ferment*") -> 9 | D16: =TEXT(COUNTIF('Coffee Audit'!H2:H2000,"*Ferment*")/COUNTA('Coffee Audit'!A2:A2000),"0%") -> 9% | E16: Frontier zone — logged as data, rarely reordered | F16: ★★ Exploratory | H16: 70→90→70°C 🏆 | I16: 7 | J16: Fluid Collective signature oscillation — highest-rated cups in archive
B17: Wet-Hulled | C17: =COUNTIF('Coffee Audit'!H2:H2000,"*Hulled*") -> 1 | D17: =TEXT(COUNTIF('Coffee Audit'!H2:H2000,"*Hulled*")/COUNTA('Coffee Audit'!A2:A2000),"0%") -> 1% | E17: Indonesian terroir · syrupy body · reference entry | F17: ★ Reference | H17: 90→70°C (descending) | I17: 4 | J17: Keryi / Pinhole / Double Shot — terpene preservation on honey/gesha
H18: 80→95→80°C | I18: 1 | J18: Kurasu Frinsa — honey process mucilage management
H19: 88°C constant | I19: 1 | J19: Oaks — LAB lactic ester preservation (Bolivia Pacamara)
H20: 75→94°C (ASCENDING) 🆕 | I20: 1 | J20: Bayu Prawiro (WBrC 2025 runner-up) on Excelsa — inverse architecture: cool base restrains ferment, hot finish releases fruit
B21: ⭐ COLOMBIA GESHA PROCESS TRILOGY — Completed 2026 · Three processes · One verdict | H21: ⚖️ RATIO BAND ANALYSIS — 1:15–1:17 Optimal Window
B22: Process | C22: Café | D22: Sensory Arc | E22: Verdict | H22: Band | I22: Count | J22: Status | K22: Chemistry Note
B23: Washed ⭐ | C23: Fluid Collective (El Obraje) | D23: Mango · Orange Blossom · Nectarine · Honey — linalool apex | E23: CUP OF THE YEAR | H23: <1:13 | I23: =SUMPRODUCT(('Coffee Audit'!A2:A2000<>"")*((ISNUMBER(SEARCH("1:10",'Coffee Audit'!M2:M2000))+ISNUMBER(SEARCH("1:11",'Coffee Audit'!M2:M2000))+ISNUMBER(SEARCH("1:12",'Coffee Audit'!M2:M2000))+ISNUMBER(SEARCH("1:2",'Coffee Audit'!M2:M2000))+ISNUMBER(SEARCH("1:1 ",'Coffee Audit'!M2:M2000)))>0)) -> 5 | J23: ⚠️ Espresso | K23: Concentration removes filter brewing purpose
B24: Honey | C24: Keryi Coffee (Finca La Esmaralda) | D24: Jasmine · Caramel · Stone Fruit · Tangerine — smooth arc | E24: EXCELLENT | H24: 1:13–1:14 | I24: =SUMPRODUCT(('Coffee Audit'!A2:A2000<>"")*((ISNUMBER(SEARCH("1:13",'Coffee Audit'!M2:M2000)))>0)) -> 5 | J24: ⚠️ Dense | K24: Polyphenolic bitterness amplified · sucrose suppressed (Entry #055)
B25: Honey | C25: Pinhole Coffee Bar (Santa Barbara #1) | D25: Bergamot · Lychee · Mandarin · Honey — cold-cup revelation | E25: VERY GOOD | H25: 1:14–1:15 | I25: =SUMPRODUCT(('Coffee Audit'!A2:A2000<>"")*((ISNUMBER(SEARCH("1:14",'Coffee Audit'!M2:M2000)))>0)) -> 9 | J25: ⚠️ Edge | K25: Aromatic headspace compressed vs optimal
B26: Natural | C26: Homeground (Inmaculada Estate) | D26: Hibiscus · Pomegranate · Darjeeling Tea — relaxing depth | E26: EXCELLENT | H26: 1:15–1:17 ✅ | I26: =SUMPRODUCT(('Coffee Audit'!A2:A2000<>"")*((ISNUMBER(SEARCH("1:15",'Coffee Audit'!M2:M2000))+ISNUMBER(SEARCH("1:16",'Coffee Audit'!M2:M2000))+ISNUMBER(SEARCH("1:17",'Coffee Audit'!M2:M2000)))>0)) -> 58 | J26: ✅ OPTIMAL | K26: ="Core extraction philosophy — "&TEXT(I26/COUNTA('Coffee Audit'!A2:A2000),"0%")&" of all logged entries" -> Core extraction philosophy — 60% of all logged entries
B27: Natural | C27: Cowpresso (Las Nubes) | D27: Lychee · Berry · Tropical — aggressive Natural expression | E27: GOOD | H27: >1:17 | I27: =SUMPRODUCT(('Coffee Audit'!A2:A2000<>"")*((ISNUMBER(SEARCH("1:18",'Coffee Audit'!M2:M2000))+ISNUMBER(SEARCH("1:19",'Coffee Audit'!M2:M2000)))>0)) -> 0 | J27: — | K27: CGA lactone risk on Naturals — confirmed Entry #056 Nylon
B28: Archive verdict on the Colombia Gesha Trilogy: Washed = genetic purity (apex). Honey = sweetness amplified. Natural = fermentation over clarity. Washed remains unmatched. | H28: Unknown | I28: =COUNTA('Coffee Audit'!A2:A2000)-SUM(I23:I27) -> 19 | J28: — | K28: Early entries pre-hardware protocol · improving each visit

Sheet 🌍 Origin & Terroir
B1: 🌍 ORIGIN & TERROIR ATLAS
B2: ="Where the archive has travelled — "&SUMPRODUCT(('Coffee Audit'!F2:F2000<>"")/COUNTIF('Coffee Audit'!F2:F2000,'Coffee Audit'!F2:F2000&""))&" distinct origin strings · Colombia leads at "&TEXT(COUNTIF('Coffee Audit'!F2:F2000,"*Colombia*")/COUNTA('Coffee Audit'!A2:A2000),"0%")&" · "&COUNTIF('Coffee Audit'!W2:W2000,"⭐ GESHA")&" Gesha entries" -> Where the archive has travelled — 60 distinct origin strings · Colombia leads at 24% · 30 Gesha entries
B4: 🗺️ ORIGIN LEAGUE TABLE — live formula, auto-updates with new entries | H4: =" ⭐ GESHA REGISTER — The Apex Varietal · "&COUNTIF('Coffee Audit'!W2:W2000,"⭐ GESHA")&" archive entries" -> ⭐ GESHA REGISTER — The Apex Varietal · 30 archive entries
B5: Origin | C5: Entries | D5: Share | E5: Gesha? | F5: Palate DNA Fit | H5: Metric | I5: Value
B6: Colombia | C6: =COUNTIF('Coffee Audit'!F2:F2000,"*Colombia*") -> 23 | D6: =TEXT(COUNTIF('Coffee Audit'!F2:F2000,"*Colombia*")/COUNTA('Coffee Audit'!A2:A2000),"0%") -> 24% | E6: =IF(SUMPRODUCT(ISNUMBER(SEARCH("Colombia",'Coffee Audit'!F2:F2000))*('Coffee Audit'!W2:W2000="⭐ GESHA"))=0,"—","⭐ ×"&SUMPRODUCT(ISNUMBER(SEARCH("Colombia",'Coffee Audit'!F2:F2000))*('Coffee Audit'!W2:W2000="⭐ GESHA"))) -> ⭐ ×10 | F6: HIGHEST — malic + Gesha depth | H6: Total Gesha/Geisha entries | I6: =COUNTIF('Coffee Audit'!W2:W2000,"⭐ GESHA") -> 30
B7: Ethiopia | C7: =COUNTIF('Coffee Audit'!F2:F2000,"*Ethiopia*") -> 10 | D7: =TEXT(COUNTIF('Coffee Audit'!F2:F2000,"*Ethiopia*")/COUNTA('Coffee Audit'!A2:A2000),"0%") -> 10% | E7: =IF(SUMPRODUCT(ISNUMBER(SEARCH("Ethiopia",'Coffee Audit'!F2:F2000))*('Coffee Audit'!W2:W2000="⭐ GESHA"))=0,"—","⭐ ×"&SUMPRODUCT(ISNUMBER(SEARCH("Ethiopia",'Coffee Audit'!F2:F2000))*('Coffee Audit'!W2:W2000="⭐ GESHA"))) -> — | F7: HIGH — linalool florals · heirloom terroir | H7: Washed Gesha | I7: =SUMPRODUCT(('Coffee Audit'!W2:W2000="⭐ GESHA")*(ISNUMBER(SEARCH("washed",'Coffee Audit'!H2:H2000)))) -> 17
B8: Brazil | C8: =COUNTIF('Coffee Audit'!F2:F2000,"*Brazil*") -> 5 | D8: =TEXT(COUNTIF('Coffee Audit'!F2:F2000,"*Brazil*")/COUNTA('Coffee Audit'!A2:A2000),"0%") -> 5% | E8: =IF(SUMPRODUCT(ISNUMBER(SEARCH("Brazil",'Coffee Audit'!F2:F2000))*('Coffee Audit'!W2:W2000="⭐ GESHA"))=0,"—","⭐ ×"&SUMPRODUCT(ISNUMBER(SEARCH("Brazil",'Coffee Audit'!F2:F2000))*('Coffee Audit'!W2:W2000="⭐ GESHA"))) -> — | F8: MED — body · Maillard sweetness baseline | H8: Honey Gesha | I8: =SUMPRODUCT(('Coffee Audit'!W2:W2000="⭐ GESHA")*(ISNUMBER(SEARCH("honey",'Coffee Audit'!H2:H2000)))) -> 5
B9: Honduras | C9: =COUNTIF('Coffee Audit'!F2:F2000,"*Honduras*") -> 3 | D9: =TEXT(COUNTIF('Coffee Audit'!F2:F2000,"*Honduras*")/COUNTA('Coffee Audit'!A2:A2000),"0%") -> 3% | E9: =IF(SUMPRODUCT(ISNUMBER(SEARCH("Honduras",'Coffee Audit'!F2:F2000))*('Coffee Audit'!W2:W2000="⭐ GESHA"))=0,"—","⭐ ×"&SUMPRODUCT(ISNUMBER(SEARCH("Honduras",'Coffee Audit'!F2:F2000))*('Coffee Audit'!W2:W2000="⭐ GESHA"))) -> — | F9: HIGH — malic stone fruit · clean finish | H9: Natural Gesha | I9: =SUMPRODUCT(('Coffee Audit'!W2:W2000="⭐ GESHA")*(ISNUMBER(SEARCH("natural",'Coffee Audit'!H2:H2000)))) -> 8
B10: Indonesia | C10: =COUNTIF('Coffee Audit'!F2:F2000,"*Indonesia*") -> 5 | D10: =TEXT(COUNTIF('Coffee Audit'!F2:F2000,"*Indonesia*")/COUNTA('Coffee Audit'!A2:A2000),"0%") -> 5% | E10: =IF(SUMPRODUCT(ISNUMBER(SEARCH("Indonesia",'Coffee Audit'!F2:F2000))*('Coffee Audit'!W2:W2000="⭐ GESHA"))=0,"—","⭐ ×"&SUMPRODUCT(ISNUMBER(SEARCH("Indonesia",'Coffee Audit'!F2:F2000))*('Coffee Audit'!W2:W2000="⭐ GESHA"))) -> — | F10: MED — wet-hulled texture study · Excelsa species capture (Entry #093) | H10: Avg Gesha price (SGD) | I10: ="S$"&TEXT(AVERAGEIFS('Coffee Audit'!Q2:Q2000,'Coffee Audit'!W2:W2000,"⭐ GESHA",'Coffee Audit'!Q2:Q2000,">0"),"0.00") -> S$15.55
B11: Peru | C11: =COUNTIF('Coffee Audit'!F2:F2000,"*Peru*") -> 10 | D11: =TEXT(COUNTIF('Coffee Audit'!F2:F2000,"*Peru*")/COUNTA('Coffee Audit'!A2:A2000),"0%") -> 10% | E11: =IF(SUMPRODUCT(ISNUMBER(SEARCH("Peru",'Coffee Audit'!F2:F2000))*('Coffee Audit'!W2:W2000="⭐ GESHA"))=0,"—","⭐ ×"&SUMPRODUCT(ISNUMBER(SEARCH("Peru",'Coffee Audit'!F2:F2000))*('Coffee Audit'!W2:W2000="⭐ GESHA"))) -> ⭐ ×8 | F11: HIGH — washed Gesha clarity (Wilder Garcia) | H11: Avg non-Gesha price (SGD) | I11: ="S$"&TEXT(AVERAGEIFS('Coffee Audit'!Q2:Q2000,'Coffee Audit'!W2:W2000,"<>⭐ GESHA",'Coffee Audit'!Q2:Q2000,">0"),"0.00") -> S$9.51
B12: Kenya | C12: =COUNTIF('Coffee Audit'!F2:F2000,"*Kenya*") -> 5 | D12: =TEXT(COUNTIF('Coffee Audit'!F2:F2000,"*Kenya*")/COUNTA('Coffee Audit'!A2:A2000),"0%") -> 5% | E12: =IF(SUMPRODUCT(ISNUMBER(SEARCH("Kenya",'Coffee Audit'!F2:F2000))*('Coffee Audit'!W2:W2000="⭐ GESHA"))=0,"—","⭐ ×"&SUMPRODUCT(ISNUMBER(SEARCH("Kenya",'Coffee Audit'!F2:F2000))*('Coffee Audit'!W2:W2000="⭐ GESHA"))) -> — | F12: HIGH — phosphoric acid · blackcurrant benchmark | H12: Gesha price premium | I12: ="+"&TEXT(AVERAGEIFS('Coffee Audit'!Q2:Q2000,'Coffee Audit'!W2:W2000,"⭐ GESHA",'Coffee Audit'!Q2:Q2000,">0")/AVERAGEIFS('Coffee Audit'!Q2:Q2000,'Coffee Audit'!W2:W2000,"<>⭐ GESHA",'Coffee Audit'!Q2:Q2000,">0")-1,"0%") -> +63%
B13: Panama | C13: =COUNTIF('Coffee Audit'!F2:F2000,"*Panama*") -> 8 | D13: =TEXT(COUNTIF('Coffee Audit'!F2:F2000,"*Panama*")/COUNTA('Coffee Audit'!A2:A2000),"0%") -> 8% | E13: HIGHEST — Gesha heartland (Kotowa · Corpachi · Lerida Estate) | F13: HIGHEST — Gesha heartland (Kotowa · Corpachi · Lerida Estate) | H13: Origins with Gesha entry | I13: Colombia · Peru · Panama · Ecuador · Honduras · Guatemala · Bolivia
B14: Nicaragua | C14: =COUNTIF('Coffee Audit'!F2:F2000,"*Nicaragua*") -> 3 | D14: =TEXT(COUNTIF('Coffee Audit'!F2:F2000,"*Nicaragua*")/COUNTA('Coffee Audit'!A2:A2000),"0%") -> 3% | E14: =IF(SUMPRODUCT(ISNUMBER(SEARCH("Nicaragua",'Coffee Audit'!F2:F2000))*('Coffee Audit'!W2:W2000="⭐ GESHA"))=0,"—","⭐ ×"&SUMPRODUCT(ISNUMBER(SEARCH("Nicaragua",'Coffee Audit'!F2:F2000))*('Coffee Audit'!W2:W2000="⭐ GESHA"))) -> — | F14: MED — clean washed + anaerobic contrast | H14: Highest-priced Gesha | I14: ="S$"&TEXT(_xlfn.MAXIFS('Coffee Audit'!Q2:Q2000,'Coffee Audit'!W2:W2000,"⭐ GESHA"),"0")&" — "&INDEX('Coffee Audit'!D2:D2000,MATCH(1,INDEX(('Coffee Audit'!W2:W2000="⭐ GESHA")*('Coffee Audit'!Q2:Q2000=_xlfn.MAXIFS('Coffee Audit'!Q2:Q2000,'Coffee Audit'!W2:W2000,"⭐ GESHA")),0),0))&" ("&INDEX('Coffee Audit'!C2:C2000,MATCH(1,INDEX(('Coffee Audit'!W2:W2000="⭐ GESHA")*('Coffee Audit'!Q2:Q2000=_xlfn.MAXIFS('Coffee Audit'!Q2:Q2000,'Coffee Audit'!W2:W2000,"⭐ GESHA")),0),0))&")" -> S$60 — Finca Sophia Torcaza Grand Reserve Washed Geisha (Pour.traits Roasters)
B15: Bolivia | C15: =COUNTIF('Coffee Audit'!F2:F2000,"*Bolivia*") -> 3 | D15: =TEXT(COUNTIF('Coffee Audit'!F2:F2000,"*Bolivia*")/COUNTA('Coffee Audit'!A2:A2000),"0%") -> 3% | E15: =IF(SUMPRODUCT(ISNUMBER(SEARCH("Bolivia",'Coffee Audit'!F2:F2000))*('Coffee Audit'!W2:W2000="⭐ GESHA"))=0,"—","⭐ ×"&SUMPRODUCT(ISNUMBER(SEARCH("Bolivia",'Coffee Audit'!F2:F2000))*('Coffee Audit'!W2:W2000="⭐ GESHA"))) -> ⭐ ×1 | F15: HIGH — Lactic Honey Pacamara (#049) · FIRST BOLIVIAN GESHA 2 Sep 2026 (Caranavi, Don Carlos — Entry #096); zero citrus at 1,550–1,650 masl | H15: Best-value Gesha | I15: ="S$"&TEXT(_xlfn.MINIFS('Coffee Audit'!Q2:Q2000,'Coffee Audit'!W2:W2000,"⭐ GESHA",'Coffee Audit'!Q2:Q2000,">0"),"0.00")&" — "&INDEX('Coffee Audit'!D2:D2000,MATCH(1,INDEX(('Coffee Audit'!W2:W2000="⭐ GESHA")*('Coffee Audit'!Q2:Q2000=_xlfn.MINIFS('Coffee Audit'!Q2:Q2000,'Coffee Audit'!W2:W2000,"⭐ GESHA",'Coffee Audit'!Q2:Q2000,">0")),0),0))&" ("&INDEX('Coffee Audit'!C2:C2000,MATCH(1,INDEX(('Coffee Audit'!W2:W2000="⭐ GESHA")*('Coffee Audit'!Q2:Q2000=_xlfn.MINIFS('Coffee Audit'!Q2:Q2000,'Coffee Audit'!W2:W2000,"⭐ GESHA",'Coffee Audit'!Q2:Q2000,">0")),0),0))&")" -> S$9.00 — Berlina — Washed Panama Geisha (Fluid Collective)
B16: Ecuador | C16: =COUNTIF('Coffee Audit'!F2:F2000,"*Ecuador*") -> 2 | D16: =TEXT(COUNTIF('Coffee Audit'!F2:F2000,"*Ecuador*")/COUNTA('Coffee Audit'!A2:A2000),"0%") -> 2% | E16: =IF(SUMPRODUCT(ISNUMBER(SEARCH("Ecuador",'Coffee Audit'!F2:F2000))*('Coffee Audit'!W2:W2000="⭐ GESHA"))=0,"—","⭐ ×"&SUMPRODUCT(ISNUMBER(SEARCH("Ecuador",'Coffee Audit'!F2:F2000))*('Coffee Audit'!W2:W2000="⭐ GESHA"))) -> ⭐ ×1 | F16: HIGHEST — #1 palate fit (Loja Gesha) | H16: Archive verdict — apex process | I16: Washed (genetic purity over fermentation)
